Workbook

Sheet README
A1: Software Valuation Model — owner-FCF DCF with durability-weighted buy prices
A3: HOW TO UPDATE AFTER A NEW FILING
A4: 1. Go to 'Inputs'. Change only BLUE cells (yellow = key judgment calls).
A5: 2. From the 10-Q / 10-K / earnings release, update: price, diluted shares, total debt, cash & investments, FCF (OCF − capex), SBC.
A6: 3. Put any one-time cash items (tax catch-ups, legal settlements, working-capital swings) in 'One-time items to remove'.
A7: 4. Revisit the judgment cells: starting growth (anchor to guidance) and P(durable).
A8: 5. Read results on 'Summary'. Use 'Sensitivity' (pick a ticker in the yellow cell) to see how r and g move value.
A9: 6. Record what changed on 'Filing Log' so you can see how your target evolved.
A11: ADDING A COMPANY
A12: Fill an empty column (G or H) on 'Inputs'. Everything else picks it up automatically (6 slots total).
A14: COLOR LEGEND
A15: Blue text = hardcoded input you edit · Black = formula (do not edit) · Green = link from another sheet · Yellow fill = key judgment assumption
... A27: Cells marked EST in the source notes are analyst estimates. P(durable) is a judgment, not data. This is analysis, not personal financial advice.

Sheet Summary
A1: Summary — price targets (all formulas; edit 'Inputs')
A2: ="Base r "&TEXT(Inputs!B4,"0.0%")&" · Conservative r "&TEXT(Inputs!B5,"0.0%")&" · Terminal g "&TEXT(Inputs!B6,"0.0%")&" · Bear decline "&TEXT(Inputs!B7,"0.0%")&" · MOS "&TEXT(Inputs!B8,"0%")
A4: Slot | B4: Ticker | C4: Price | D4: EV / owner FCF | E4: SBC % of FCF | F4: Starting growth | G4: Going-concern value (base r) | H4: Going-concern value (cons. r) | I4: Bear value (cons. r) | J4: P(durable) | K4: Weighted value (cons. r) | L4: Going-concern × (1−MOS) | M4: BUY BELOW | N4: Price vs buy-below | O4: Implied growth (base r) | P4: Implied growth (cons. r) | Q4: Verdict
A5: 1 | B5: =IF(INDEX(Inputs!$C$12:$H$12,$A5)="","",INDEX(Inputs!$C$12:$H$12,$A5)) | C5: =IF($B5="","",INDEX(Inputs!$C$14:$H$14,$A5)) | D5: =IF($B5="","",(INDEX(Inputs!$C$14:$H$14,$A5)*INDEX(Inputs!$C$15:$H$15,$A5)+INDEX(Inputs!$C$19:$H$19,$A5))/INDEX(Inputs!$C$25:$H$25,$A5)) | E5: =IF($B5="","",INDEX(Inputs!$C$24:$H$24,$A5)/INDEX(Inputs!$C$23:$H$23,$A5)) | F5: =IF($B5="","",INDEX(Inputs!$C$26:$H$26,$A5)) | G5: =IF($B5="","",INDEX(DCF!$C$60:$H$60,$A5)) | H5: =IF($B5="","",INDEX(DCF!$C$65:$H$65,$A5)) | I5: =IF($B5="","",INDEX(DCF!$C$66:$H$66,$A5)) | J5: =IF($B5="","",INDEX(Inputs!$C$27:$H$27,$A5)) | K5: =IF($B5="","",J5*H5+(1-J5)*I5) | L5: =IF($B5="","",H5*(1-Inputs!$B$8)) | M5: =IF($B5="","",MIN(K5,L5)) | N5: =IF($B5="","",M5/C5-1) | O5: =IF($B5="","",IF((INDEX(Inputs!$C$14:$H$14,$A5)*INDEX(Inputs!$C$15:$H$15,$A5)+INDEX(Inputs!$C$19:$H$19,$A5))/INDEX(Inputs!$C$25:$H$25,$A5)<ImpliedCalc!$L$4,"< -20%",IF((INDEX(Inputs!$C$14:$H$14,$A5)*INDEX(Inputs!$C$15:$H$15,$A5)+INDEX(Inputs!$C$19:$H$19,$A5))/INDEX(Inputs!$C$25:$H$25,$A5)>ImpliedCalc!$L$124,"> 40%",INDEX(ImpliedCalc!$A$4:$A$124,MATCH((INDEX(Inputs!$C$14:$H$14,$A5)*INDEX(Inputs!$C$15:$H$15,$A5)+INDEX(Inputs!$C$19:$H$19,$A5))/INDEX(Inputs!$C$25:$H$25,$A5),ImpliedCalc!$L$4:$L$124,1))))) | P5: =IF($B5="","",IF((INDEX(Inputs!$C$14:$H$14,$A5)*INDEX(Inputs!$C$15:$H$15,$A5)+INDEX(Inputs!$C$19:$H$19,$A5))/INDEX(Inputs!$C$25:$H$25,$A5)<ImpliedCalc!$M$4,"< -20%",IF((INDEX(Inputs!$C$14:$H$14,$A5)*INDEX(Inputs!$C$15:$H$15,$A5)+INDEX(Inputs!$C$19:$H$19,$A5))/INDEX(Inputs!$C$25:$H$25,$A5)>ImpliedCalc!$M$124,"> 40%",INDEX(ImpliedCalc!$A$4:$A$124,MATCH((INDEX(Inputs!$C$14:$H$14,$A5)*INDEX(Inputs!$C$15:$H$15,$A5)+INDEX(Inputs!$C$19:$H$19,$A5))/INDEX(Inputs!$C$25:$H$25,$A5),ImpliedCalc!$M$4:$M$124,1))))) | Q5: =IF($B5="","",IF(C5<=M5,"BUY ZONE",IF(C5<=M5*1.1,"WATCH","NO BUY")))
A6: 2 | B6: =IF(INDEX(Inputs!$C$12:$H$12,$A6)="","",INDEX(Inputs!$C$12:$H$12,$A6)) | C6: =IF($B6="","",INDEX(Inputs!$C$14:$H$14,$A6)) | D6: =IF($B6="","",(INDEX(Inputs!$C$14:$H$14,$A6)*INDEX(Inputs!$C$15:$H$15,$A6)+INDEX(Inputs!$C$19:$H$19,$A6))/INDEX(Inputs!$C$25:$H$25,$A6)) | E6: =IF($B6="","",INDEX(Inputs!$C$24:$H$24,$A6)/INDEX(Inputs!$C$23:$H$23,$A6)) | F6: =IF($B6="","",INDEX(Inputs!$C$26:$H$26,$A6)) | G6: =IF($B6="","",INDEX(DCF!$C$60:$H$60,$A6)) | H6: =IF($B6="","",INDEX(DCF!$C$65:$H$65,$A6)) | I6: =IF($B6="","",INDEX(DCF!$C$66:$H$66,$A6)) | J6: =IF($B6="","",INDEX(Inputs!$C$27:$H$27,$A6)) | K6: =IF($B6="","",J6*H6+(1-J6)*I6) | L6: =IF($B6="","",H6*(1-Inputs!$B$8)) | M6: =IF($B6="","",MIN(K6,L6)) | N6: =IF($B6="","",M6/C6-1) | O6: =IF($B6="","",IF((INDEX(Inputs!$C$14:$H$14,$A6)*INDEX(Inputs!$C$15:$H$15,$A6)+INDEX(Inputs!$C$19:$H$19,$A6))/INDEX(Inputs!$C$25:$H$25,$A6)<ImpliedCalc!$L$4,"< -20%",IF((INDEX(Inputs!$C$14:$H$14,$A6)*INDEX(Inputs!$C$15:$H$15,$A6)+INDEX(Inputs!$C$19:$H$19,$A6))/INDEX(Inputs!$C$25:$H$25,$A6)>ImpliedCalc!$L$124,"> 40%",INDEX(ImpliedCalc!$A$4:$A$124,MATCH((INDEX(Inputs!$C$14:$H$14,$A6)*INDEX(Inputs!$C$15:$H$15,$A6)+INDEX(Inputs!$C$19:$H$19,$A6))/INDEX(Inputs!$C$25:$H$25,$A6),ImpliedCalc!$L$4:$L$124,1))))) | P6: =IF($B6="","",IF((INDEX(Inputs!$C$14:$H$14,$A6)*INDEX(Inputs!$C$15:$H$15,$A6)+INDEX(Inputs!$C$19:$H$19,$A6))/INDEX(Inputs!$C$25:$H$25,$A6)<ImpliedCalc!$M$4,"< -20%",IF((INDEX(Inputs!$C$14:$H$14,$A6)*INDEX(Inputs!$C$15:$H$15,$A6)+INDEX(Inputs!$C$19:$H$19,$A6))/INDEX(Inputs!$C$25:$H$25,$A6)>ImpliedCalc!$M$124,"> 40%",INDEX(ImpliedCalc!$A$4:$A$124,MATCH((INDEX(Inputs!$C$14:$H$14,$A6)*INDEX(Inputs!$C$15:$H$15,$A6)+INDEX(Inputs!$C$19:$H$19,$A6))/INDEX(Inputs!$C$25:$H$25,$A6),ImpliedCalc!$M$4:$M$124,1))))) | Q6: =IF($B6="","",IF(C6<=M6,"BUY ZONE",IF(C6<=M6*1.1,"WATCH","NO BUY")))
A7: 3 | B7: =IF(INDEX(Inputs!$C$12:$H$12,$A7)="","",INDEX(Inputs!$C$12:$H$12,$A7)) | C7: =IF($B7="","",INDEX(Inputs!$C$14:$H$14,$A7)) | D7: =IF($B7="","",(INDEX(Inputs!$C$14:$H$14,$A7)*INDEX(Inputs!$C$15:$H$15,$A7)+INDEX(Inputs!$C$19:$H$19,$A7))/INDEX(Inputs!$C$25:$H$25,$A7)) | E7: =IF($B7="","",INDEX(Inputs!$C$24:$H$24,$A7)/INDEX(Inputs!$C$23:$H$23,$A7)) | F7: =IF($B7="","",INDEX(Inputs!$C$26:$H$26,$A7)) | G7: =IF($B7="","",INDEX(DCF!$C$60:$H$60,$A7)) | H7: =IF($B7="","",INDEX(DCF!$C$65:$H$65,$A7)) | I7: =IF($B7="","",INDEX(DCF!$C$66:$H$66,$A7)) | J7: =IF($B7="","",INDEX(Inputs!$C$27:$H$27,$A7)) | K7: =IF($B7="","",J7*H7+(1-J7)*I7) | L7: =IF($B7="","",H7*(1-Inputs!$B$8)) | M7: =IF($B7="","",MIN(K7,L7)) | N7: =IF($B7="","",M7/C7-1) | O7: =IF($B7="","",IF((INDEX(Inputs!$C$14:$H$14,$A7)*INDEX(Inputs!$C$15:$H$15,$A7)+INDEX(Inputs!$C$19:$H$19,$A7))/INDEX(Inputs!$C$25:$H$25,$A7)<ImpliedCalc!$L$4,"< -20%",IF((INDEX(Inputs!$C$14:$H$14,$A7)*INDEX(Inputs!$C$15:$H$15,$A7)+INDEX(Inputs!$C$19:$H$19,$A7))/INDEX(Inputs!$C$25:$H$25,$A7)>ImpliedCalc!$L$124,"> 40%",INDEX(ImpliedCalc!$A$4:$A$124,MATCH((INDEX(Inputs!$C$14:$H$14,$A7)*INDEX(Inputs!$C$15:$H$15,$A7)+INDEX(Inputs!$C$19:$H$19,$A7))/INDEX(Inputs!$C$25:$H$25,$A7),ImpliedCalc!$L$4:$L$124,1))))) | P7: =IF($B7="","",IF((INDEX(Inputs!$C$14:$H$14,$A7)*INDEX(Inputs!$C$15:$H$15,$A7)+INDEX(Inputs!$C$19:$H$19,$A7))/INDEX(Inputs!$C$25:$H$25,$A7)<ImpliedCalc!$M$4,"< -20%",IF((INDEX(Inputs!$C$14:$H$14,$A7)*INDEX(Inputs!$C$15:$H$15,$A7)+INDEX(Inputs!$C$19:$H$19,$A7))/INDEX(Inputs!$C$25:$H$25,$A7)>ImpliedCalc!$M$124,"> 40%",INDEX(ImpliedCalc!$A$4:$A$124,MATCH((INDEX(Inputs!$C$14:$H$14,$A7)*INDEX(Inputs!$C$15:$H$15,$A7)+INDEX(Inputs!$C$19:$H$19,$A7))/INDEX(Inputs!$C$25:$H$25,$A7),ImpliedCalc!$M$4:$M$124,1))))) | Q7: =IF($B7="","",IF(C7<=M7,"BUY ZONE",IF(C7<=M7*1.1,"WATCH","NO BUY")))
A8: 4 | B8: =IF(INDEX(Inputs!$C$12:$H$12,$A8)="","",INDEX(Inputs!$C$12:$H$12,$A8)) | C8: =IF($B8="","",INDEX(Inputs!$C$14:$H$14,$A8)) | D8: =IF($B8="","",(INDEX(Inputs!$C$14:$H$14,$A8)*INDEX(Inputs!$C$15:$H$15,$A8)+INDEX(Inputs!$C$19:$H$19,$A8))/INDEX(Inputs!$C$25:$H$25,$A8)) | E8: =IF($B8="","",INDEX(Inputs!$C$24:$H$24,$A8)/INDEX(Inputs!$C$23:$H$23,$A8)) | F8: =IF($B8="","",INDEX(Inputs!$C$26:$H$26,$A8)) | G8: =IF($B8="","",INDEX(DCF!$C$60:$H$60,$A8)) | H8: =IF($B8="","",INDEX(DCF!$C$65:$H$65,$A8)) | I8: =IF($B8="","",INDEX(DCF!$C$66:$H$66,$A8)) | J8: =IF($B8="","",INDEX(Inputs!$C$27:$H$27,$A8)) | K8: =IF($B8="","",J8*H8+(1-J8)*I8) | L8: =IF($B8="","",H8*(1-Inputs!$B$8)) | M8: =IF($B8="","",MIN(K8,L8)) | N8: =IF($B8="","",M8/C8-1) | O8: =IF($B8="","",IF((INDEX(Inputs!$C$14:$H$14,$A8)*INDEX(Inputs!$C$15:$H$15,$A8)+INDEX(Inputs!$C$19:$H$19,$A8))/INDEX(Inputs!$C$25:$H$25,$A8)<ImpliedCalc!$L$4,"< -20%",IF((INDEX(Inputs!$C$14:$H$14,$A8)*INDEX(Inputs!$C$15:$H$15,$A8)+INDEX(Inputs!$C$19:$H$19,$A8))/INDEX(Inputs!$C$25:$H$25,$A8)>ImpliedCalc!$L$124,"> 40%",INDEX(ImpliedCalc!$A$4:$A$124,MATCH((INDEX(Inputs!$C$14:$H$14,$A8)*INDEX(Inputs!$C$15:$H$15,$A8)+INDEX(Inputs!$C$19:$H$19,$A8))/INDEX(Inputs!$C$25:$H$25,$A8),ImpliedCalc!$L$4:$L$124,1))))) | P8: =IF($B8="","",IF((INDEX(Inputs!$C$14:$H$14,$A8)*INDEX(Inputs!$C$15:$H$15,$A8)+INDEX(Inputs!$C$19:$H$19,$A8))/INDEX(Inputs!$C$25:$H$25,$A8)<ImpliedCalc!$M$4,"< -20%",IF((INDEX(Inputs!$C$14:$H$14,$A8)*INDEX(Inputs!$C$15:$H$15,$A8)+INDEX(Inputs!$C$19:$H$19,$A8))/INDEX(Inputs!$C$25:$H$25,$A8)>ImpliedCalc!$M$124,"> 40%",INDEX(ImpliedCalc!$A$4:$A$124,MATCH((INDEX(Inputs!$C$14:$H$14,$A8)*INDEX(Inputs!$C$15:$H$15,$A8)+INDEX(Inputs!$C$19:$H$19,$A8))/INDEX(Inputs!$C$25:$H$25,$A8),ImpliedCalc!$M$4:$M$124,1))))) | Q8: =IF($B8="","",IF(C8<=M8,"BUY ZONE",IF(C8<=M8*1.1,"WATCH","NO BUY")))
A9: 5 | B9: =IF(INDEX(Inputs!$C$12:$H$12,$A9)="","",INDEX(Inputs!$C$12:$H$12,$A9)) | C9: =IF($B9="","",INDEX(Inputs!$C$14:$H$14,$A9)) | D9: =IF($B9="","",(INDEX(Inputs!$C$14:$H$14,$A9)*INDEX(Inputs!$C$15:$H$15,$A9)+INDEX(Inputs!$C$19:$H$19,$A9))/INDEX(Inputs!$C$25:$H$25,$A9)) | E9: =IF($B9="","",INDEX(Inputs!$C$24:$H$24,$A9)/INDEX(Inputs!$C$23:$H$23,$A9)) | F9: =IF($B9="","",INDEX(Inputs!$C$26:$H$26,$A9)) | G9: =IF($B9="","",INDEX(DCF!$C$60:$H$60,$A9)) | H9: =IF($B9="","",INDEX(DCF!$C$65:$H$65,$A9)) | I9: =IF($B9="","",INDEX(DCF!$C$66:$H$66,$A9)) | J9: =IF($B9="","",INDEX(Inputs!$C$27:$H$27,$A9)) | K9: =IF($B9="","",J9*H9+(1-J9)*I9) | L9: =IF($B9="","",H9*(1-Inputs!$B$8)) | M9: =IF($B9="","",MIN(K9,L9)) | N9: =IF($B9="","",M9/C9-1) | O9: =IF($B9="","",IF((INDEX(Inputs!$C$14:$H$14,$A9)*INDEX(Inputs!$C$15:$H$15,$A9)+INDEX(Inputs!$C$19:$H$19,$A9))/INDEX(Inputs!$C$25:$H$25,$A9)<ImpliedCalc!$L$4,"< -20%",IF((INDEX(Inputs!$C$14:$H$14,$A9)*INDEX(Inputs!$C$15:$H$15,$A9)+INDEX(Inputs!$C$19:$H$19,$A9))/INDEX(Inputs!$C$25:$H$25,$A9)>ImpliedCalc!$L$124,"> 40%",INDEX(ImpliedCalc!$A$4:$A$124,MATCH((INDEX(Inputs!$C$14:$H$14,$A9)*INDEX(Inputs!$C$15:$H$15,$A9)+INDEX(Inputs!$C$19:$H$19,$A9))/INDEX(Inputs!$C$25:$H$25,$A9),ImpliedCalc!$L$4:$L$124,1))))) | P9: =IF($B9="","",IF((INDEX(Inputs!$C$14:$H$14,$A9)*INDEX(Inputs!$C$15:$H$15,$A9)+INDEX(Inputs!$C$19:$H$19,$A9))/INDEX(Inputs!$C$25:$H$25,$A9)<ImpliedCalc!$M$4,"< -20%",IF((INDEX(Inputs!$C$14:$H$14,$A9)*INDEX(Inputs!$C$15:$H$15,$A9)+INDEX(Inputs!$C$19:$H$19,$A9))/INDEX(Inputs!$C$25:$H$25,$A9)>ImpliedCalc!$M$124,"> 40%",INDEX(ImpliedCalc!$A$4:$A$124,MATCH((INDEX(Inputs!$C$14:$H$14,$A9)*INDEX(Inputs!$C$15:$H$15,$A9)+INDEX(Inputs!$C$19:$H$19,$A9))/INDEX(Inputs!$C$25:$H$25,$A9),ImpliedCalc!$M$4:$M$124,1))))) | Q9: =IF($B9="","",IF(C9<=M9,"BUY ZONE",IF(C9<=M9*1.1,"WATCH","NO BUY")))
A10: 6 | B10: =IF(INDEX(Inputs!$C$12:$H$12,$A10)="","",INDEX(Inputs!$C$12:$H$12,$A10)) | C10: =IF($B10="","",INDEX(Inputs!$C$14:$H$14,$A10)) | D10: =IF($B10="","",(INDEX(Inputs!$C$14:$H$14,$A10)*INDEX(Inputs!$C$15:$H$15,$A10)+INDEX(Inputs!$C$19:$H$19,$A10))/INDEX(Inputs!$C$25:$H$25,$A10)) | E10: =IF($B10="","",INDEX(Inputs!$C$24:$H$24,$A10)/INDEX(Inputs!$C$23:$H$23,$A10)) | F10: =IF($B10="","",INDEX(Inputs!$C$26:$H$26,$A10)) | G10: =IF($B10="","",INDEX(DCF!$C$60:$H$60,$A10)) | H10: =IF($B10="","",INDEX(DCF!$C$65:$H$65,$A10)) | I10: =IF($B10="","",INDEX(DCF!$C$66:$H$66,$A10)) | J10: =IF($B10="","",INDEX(Inputs!$C$27:$H$27,$A10)) | K10: =IF($B10="","",J10*H10+(1-J10)*I10) | L10: =IF($B10="","",H10*(1-Inputs!$B$8)) | M10: =IF($B10="","",MIN(K10,L10)) | N10: =IF($B10="","",M10/C10-1) | O10: =IF($B10="","",IF((INDEX(Inputs!$C$14:$H$14,$A10)*INDEX(Inputs!$C$15:$H$15,$A10)+INDEX(Inputs!$C$19:$H$19,$A10))/INDEX(Inputs!$C$25:$H$25,$A10)<ImpliedCalc!$L$4,"< -20%",IF((INDEX(Inputs!$C$14:$H$14,$A10)*INDEX(Inputs!$C$15:$H$15,$A10)+INDEX(Inputs!$C$19:$H$19,$A10))/INDEX(Inputs!$C$25:$H$25,$A10)>ImpliedCalc!$L$124,"> 40%",INDEX(ImpliedCalc!$A$4:$A$124,MATCH((INDEX(Inputs!$C$14:$H$14,$A10)*INDEX(Inputs!$C$15:$H$15,$A10)+INDEX(Inputs!$C$19:$H$19,$A10))/INDEX(Inputs!$C$25:$H$25,$A10),ImpliedCalc!$L$4:$L$124,1))))) | P10: =IF($B10="","",IF((INDEX(Inputs!$C$14:$H$14,$A10)*INDEX(Inputs!$C$15:$H$15,$A10)+INDEX(Inputs!$C$19:$H$19,$A10))/INDEX(Inputs!$C$25:$H$25,$A10)<ImpliedCalc!$M$4,"< -20%",IF((INDEX(Inputs!$C$14:$H$14,$A10)*INDEX(Inputs!$C$15:$H$15,$A10)+INDEX(Inputs!$C$19:$H$19,$A10))/INDEX(Inputs!$C$25:$H$25,$A10)>ImpliedCalc!$M$124,"> 40%",INDEX(ImpliedCalc!$A$4:$A$124,MATCH((INDEX(Inputs!$C$14:$H$14,$A10)*INDEX(Inputs!$C$15:$H$15,$A10)+INDEX(Inputs!$C$19:$H$19,$A10))/INDEX(Inputs!$C$25:$H$25,$A10),ImpliedCalc!$M$4:$M$124,1))))) | Q10: =IF($B10="","",IF(C10<=M10,"BUY ZONE",IF(C10<=M10*1.1,"WATCH","NO BUY")))
A12: Buy below = MIN(weighted value, going-concern × (1 − MOS)), both at the conservative discount rate. Verdict: BUY ZONE if price ≤ buy-below; WATCH if within 10% above; else NO BUY.
A13: Implied growth = starting growth at which going-concern value equals today's price (0.5% steps). Compare with guidance: far above guidance = market optimistic; below = market pessimistic.
A15: P(durable) sensitivity of weighted value (cons. r)
B16: Ticker | C16: 0.3 | D16: 0.5 | E16: 0.7 | F16: 0.9
B17: =B5 | C17: =IF($B17="","",C$16*$H5+(1-C$16)*$I5) | D17: =IF($B17="","",D$16*$H5+(1-D$16)*$I5) | E17: =IF($B17="","",E$16*$H5+(1-E$16)*$I5) | F17: =IF($B17="","",F$16*$H5+(1-F$16)*$I5)
B18: =B6 | C18: =IF($B18="","",C$16*$H6+(1-C$16)*$I6) | D18: =IF($B18="","",D$16*$H6+(1-D$16)*$I6) | E18: =IF($B18="","",E$16*$H6+(1-E$16)*$I6) | F18: =IF($B18="","",F$16*$H6+(1-F$16)*$I6)
B19: =B7 | C19: =IF($B19="","",C$16*$H7+(1-C$16)*$I7) | D19: =IF($B19="","",D$16*$H7+(1-D$16)*$I7) | E19: =IF($B19="","",E$16*$H7+(1-E$16)*$I7) | F19: =IF($B19="","",F$16*$H7+(1-F$16)*$I7)
B20: =B8 | C20: =IF($B20="","",C$16*$H8+(1-C$16)*$I8) | D20: =IF($B20="","",D$16*$H8+(1-D$16)*$I8) | E20: =IF($B20="","",E$16*$H8+(1-E$16)*$I8) | F20: =IF($B20="","",F$16*$H8+(1-F$16)*$I8)
B21: =B9 | C21: =IF($B21="","",C$16*$H9+(1-C$16)*$I9) | D21: =IF($B21="","",D$16*$H9+(1-D$16)*$I9) | E21: =IF($B21="","",E$16*$H9+(1-E$16)*$I9) | F21: =IF($B21="","",F$16*$H9+(1-F$16)*$I9)
B22: =B10 | C22: =IF($B22="","",C$16*$H10+(1-C$16)*$I10) | D22: =IF($B22="","",D$16*$H10+(1-D$16)*$I10) | E22: =IF($B22="","",E$16*$H10+(1-E$16)*$I10) | F22: =IF($B22="","",F$16*$H10+(1-F$16)*$I10)

Sheet Sensitivity
A1: Sensitivity — going-concern value per share
A3: Pick ticker: | B3: INTU
A4: Slot | B4: =MATCH(B3,Inputs!$C$12:$H$12,0)
A5: Price | B5: =INDEX(Inputs!$C$14:$H$14,B4)
A6: Owner FCF ($mm) | B6: =INDEX(Inputs!$C$25:$H$25,B4)
A7: Net debt ($mm) | B7: =INDEX(Inputs!$C$19:$H$19,B4)
A8: Shares (mm) | B8: =INDEX(Inputs!$C$15:$H$15,B4)
A10: Discount rate ↓ / Starting growth → (edit the blue/yellow cells)
B11: -0.05 | C11: 0 | D11: 0.05 | E11: 0.09 | F11: 0.13 | G11: 0.17
A12: 0.085 | B12: =IF($B$4="","",($B$6*(SUMPRODUCT(B$27:B$36,1/(1+$A12)^$A$27:$A$36)+B$36*(1+Inputs!$B$6)/($A12-Inputs!$B$6)/(1+$A12)^10)-$B$7)/$B$8) | C12: =IF($B$4="","",($B$6*(SUMPRODUCT(C$27:C$36,1/(1+$A12)^$A$27:$A$36)+C$36*(1+Inputs!$B$6)/($A12-Inputs!$B$6)/(1+$A12)^10)-$B$7)/$B$8) | D12: =IF($B$4="","",($B$6*(SUMPRODUCT(D$27:D$36,1/(1+$A12)^$A$27:$A$36)+D$36*(1+Inputs!$B$6)/($A12-Inputs!$B$6)/(1+$A12)^10)-$B$7)/$B$8) | E12: =IF($B$4="","",($B$6*(SUMPRODUCT(E$27:E$36,1/(1+$A12)^$A$27:$A$36)+E$36*(1+Inputs!$B$6)/($A12-Inputs!$B$6)/(1+$A12)^10)-$B$7)/$B$8) | F12: =IF($B$4="","",($B$6*(SUMPRODUCT(F$27:F$36,1/(1+$A12)^$A$27:$A$36)+F$36*(1+Inputs!$B$6)/($A12-Inputs!$B$6)/(1+$A12)^10)-$B$7)/$B$8) | G12: =IF($B$4="","",($B$6*(SUMPRODUCT(G$27:G$36,1/(1+$A12)^$A$27:$A$36)+G$36*(1+Inputs!$B$6)/($A12-Inputs!$B$6)/(1+$A12)^10)-$B$7)/$B$8)
A13: 0.095 | B13: =IF($B$4="","",($B$6*(SUMPRODUCT(B$27:B$36,1/(1+$A13)^$A$27:$A$36)+B$36*(1+Inputs!$B$6)/($A13-Inputs!$B$6)/(1+$A13)^10)-$B$7)/$B$8) | C13: =IF($B$4="","",($B$6*(SUMPRODUCT(C$27:C$36,1/(1+$A13)^$A$27:$A$36)+C$36*(1+Inputs!$B$6)/($A13-Inputs!$B$6)/(1+$A13)^10)-$B$7)/$B$8) | D13: =IF($B$4="","",($B$6*(SUMPRODUCT(D$27:D$36,1/(1+$A13)^$A$27:$A$36)+D$36*(1+Inputs!$B$6)/($A13-Inputs!$B$6)/(1+$A13)^10)-$B$7)/$B$8) | E13: =IF($B$4="","",($B$6*(SUMPRODUCT(E$27:E$36,1/(1+$A13)^$A$27:$A$36)+E$36*(1+Inputs!$B$6)/($A13-Inputs!$B$6)/(1+$A13)^10)-$B$7)/$B$8) | F13: =IF($B$4="","",($B$6*(SUMPRODUCT(F$27:F$36,1/(1+$A13)^$A$27:$A$36)+F$36*(1+Inputs!$B$6)/($A13-Inputs!$B$6)/(1+$A13)^10)-$B$7)/$B$8) | G13: =IF($B$4="","",($B$6*(SUMPRODUCT(G$27:G$36,1/(1+$A13)^$A$27:$A$36)+G$36*(1+Inputs!$B$6)/($A13-Inputs!$B$6)/(1+$A13)^10)-$B$7)/$B$8)
A14: 0.105 | B14: =IF($B$4="","",($B$6*(SUMPRODUCT(B$27:B$36,1/(1+$A14)^$A$27:$A$36)+B$36*(1+Inputs!$B$6)/($A14-Inputs!$B$6)/(1+$A14)^10)-$B$7)/$B$8) | C14: =IF($B$4="","",($B$6*(SUMPRODUCT(C$27:C$36,1/(1+$A14)^$A$27:$A$36)+C$36*(1+Inputs!$B$6)/($A14-Inputs!$B$6)/(1+$A14)^10)-$B$7)/$B$8) | D14: =IF($B$4="","",($B$6*(SUMPRODUCT(D$27:D$36,1/(1+$A14)^$A$27:$A$36)+D$36*(1+Inputs!$B$6)/($A14-Inputs!$B$6)/(1+$A14)^10)-$B$7)/$B$8) | E14: =IF($B$4="","",($B$6*(SUMPRODUCT(E$27:E$36,1/(1+$A14)^$A$27:$A$36)+E$36*(1+Inputs!$B$6)/($A14-Inputs!$B$6)/(1+$A14)^10)-$B$7)/$B$8) | F14: =IF($B$4="","",($B$6*(SUMPRODUCT(F$27:F$36,1/(1+$A14)^$A$27:$A$36)+F$36*(1+Inputs!$B$6)/($A14-Inputs!$B$6)/(1+$A14)^10)-$B$7)/$B$8) | G14: =IF($B$4="","",($B$6*(SUMPRODUCT(G$27:G$36,1/(1+$A14)^$A$27:$A$36)+G$36*(1+Inputs!$B$6)/($A14-Inputs!$B$6)/(1+$A14)^10)-$B$7)/$B$8)
A15: 0.115 | B15: =IF($B$4="","",($B$6*(SUMPRODUCT(B$27:B$36,1/(1+$A15)^$A$27:$A$36)+B$36*(1+Inputs!$B$6)/($A15-Inputs!$B$6)/(1+$A15)^10)-$B$7)/$B$8) | C15: =IF($B$4="","",($B$6*(SUMPRODUCT(C$27:C$36,1/(1+$A15)^$A$27:$A$36)+C$36*(1+Inputs!$B$6)/($A15-Inputs!$B$6)/(1+$A15)^10)-$B$7)/$B$8) | D15: =IF($B$4="","",($B$6*(SUMPRODUCT(D$27:D$36,1/(1+$A15)^$A$27:$A$36)+D$36*(1+Inputs!$B$6)/($A15-Inputs!$B$6)/(1+$A15)^10)-$B$7)/$B$8) | E15: =IF($B$4="","",($B$6*(SUMPRODUCT(E$27:E$36,1/(1+$A15)^$A$27:$A$36)+E$36*(1+Inputs!$B$6)/($A15-Inputs!$B$6)/(1+$A15)^10)-$B$7)/$B$8) | F15: =IF($B$4="","",($B$6*(SUMPRODUCT(F$27:F$36,1/(1+$A15)^$A$27:$A$36)+F$36*(1+Inputs!$B$6)/($A15-Inputs!$B$6)/(1+$A15)^10)-$B$7)/$B$8) | G15: =IF($B$4="","",($B$6*(SUMPRODUCT(G$27:G$36,1/(1+$A15)^$A$27:$A$36)+G$36*(1+Inputs!$B$6)/($A15-Inputs!$B$6)/(1+$A15)^10)-$B$7)/$B$8)
A16: 0.125 | B16: =IF($B$4="","",($B$6*(SUMPRODUCT(B$27:B$36,1/(1+$A16)^$A$27:$A$36)+B$36*(1+Inputs!$B$6)/($A16-Inputs!$B$6)/(1+$A16)^10)-$B$7)/$B$8) | C16: =IF($B$4="","",($B$6*(SUMPRODUCT(C$27:C$36,1/(1+$A16)^$A$27:$A$36)+C$36*(1+Inputs!$B$6)/($A16-Inputs!$B$6)/(1+$A16)^10)-$B$7)/$B$8) | D16: =IF($B$4="","",($B$6*(SUMPRODUCT(D$27:D$36,1/(1+$A16)^$A$27:$A$36)+D$36*(1+Inputs!$B$6)/($A16-Inputs!$B$6)/(1+$A16)^10)-$B$7)/$B$8) | E16: =IF($B$4="","",($B$6*(SUMPRODUCT(E$27:E$36,1/(1+$A16)^$A$27:$A$36)+E$36*(1+Inputs!$B$6)/($A16-Inputs!$B$6)/(1+$A16)^10)-$B$7)/$B$8) | F16: =IF($B$4="","",($B$6*(SUMPRODUCT(F$27:F$36,1/(1+$A16)^$A$27:$A$36)+F$36*(1+Inputs!$B$6)/($A16-Inputs!$B$6)/(1+$A16)^10)-$B$7)/$B$8) | G16: =IF($B$4="","",($B$6*(SUMPRODUCT(G$27:G$36,1/(1+$A16)^$A$27:$A$36)+G$36*(1+Inputs!$B$6)/($A16-Inputs!$B$6)/(1+$A16)^10)-$B$7)/$B$8)
A18: Green = value above today's price; red = below. Terminal growth comes from Inputs!B6; change it there to test 2% vs 3%.
A25: Helper: cumulative growth factors per column (do not edit)
A26: Year | B26: =B11 | C26: =C11 | D26: =D11 | E26: =E11 | F26: =F11 | G26: =G11
A27: 1 | B27: =1*(1+B$11+(Inputs!$B$6-B$11)*($A27-1)/9) | C27: =1*(1+C$11+(Inputs!$B$6-C$11)*($A27-1)/9) | D27: =1*(1+D$11+(Inputs!$B$6-D$11)*($A27-1)/9) | E27: =1*(1+E$11+(Inputs!$B$6-E$11)*($A27-1)/9) | F27: =1*(1+F$11+(Inputs!$B$6-F$11)*($A27-1)/9) | G27: =1*(1+G$11+(Inputs!$B$6-G$11)*($A27-1)/9)
A28: 2 | B28: =B27*(1+B$11+(Inputs!$B$6-B$11)*($A28-1)/9) | C28: =C27*(1+C$11+(Inputs!$B$6-C$11)*($A28-1)/9) | D28: =D27*(1+D$11+(Inputs!$B$6-D$11)*($A28-1)/9) | E28: =E27*(1+E$11+(Inputs!$B$6-E$11)*($A28-1)/9) | F28: =F27*(1+F$11+(Inputs!$B$6-F$11)*($A28-1)/9) | G28: =G27*(1+G$11+(Inputs!$B$6-G$11)*($A28-1)/9)
A29: 3 | B29: =B28*(1+B$11+(Inputs!$B$6-B$11)*($A29-1)/9) | C29: =C28*(1+C$11+(Inputs!$B$6-C$11)*($A29-1)/9) | D29: =D28*(1+D$11+(Inputs!$B$6-D$11)*($A29-1)/9) | E29: =E28*(1+E$11+(Inputs!$B$6-E$11)*($A29-1)/9) | F29: =F28*(1+F$11+(Inputs!$B$6-F$11)*($A29-1)/9) | G29: =G28*(1+G$11+(Inputs!$B$6-G$11)*($A29-1)/9)
A30: 4 | B30: =B29*(1+B$11+(Inputs!$B$6-B$11)*($A30-1)/9) | C30: =C29*(1+C$11+(Inputs!$B$6-C$11)*($A30-1)/9) | D30: =D29*(1+D$11+(Inputs!$B$6-D$11)*($A30-1)/9) | E30: =E29*(1+E$11+(Inputs!$B$6-E$11)*($A30-1)/9) | F30: =F29*(1+F$11+(Inputs!$B$6-F$11)*($A30-1)/9) | G30: =G29*(1+G$11+(Inputs!$B$6-G$11)*($A30-1)/9)
A31: 5 | B31: =B30*(1+B$11+(Inputs!$B$6-B$11)*($A31-1)/9) | C31: =C30*(1+C$11+(Inputs!$B$6-C$11)*($A31-1)/9) | D31: =D30*(1+D$11+(Inputs!$B$6-D$11)*($A31-1)/9) | E31: =E30*(1+E$11+(Inputs!$B$6-E$11)*($A31-1)/9) | F31: =F30*(1+F$11+(Inputs!$B$6-F$11)*($A31-1)/9) | G31: =G30*(1+G$11+(Inputs!$B$6-G$11)*($A31-1)/9)
A32: 6 | B32: =B31*(1+B$11+(Inputs!$B$6-B$11)*($A32-1)/9) | C32: =C31*(1+C$11+(Inputs!$B$6-C$11)*($A32-1)/9) | D32: =D31*(1+D$11+(Inputs!$B$6-D$11)*($A32-1)/9) | E32: =E31*(1+E$11+(Inputs!$B$6-E$11)*($A32-1)/9) | F32: =F31*(1+F$11+(Inputs!$B$6-F$11)*($A32-1)/9) | G32: =G31*(1+G$11+(Inputs!$B$6-G$11)*($A32-1)/9)
A33: 7 | B33: =B32*(1+B$11+(Inputs!$B$6-B$11)*($A33-1)/9) | C33: =C32*(1+C$11+(Inputs!$B$6-C$11)*($A33-1)/9) | D33: =D32*(1+D$11+(Inputs!$B$6-D$11)*($A33-1)/9) | E33: =E32*(1+E$11+(Inputs!$B$6-E$11)*($A33-1)/9) | F33: =F32*(1+F$11+(Inputs!$B$6-F$11)*($A33-1)/9) | G33: =G32*(1+G$11+(Inputs!$B$6-G$11)*($A33-1)/9)
A34: 8 | B34: =B33*(1+B$11+(Inputs!$B$6-B$11)*($A34-1)/9) | C34: =C33*(1+C$11+(Inputs!$B$6-C$11)*($A34-1)/9) | D34: =D33*(1+D$11+(Inputs!$B$6-D$11)*($A34-1)/9) | E34: =E33*(1+E$11+(Inputs!$B$6-E$11)*($A34-1)/9) | F34: =F33*(1+F$11+(Inputs!$B$6-F$11)*($A34-1)/9) | G34: =G33*(1+G$11+(Inputs!$B$6-G$11)*($A34-1)/9)
A35: 9 | B35: =B34*(1+B$11+(Inputs!$B$6-B$11)*($A35-1)/9) | C35: =C34*(1+C$11+(Inputs!$B$6-C$11)*($A35-1)/9) | D35: =D34*(1+D$11+(Inputs!$B$6-D$11)*($A35-1)/9) | E35: =E34*(1+E$11+(Inputs!$B$6-E$11)*($A35-1)/9) | F35: =F34*(1+F$11+(Inputs!$B$6-F$11)*($A35-1)/9) | G35: =G34*(1+G$11+(Inputs!$B$6-G$11)*($A35-1)/9)
A36: 10 | B36: =B35*(1+B$11+(Inputs!$B$6-B$11)*($A36-1)/9) | C36: =C35*(1+C$11+(Inputs!$B$6-C$11)*($A36-1)/9) | D36: =D35*(1+D$11+(Inputs!$B$6-D$11)*($A36-1)/9) | E36: =E35*(1+E$11+(Inputs!$B$6-E$11)*($A36-1)/9) | F36: =F35*(1+F$11+(Inputs!$B$6-F$11)*($A36-1)/9) | G36: =G35*(1+G$11+(Inputs!$B$6-G$11)*($A36-1)/9)

Sheet Inputs
A1: Inputs — edit BLUE cells only
A3: GLOBAL ASSUMPTIONS
A4: Base discount rate | B4: 0.095 | I4: Typical large-cap software cost of equity; CAPM with raw betas 1.3–1.5 gives ~10–11%.
A5: Conservative discount rate (used for buy price) | B5: 0.105 | I5: Higher hurdle used for weighted value and buy-below price.
A6: Terminal growth | B6: 0.03 | I6: Perpetual growth after year 10. 2% cuts value ~11% vs 3%.
A7: Bear case: annual owner-FCF decline | B7: 0.05 | I7: Structural-decline scenario (e.g., AI disruption).
A8: Margin of safety on going-concern value | B8: 0.3 | I8: Buy-below cross-check: going-concern × (1 − this).
A10: COMPANY INPUTS
A11: Item | B11: Units | C11: Slot 1 | D11: Slot 2 | E11: Slot 3 | F11: Slot 4 | G11: Slot 5 | H11: Slot 6 | I11: Notes
A12: Ticker | B12: text | C12: INTU | D12: ADBE | E12: ADSK | F12: CRM
A13: Price date | B13: text | C13: 2026-09-26 | D13: 2026-09-26 | E13: 2026-09-26 | F13: 2026-09-26
A14: Share price | B14: $ | C14: 275.79 | D14: 235.47 | E14: 209.4 | F14: 234.02
A15: Diluted shares | B15: mm | C15: 267 | D15: 396 | E15: 214 | F15: 821 | I15: Use latest diluted count (CRM fell 962M→821M after the ASR).
A16: Total debt | B16: $mm | C16: 7700 | D16: 6360 | E16: 3980 | F16: 39500
A17: Cash & investments | B17: $mm | C17: 7200 | D17: 5640 | E17: 1830 | F17: 11400
A18: Other claims (pending deals, etc.) | B18: $mm | C18: 0 | D18: 0 | E18: 0 | F18: 1500 | I18: Pending cash acquisitions, underfunded pensions, etc.
A19: Net debt | B19: $mm | C19: =IF(C12="","",C16-C17+C18) | D19: =IF(D12="","",D16-D17+D18) | E19: =IF(E12="","",E16-E17+E18) | F19: =IF(F12="","",F16-F17+F18) | G19: =IF(G12="","",G16-G17+G18) | H19: =IF(H12="","",H16-H17+H18)
A20: Reported FCF (OCF − capex), TTM or guided | B20: $mm | C20: 8620 | D20: 10500 | E20: 2740 | F20: 15050
A21: One-time items to remove | B21: $mm | C21: 1120 | D21: 0 | E21: 0 | F21: 0 | I21: Remove non-recurring cash (e.g., INTU FY26 R&D tax catch-up, EST $1.12B).
A22: After-tax net interest add-back (unlevered) | B22: $mm | C22: 0 | D22: 0 | E22: 0 | F22: 950 | I22: Use if FCF is after big interest costs and you subtract net debt (avoids double count).
A23: Normalized FCF | B23: $mm | C23: =IF(C12="","",C20-C21+C22) | D23: =IF(D12="","",D20-D21+D22) | E23: =IF(E12="","",E20-E21+E22) | F23: =IF(F12="","",F20-F21+F22) | G23: =IF(G12="","",G20-G21+G22) | H23: =IF(H12="","",H20-H21+H22)
A24: Stock-based compensation | B24: $mm | C24: 1900 | D24: 2100 | E24: 850 | F24: 3600
A25: Owner FCF (normalized FCF − SBC) | B25: $mm | C25: =IF(C12="","",C23-C24) | D25: =IF(D12="","",D23-D24) | E25: =IF(E12="","",E23-E24) | F25: =IF(F12="","",F23-F24) | G25: =IF(G12="","",G23-G24) | H25: =IF(H12="","",H23-H24)
A26: Starting growth (year 1) | B26: % | C26: 0.09 | D26: 0.1 | E26: 0.12 | F26: 0.09 | I26: Anchor to revenue/FCF guidance; fades linearly to terminal growth by year 10.
A27: P(durable) — judgment | B27: % | C27: 0.5 | D27: 0.5 | E27: 0.8 | F27: 0.8 | I27: Your probability the business stays a durable going concern (vs structural decline). Biggest driver for INTU/ADBE.
A28: FCF period / basis | B28: text | C28: FY26 (Jul-26) reported | D28: TTM to Aug-26 (est.) | E28: FY27 (Jan-27) guidance midpoint | F28: FY27 (Jan-27) guidance (+4-5%)
A29: Last updated | B29: text | C29: 2026-09-27 | D29: 2026-09-27 | E29: 2026-09-27 | F29: 2026-09-27
A30: Source notes | B30: text | C30: FY26 10-K/Q4 release: OCF $8.84B, capex $221M, cash+inv $7.2B, debt $7.7B. One-time = EST R&D-expensing tax catch-up. SBC ~$1.7-2.1B. FY27 rev guide +9-10%. | D30: Q3 FY26 10-Q (Aug-28-26): cash $4.36B + ST inv $1.28B; debt $6.36B. TTM FCF ~$10.3-10.5B. SBC ~$2.1B/yr. FY26 rev ~+12%, ARR +11.2%. | E30: Q2 FY27 10-Q: cash $4.36B, debt $2.98B; then MaintainX $3.53B paid Aug-3 with $1.0B term loan (EST post-deal). FY27 FCF guide $2.725-2.75B; SBC FY26 $788M. | F30: Q2 FY27: cash $8.31B + securities $3.09B; debt ~$39.5B after $25B ASR; Contentful $1.5B pending. FY27 FCF guide +4-5% on $14.4B. Interest add-back EST. Diluted shares 821M.

Sheet DCF
A1: DCF engine — all formulas (no inputs here)
A3: Line | B3: Year | C3: Slot 1 | D3: Slot 2 | E3: Slot 3 | F3: Slot 4 | G3: Slot 5 | H3: Slot 6
A4: Ticker | C4: =IF(Inputs!C12="","",Inputs!C12) | D4: =IF(Inputs!D12="","",Inputs!D12) | E4: =IF(Inputs!E12="","",Inputs!E12) | F4: =IF(Inputs!F12="","",Inputs!F12) | G4: =IF(Inputs!G12="","",Inputs!G12) | H4: =IF(Inputs!H12="","",Inputs!H12)
A5: Owner FCF, year 0 ($mm) | C5: =IF(C$4="","",Inputs!C25) | D5: =IF(D$4="","",Inputs!D25) | E5: =IF(E$4="","",Inputs!E25) | F5: =IF(F$4="","",Inputs!F25) | G5: =IF(G$4="","",Inputs!G25) | H5: =IF(H$4="","",Inputs!H25)
A6: Starting growth | C6: =IF(C$4="","",Inputs!C26) | D6: =IF(D$4="","",Inputs!D26) | E6: =IF(E$4="","",Inputs!E26) | F6: =IF(F$4="","",Inputs!F26) | G6: =IF(G$4="","",Inputs!G26) | H6: =IF(H$4="","",Inputs!H26)
A8: Growth rate by year
A9: Year 1 | B9: 1 | C9: =IF(C$4="","",C$6+(Inputs!$B$6-C$6)*($B9-1)/9) | D9: =IF(D$4="","",D$6+(Inputs!$B$6-D$6)*($B9-1)/9) | E9: =IF(E$4="","",E$6+(Inputs!$B$6-E$6)*($B9-1)/9) | F9: =IF(F$4="","",F$6+(Inputs!$B$6-F$6)*($B9-1)/9) | G9: =IF(G$4="","",G$6+(Inputs!$B$6-G$6)*($B9-1)/9) | H9: =IF(H$4="","",H$6+(Inputs!$B$6-H$6)*($B9-1)/9)
A10: Year 2 | B10: 2 | C10: =IF(C$4="","",C$6+(Inputs!$B$6-C$6)*($B10-1)/9) | D10: =IF(D$4="","",D$6+(Inputs!$B$6-D$6)*($B10-1)/9) | E10: =IF(E$4="","",E$6+(Inputs!$B$6-E$6)*($B10-1)/9) | F10: =IF(F$4="","",F$6+(Inputs!$B$6-F$6)*($B10-1)/9) | G10: =IF(G$4="","",G$6+(Inputs!$B$6-G$6)*($B10-1)/9) | H10: =IF(H$4="","",H$6+(Inputs!$B$6-H$6)*($B10-1)/9)
A11: Year 3 | B11: 3 | C11: =IF(C$4="","",C$6+(Inputs!$B$6-C$6)*($B11-1)/9) | D11: =IF(D$4="","",D$6+(Inputs!$B$6-D$6)*($B11-1)/9) | E11: =IF(E$4="","",E$6+(Inputs!$B$6-E$6)*($B11-1)/9) | F11: =IF(F$4="","",F$6+(Inputs!$B$6-F$6)*($B11-1)/9) | G11: =IF(G$4="","",G$6+(Inputs!$B$6-G$6)*($B11-1)/9) | H11: =IF(H$4="","",H$6+(Inputs!$B$6-H$6)*($B11-1)/9)
A12: Year 4 | B12: 4 | C12: =IF(C$4="","",C$6+(Inputs!$B$6-C$6)*($B12-1)/9) | D12: =IF(D$4="","",D$6+(Inputs!$B$6-D$6)*($B12-1)/9) | E12: =IF(E$4="","",E$6+(Inputs!$B$6-E$6)*($B12-1)/9) | F12: =IF(F$4="","",F$6+(Inputs!$B$6-F$6)*($B12-1)/9) | G12: =IF(G$4="","",G$6+(Inputs!$B$6-G$6)*($B12-1)/9) | H12: =IF(H$4="","",H$6+(Inputs!$B$6-H$6)*($B12-1)/9)
A13: Year 5 | B13: 5 | C13: =IF(C$4="","",C$6+(Inputs!$B$6-C$6)*($B13-1)/9) | D13: =IF(D$4="","",D$6+(Inputs!$B$6-D$6)*($B13-1)/9) | E13: =IF(E$4="","",E$6+(Inputs!$B$6-E$6)*($B13-1)/9) | F13: =IF(F$4="","",F$6+(Inputs!$B$6-F$6)*($B13-1)/9) | G13: =IF(G$4="","",G$6+(Inputs!$B$6-G$6)*($B13-1)/9) | H13: =IF(H$4="","",H$6+(Inputs!$B$6-H$6)*($B13-1)/9)
A14: Year 6 | B14: 6 | C14: =IF(C$4="","",C$6+(Inputs!$B$6-C$6)*($B14-1)/9) | D14: =IF(D$4="","",D$6+(Inputs!$B$6-D$6)*($B14-1)/9) | E14: =IF(E$4="","",E$6+(Inputs!$B$6-E$6)*($B14-1)/9) | F14: =IF(F$4="","",F$6+(Inputs!$B$6-F$6)*($B14-1)/9) | G14: =IF(G$4="","",G$6+(Inputs!$B$6-G$6)*($B14-1)/9) | H14: =IF(H$4="","",H$6+(Inputs!$B$6-H$6)*($B14-1)/9)
A15: Year 7 | B15: 7 | C15: =IF(C$4="","",C$6+(Inputs!$B$6-C$6)*($B15-1)/9) | D15: =IF(D$4="","",D$6+(Inputs!$B$6-D$6)*($B15-1)/9) | E15: =IF(E$4="","",E$6+(Inputs!$B$6-E$6)*($B15-1)/9) | F15: =IF(F$4="","",F$6+(Inputs!$B$6-F$6)*($B15-1)/9) | G15: =IF(G$4="","",G$6+(Inputs!$B$6-G$6)*($B15-1)/9) | H15: =IF(H$4="","",H$6+(Inputs!$B$6-H$6)*($B15-1)/9)
A16: Year 8 | B16: 8 | C16: =IF(C$4="","",C$6+(Inputs!$B$6-C$6)*($B16-1)/9) | D16: =IF(D$4="","",D$6+(Inputs!$B$6-D$6)*($B16-1)/9) | E16: =IF(E$4="","",E$6+(Inputs!$B$6-E$6)*($B16-1)/9) | F16: =IF(F$4="","",F$6+(Inputs!$B$6-F$6)*($B16-1)/9) | G16: =IF(G$4="","",G$6+(Inputs!$B$6-G$6)*($B16-1)/9) | H16: =IF(H$4="","",H$6+(Inputs!$B$6-H$6)*($B16-1)/9)
A17: Year 9 | B17: 9 | C17: =IF(C$4="","",C$6+(Inputs!$B$6-C$6)*($B17-1)/9) | D17: =IF(D$4="","",D$6+(Inputs!$B$6-D$6)*($B17-1)/9) | E17: =IF(E$4="","",E$6+(Inputs!$B$6-E$6)*($B17-1)/9) | F17: =IF(F$4="","",F$6+(Inputs!$B$6-F$6)*($B17-1)/9) | G17: =IF(G$4="","",G$6+(Inputs!$B$6-G$6)*($B17-1)/9) | H17: =IF(H$4="","",H$6+(Inputs!$B$6-H$6)*($B17-1)/9)
A18: Year 10 | B18: 10 | C18: =IF(C$4="","",C$6+(Inputs!$B$6-C$6)*($B18-1)/9) | D18: =IF(D$4="","",D$6+(Inputs!$B$6-D$6)*($B18-1)/9) | E18: =IF(E$4="","",E$6+(Inputs!$B$6-E$6)*($B18-1)/9) | F18: =IF(F$4="","",F$6+(Inputs!$B$6-F$6)*($B18-1)/9) | G18: =IF(G$4="","",G$6+(Inputs!$B$6-G$6)*($B18-1)/9) | H18: =IF(H$4="","",H$6+(Inputs!$B$6-H$6)*($B18-1)/9)
A20: Owner FCF ($mm)
A21: Year 1 | B21: 1 | C21: =IF(C$4="","",C$5*(1+C9)) | D21: =IF(D$4="","",D$5*(1+D9)) | E21: =IF(E$4="","",E$5*(1+E9)) | F21: =IF(F$4="","",F$5*(1+F9)) | G21: =IF(G$4="","",G$5*(1+G9)) | H21: =IF(H$4="","",H$5*(1+H9))
A22: Year 2 | B22: 2 | C22: =IF(C$4="","",C21*(1+C10)) | D22: =IF(D$4="","",D21*(1+D10)) | E22: =IF(E$4="","",E21*(1+E10)) | F22: =IF(F$4="","",F21*(1+F10)) | G22: =IF(G$4="","",G21*(1+G10)) | H22: =IF(H$4="","",H21*(1+H10))
A23: Year 3 | B23: 3 | C23: =IF(C$4="","",C22*(1+C11)) | D23: =IF(D$4="","",D22*(1+D11)) | E23: =IF(E$4="","",E22*(1+E11)) | F23: =IF(F$4="","",F22*(1+F11)) | G23: =IF(G$4="","",G22*(1+G11)) | H23: =IF(H$4="","",H22*(1+H11))
A24: Year 4 | B24: 4 | C24: =IF(C$4="","",C23*(1+C12)) | D24: =IF(D$4="","",D23*(1+D12)) | E24: =IF(E$4="","",E23*(1+E12)) | F24: =IF(F$4="","",F23*(1+F12)) | G24: =IF(G$4="","",G23*(1+G12)) | H24: =IF(H$4="","",H23*(1+H12))
A25: Year 5 | B25: 5 | C25: =IF(C$4="","",C24*(1+C13)) | D25: =IF(D$4="","",D24*(1+D13)) | E25: =IF(E$4="","",E24*(1+E13)) | F25: =IF(F$4="","",F24*(1+F13)) | G25: =IF(G$4="","",G24*(1+G13)) | H25: =IF(H$4="","",H24*(1+H13))
A26: Year 6 | B26: 6 | C26: =IF(C$4="","",C25*(1+C14)) | D26: =IF(D$4="","",D25*(1+D14)) | E26: =IF(E$4="","",E25*(1+E14)) | F26: =IF(F$4="","",F25*(1+F14)) | G26: =IF(G$4="","",G25*(1+G14)) | H26: =IF(H$4="","",H25*(1+H14))
A27: Year 7 | B27: 7 | C27: =IF(C$4="","",C26*(1+C15)) | D27: =IF(D$4="","",D26*(1+D15)) | E27: =IF(E$4="","",E26*(1+E15)) | F27: =IF(F$4="","",F26*(1+F15)) | G27: =IF(G$4="","",G26*(1+G15)) | H27: =IF(H$4="","",H26*(1+H15))
A28: Year 8 | B28: 8 | C28: =IF(C$4="","",C27*(1+C16)) | D28: =IF(D$4="","",D27*(1+D16)) | E28: =IF(E$4="","",E27*(1+E16)) | F28: =IF(F$4="","",F27*(1+F16)) | G28: =IF(G$4="","",G27*(1+G16)) | H28: =IF(H$4="","",H27*(1+H16))
A29: Year 9 | B29: 9 | C29: =IF(C$4="","",C28*(1+C17)) | D29: =IF(D$4="","",D28*(1+D17)) | E29: =IF(E$4="","",E28*(1+E17)) | F29: =IF(F$4="","",F28*(1+F17)) | G29: =IF(G$4="","",G28*(1+G17)) | H29: =IF(H$4="","",H28*(1+H17))
A30: Year 10 | B30: 10 | C30: =IF(C$4="","",C29*(1+C18)) | D30: =IF(D$4="","",D29*(1+D18)) | E30: =IF(E$4="","",E29*(1+E18)) | F30: =IF(F$4="","",F29*(1+F18)) | G30: =IF(G$4="","",G29*(1+G18)) | H30: =IF(H$4="","",H29*(1+H18))
A32: PV of owner FCF @ base discount rate ($mm)
A33: Year 1 | B33: 1 | C33: =IF(C$4="","",C21/(1+Inputs!$B$4)^$B33) | D33: =IF(D$4="","",D21/(1+Inputs!$B$4)^$B33) | E33: =IF(E$4="","",E21/(1+Inputs!$B$4)^$B33) | F33: =IF(F$4="","",F21/(1+Inputs!$B$4)^$B33) | G33: =IF(G$4="","",G21/(1+Inputs!$B$4)^$B33) | H33: =IF(H$4="","",H21/(1+Inputs!$B$4)^$B33)
A34: Year 2 | B34: 2 | C34: =IF(C$4="","",C22/(1+Inputs!$B$4)^$B34) | D34: =IF(D$4="","",D22/(1+Inputs!$B$4)^$B34) | E34: =IF(E$4="","",E22/(1+Inputs!$B$4)^$B34) | F34: =IF(F$4="","",F22/(1+Inputs!$B$4)^$B34) | G34: =IF(G$4="","",G22/(1+Inputs!$B$4)^$B34) | H34: =IF(H$4="","",H22/(1+Inputs!$B$4)^$B34)
A35: Year 3 | B35: 3 | C35: =IF(C$4="","",C23/(1+Inputs!$B$4)^$B35) | D35: =IF(D$4="","",D23/(1+Inputs!$B$4)^$B35) | E35: =IF(E$4="","",E23/(1+Inputs!$B$4)^$B35) | F35: =IF(F$4="","",F23/(1+Inputs!$B$4)^$B35) | G35: =IF(G$4="","",G23/(1+Inputs!$B$4)^$B35) | H35: =IF(H$4="","",H23/(1+Inputs!$B$4)^$B35)
A36: Year 4 | B36: 4 | C36: =IF(C$4="","",C24/(1+Inputs!$B$4)^$B36) | D36: =IF(D$4="","",D24/(1+Inputs!$B$4)^$B36) | E36: =IF(E$4="","",E24/(1+Inputs!$B$4)^$B36) | F36: =IF(F$4="","",F24/(1+Inputs!$B$4)^$B36) | G36: =IF(G$4="","",G24/(1+Inputs!$B$4)^$B36) | H36: =IF(H$4="","",H24/(1+Inputs!$B$4)^$B36)
A37: Year 5 | B37: 5 | C37: =IF(C$4="","",C25/(1+Inputs!$B$4)^$B37) | D37: =IF(D$4="","",D25/(1+Inputs!$B$4)^$B37) | E37: =IF(E$4="","",E25/(1+Inputs!$B$4)^$B37) | F37: =IF(F$4="","",F25/(1+Inputs!$B$4)^$B37) | G37: =IF(G$4="","",G25/(1+Inputs!$B$4)^$B37) | H37: =IF(H$4="","",H25/(1+Inputs!$B$4)^$B37)
A38: Year 6 | B38: 6 | C38: =IF(C$4="","",C26/(1+Inputs!$B$4)^$B38) | D38: =IF(D$4="","",D26/(1+Inputs!$B$4)^$B38) | E38: =IF(E$4="","",E26/(1+Inputs!$B$4)^$B38) | F38: =IF(F$4="","",F26/(1+Inputs!$B$4)^$B38) | G38: =IF(G$4="","",G26/(1+Inputs!$B$4)^$B38) | H38: =IF(H$4="","",H26/(1+Inputs!$B$4)^$B38)
A39: Year 7 | B39: 7 | C39: =IF(C$4="","",C27/(1+Inputs!$B$4)^$B39) | D39: =IF(D$4="","",D27/(1+Inputs!$B$4)^$B39) | E39: =IF(E$4="","",E27/(1+Inputs!$B$4)^$B39) | F39: =IF(F$4="","",F27/(1+Inputs!$B$4)^$B39) | G39: =IF(G$4="","",G27/(1+Inputs!$B$4)^$B39) | H39: =IF(H$4="","",H27/(1+Inputs!$B$4)^$B39)
A40: Year 8 | B40: 8 | C40: =IF(C$4="","",C28/(1+Inputs!$B$4)^$B40) | D40: =IF(D$4="","",D28/(1+Inputs!$B$4)^$B40) | E40: =IF(E$4="","",E28/(1+Inputs!$B$4)^$B40) | F40: =IF(F$4="","",F28/(1+Inputs!$B$4)^$B40) | G40: =IF(G$4="","",G28/(1+Inputs!$B$4)^$B40) | H40: =IF(H$4="","",H28/(1+Inputs!$B$4)^$B40)
A41: Year 9 | B41: 9 | C41: =IF(C$4="","",C29/(1+Inputs!$B$4)^$B41) | D41: =IF(D$4="","",D29/(1+Inputs!$B$4)^$B41) | E41: =IF(E$4="","",E29/(1+Inputs!$B$4)^$B41) | F41: =IF(F$4="","",F29/(1+Inputs!$B$4)^$B41) | G41: =IF(G$4="","",G29/(1+Inputs!$B$4)^$B41) | H41: =IF(H$4="","",H29/(1+Inputs!$B$4)^$B41)
A42: Year 10 | B42: 10 | C42: =IF(C$4="","",C30/(1+Inputs!$B$4)^$B42) | D42: =IF(D$4="","",D30/(1+Inputs!$B$4)^$B42) | E42: =IF(E$4="","",E30/(1+Inputs!$B$4)^$B42) | F42: =IF(F$4="","",F30/(1+Inputs!$B$4)^$B42) | G42: =IF(G$4="","",G30/(1+Inputs!$B$4)^$B42) | H42: =IF(H$4="","",H30/(1+Inputs!$B$4)^$B42)
A44: PV of owner FCF @ conservative discount rate ($mm)
A45: Year 1 | B45: 1 | C45: =IF(C$4="","",C21/(1+Inputs!$B$5)^$B45) | D45: =IF(D$4="","",D21/(1+Inputs!$B$5)^$B45) | E45: =IF(E$4="","",E21/(1+Inputs!$B$5)^$B45) | F45: =IF(F$4="","",F21/(1+Inputs!$B$5)^$B45) | G45: =IF(G$4="","",G21/(1+Inputs!$B$5)^$B45) | H45: =IF(H$4="","",H21/(1+Inputs!$B$5)^$B45)
...

Sheet ImpliedCalc
A1: Helper: value multiple of year-0 owner FCF for each starting growth (do not edit)
L2: Years 1-10 = cumulative growth factors
A3: Start g | B3: 1 | C3: 2 | D3: 3 | E3: 4 | F3: 5 | G3: 6 | H3: 7 | I3: 8 | J3: 9 | K3: 10 | L3: Mult @ base r | M3: Mult @ cons r
A4: =ROUND(-0.2+0*0.005,4) | B4: =1*(1+$A4+(Inputs!$B$6-$A4)*(B$3-1)/9) | C4: =B4*(1+$A4+(Inputs!$B$6-$A4)*(C$3-1)/9) | D4: =C4*(1+$A4+(Inputs!$B$6-$A4)*(D$3-1)/9) | E4: =D4*(1+$A4+(Inputs!$B$6-$A4)*(E$3-1)/9) | F4: =E4*(1+$A4+(Inputs!$B$6-$A4)*(F$3-1)/9) | G4: =F4*(1+$A4+(Inputs!$B$6-$A4)*(G$3-1)/9) | H4: =G4*(1+$A4+(Inputs!$B$6-$A4)*(H$3-1)/9) | I4: =H4*(1+$A4+(Inputs!$B$6-$A4)*(I$3-1)/9) | J4: =I4*(1+$A4+(Inputs!$B$6-$A4)*(J$3-1)/9) | K4: =J4*(1+$A4+(Inputs!$B$6-$A4)*(K$3-1)/9) | L4: =SUMPRODUCT(B4:K4,1/(1+Inputs!$B$4)^$B$3:$K$3)+K4*(1+Inputs!$B$6)/(Inputs!$B$4-Inputs!$B$6)/(1+Inputs!$B$4)^10 | M4: =SUMPRODUCT(B4:K4,1/(1+Inputs!$B$5)^$B$3:$K$3)+K4*(1+Inputs!$B$6)/(Inputs!$B$5-Inputs!$B$6)/(1+Inputs!$B$5)^10
A5: =ROUND(-0.2+1*0.005,4) | B5: =1*(1+$A5+(Inputs!$B$6-$A5)*(B$3-1)/9) | C5: =B5*(1+$A5+(Inputs!$B$6-$A5)*(C$3-1)/9) | D5: =C5*(1+$A5+(Inputs!$B$6-$A5)*(D$3-1)/9) | E5: =D5*(1+$A5+(Inputs!$B$6-$A5)*(E$3-1)/9) | F5: =E5*(1+$A5+(Inputs!$B$6-$A5)*(F$3-1)/9) | G5: =F5*(1+$A5+(Inputs!$B$6-$A5)*(G$3-1)/9) | H5: =G5*(1+$A5+(Inputs!$B$6-$A5)*(H$3-1)/9) | I5: =H5*(1+$A5+(Inputs!$B$6-$A5)*(I$3-1)/9) | J5: =I5*(1+$A5+(Inputs!$B$6-$A5)*(J$3-1)/9) | K5: =J5*(1+$A5+(Inputs!$B$6-$A5)*(K$3-1)/9) | L5: =SUMPRODUCT(B5:K5,1/(1+Inputs!$B$4)^$B$3:$K$3)+K5*(1+Inputs!$B$6)/(Inputs!$B$4-Inputs!$B$6)/(1+Inputs!$B$4)^10 | M5: =SUMPRODUCT(B5:K5,1/(1+Inputs!$B$5)^$B$3:$K$3)+K5*(1+Inputs!$B$6)/(Inputs!$B$5-Inputs!$B$6)/(1+Inputs!$B$5)^10
A6: =ROUND(-0.2+2*0.005,4) | B6: =1*(1+$A6+(Inputs!$B$6-$A6)*(B$3-1)/9) | C6: =B6*(1+$A6+(Inputs!$B$6-$A6)*(C$3-1)/9) | D6: =C6*(1+$A6+(Inputs!$B$6-$A6)*(D$3-1)/9) | E6: =D6*(1+$A6+(Inputs!$B$6-$A6)*(E$3-1)/9) | F6: =E6*(1+$A6+(Inputs!$B$6-$A6)*(F$3-1)/9) | G6: =F6*(1+$A6+(Inputs!$B$6-$A6)*(G$3-1)/9) | H6: =G6*(1+$A6+(Inputs!$B$6-$A6)*(H$3-1)/9) | I6: =H6*(1+$A6+(Inputs!$B$6-$A6)*(I$3-1)/9) | J6: =I6*(1+$A6+(Inputs!$B$6-$A6)*(J$3-1)/9) | K6: =J6*(1+$A6+(Inputs!$B$6-$A6)*(K$3-1)/9) | L6: =SUMPRODUCT(B6:K6,1/(1+Inputs!$B$4)^$B$3:$K$3)+K6*(1+Inputs!$B$6)/(Inputs!$B$4-Inputs!$B$6)/(1+Inputs!$B$4)^10 | M6: =SUMPRODUCT(B6:K6,1/(1+Inputs!$B$5)^$B$3:$K$3)+K6*(1+Inputs!$B$6)/(Inputs!$B$5-Inputs!$B$6)/(1+Inputs!$B$5)^10
A7: =ROUND(-0.2+3*0.005,4) | B7: =1*(1+$A7+(Inputs!$B$6-$A7)*(B$3-1)/9) | C7: =B7*(1+$A7+(Inputs!$B$6-$A7)*(C$3-1)/9) | D7: =C7*(1+$A7+(Inputs!$B$6-$A7)*(D$3-1)/9) | E7: =D7*(1+$A7+(Inputs!$B$6-$A7)*(E$3-1)/9) | F7: =E7*(1+$A7+(Inputs!$B$6-$A7)*(F$3-1)/9) | G7: =F7*(1+$A7+(Inputs!$B$6-$A7)*(G$3-1)/9) | H7: =G7*(1+$A7+(Inputs!$B$6-$A7)*(H$3-1)/9) | I7: =H7*(1+$A7+(Inputs!$B$6-$A7)*(I$3-1)/9) | J7: =I7*(1+$A7+(Inputs!$B$6-$A7)*(J$3-1)/9) | K7: =J7*(1+$A7+(Inputs!$B$6-$A7)*(K$3-1)/9) | L7: =SUMPRODUCT(B7:K7,1/(1+Inputs!$B$4)^$B$3:$K$3)+K7*(1+Inputs!$B$6)/(Inputs!$B$4-Inputs!$B$6)/(1+Inputs!$B$4)^10 | M7: =SUMPRODUCT(B7:K7,1/(1+Inputs!$B$5)^$B$3:$K$3)+K7*(1+Inputs!$B$6)/(Inputs!$B$5-Inputs!$B$6)/(1+Inputs!$B$5)^10
A8: =ROUND(-0.2+4*0.005,4) | B8: =1*(1+$A8+(Inputs!$B$6-$A8)*(B$3-1)/9) | C8: =B8*(1+$A8+(Inputs!$B$6-$A8)*(C$3-1)/9) | D8: =C8*(1+$A8+(Inputs!$B$6-$A8)*(D$3-1)/9) | E8: =D8*(1+$A8+(Inputs!$B$6-$A8)*(E$3-1)/9) | F8: =E8*(1+$A8+(Inputs!$B$6-$A8)*(F$3-1)/9) | G8: =F8*(1+$A8+(Inputs!$B$6-$A8)*(G$3-1)/9) | H8: =G8*(1+$A8+(Inputs!$B$6-$A8)*(H$3-1)/9) | I8: =H8*(1+$A8+(Inputs!$B$6-$A8)*(I$3-1)/9) | J8: =I8*(1+$A8+(Inputs!$B$6-$A8)*(J$3-1)/9) | K8: =J8*(1+$A8+(Inputs!$B$6-$A8)*(K$3-1)/9) | L8: =SUMPRODUCT(B8:K8,1/(1+Inputs!$B$4)^$B$3:$K$3)+K8*(1+Inputs!$B$6)/(Inputs!$B$4-Inputs!$B$6)/(1+Inputs!$B$4)^10 | M8: =SUMPRODUCT(B8:K8,1/(1+Inputs!$B$5)^$B$3:$K$3)+K8*(1+Inputs!$B$6)/(Inputs!$B$5-Inputs!$B$6)/(1+Inputs!$B$5)^10
A9: =ROUND(-0.2+5*0.005,4) | B9: =1*(1+$A9+(Inputs!$B$6-$A9)*(B$3-1)/9) | C9: =B9*(1+$A9+(Inputs!$B$6-$A9)*(C$3-1)/9) | D9: =C9*(1+$A9+(Inputs!$B$6-$A9)*(D$3-1)/9) | E9: =D9*(1+$A9+(Inputs!$B$6-$A9)*(E$3-1)/9) | F9: =E9*(1+$A9+(Inputs!$B$6-$A9)*(F$3-1)/9) | G9: =F9*(1+$A9+(Inputs!$B$6-$A9)*(G$3-1)/9) | H9: =G9*(1+$A9+(Inputs!$B$6-$A9)*(H$3-1)/9) | I9: =H9*(1+$A9+(Inputs!$B$6-$A9)*(I$3-1)/9) | J9: =I9*(1+$A9+(Inputs!$B$6-$A9)*(J$3-1)/9) | K9: =J9*(1+$A9+(Inputs!$B$6-$A9)*(K$3-1)/9) | L9: =SUMPRODUCT(B9:K9,1/(1+Inputs!$B$4)^$B$3:$K$3)+K9*(1+Inputs!$B$6)/(Inputs!$B$4-Inputs!$B$6)/(1+Inputs!$B$4)^10 | M9: =SUMPRODUCT(B9:K9,1/(1+Inputs!$B$5)^$B$3:$K$3)+K9*(1+Inputs!$B$6)/(Inputs!$B$5-Inputs!$B$6)/(1+Inputs!$B$5)^10
A10: =ROUND(-0.2+6*0.005,4) | B10: =1*(1+$A10+(Inputs!$B$6-$A10)*(B$3-1)/9) | C10: =B10*(1+$A10+(Inputs!$B$6-$A10)*(C$3-1)/9) | D10: =C10*(1+$A10+(Inputs!$B$6-$A10)*(D$3-1)/9) | E10: =D10*(1+$A10+(Inputs!$B$6-$A10)*(E$3-1)/9) | F10: =E10*(1+$A10+(Inputs!$B$6-$A10)*(F$3-1)/9) | G10: =F10*(1+$A10+(Inputs!$B$6-$A10)*(G$3-1)/9) | H10: =G10*(1+$A10+(Inputs!$B$6-$A10)*(H$3-1)/9) | I10: =H10*(1+$A10+(Inputs!$B$6-$A10)*(I$3-1)/9) | J10: =I10*(1+$A10+(Inputs!$B$6-$A10)*(J$3-1)/9) | K10: =J10*(1+$A10+(Inputs!$B$6-$A10)*(K$3-1)/9) | L10: =SUMPRODUCT(B10:K10,1/(1+Inputs!$B$4)^$B$3:$K$3)+K10*(1+Inputs!$B$6)/(Inputs!$B$4-Inputs!$B$6)/(1+Inputs!$B$4)^10 | M10: =SUMPRODUCT(B10:K10,1/(1+Inputs!$B$5)^$B$3:$K$3)+K10*(1+Inputs!$B$6)/(Inputs!$B$5-Inputs!$B$6)/(1+Inputs!$B$5)^10
A11: =ROUND(-0.2+7*0.005,4) | B11: =1*(1+$A11+(Inputs!$B$6-$A11)*(B$3-1)/9) | C11: =B11*(1+$A11+(Inputs!$B$6-$A11)*(C$3-1)/9) | D11: =C11*(1+$A11+(Inputs!$B$6-$A11)*(D$3-1)/9) | E11: =D11*(1+$A11+(Inputs!$B$6-$A11)*(E$3-1)/9) | F11: =E11*(1+$A11+(Inputs!$B$6-$A11)*(F$3-1)/9) | G11: =F11*(1+$A11+(Inputs!$B$6-$A11)*(G$3-1)/9) | H11: =G11*(1+$A11+(Inputs!$B$6-$A11)*(H$3-1)/9) | I11: =H11*(1+$A11+(Inputs!$B$6-$A11)*(I$3-1)/9) | J11: =I11*(1+$A11+(Inputs!$B$6-$A11)*(J$3-1)/9) | K11: =J11*(1+$A11+(Inputs!$B$6-$A11)*(K$3-1)/9) | L11: =SUMPRODUCT(B11:K11,1/(1+Inputs!$B$4)^$B$3:$K$3)+K11*(1+Inputs!$B$6)/(Inputs!$B$4-Inputs!$B$6)/(1+Inputs!$B$4)^10 | M11: =SUMPRODUCT(B11:K11,1/(1+Inputs!$B$5)^$B$3:$K$3)+K11*(1+Inputs!$B$6)/(Inputs!$B$5-Inputs!$B$6)/(1+Inputs!$B$5)^10
A12: =ROUND(-0.2+8*0.005,4) | B12: =1*(1+$A12+(Inputs!$B$6-$A12)*(B$3-1)/9) | C12: =B12*(1+$A12+(Inputs!$B$6-$A12)*(C$3-1)/9) | D12: =C12*(1+$A12+(Inputs!$B$6-$A12)*(D$3-1)/9) | E12: =D12*(1+$A12+(Inputs!$B$6-$A12)*(E$3-1)/9) | F12: =E12*(1+$A12+(Inputs!$B$6-$A12)*(F$3-1)/9) | G12: =F12*(1+$A12+(Inputs!$B$6-$A12)*(G$3-1)/9) | H12: =G12*(1+$A12+(Inputs!$B$6-$A12)*(H$3-1)/9) | I12: =H12*(1+$A12+(Inputs!$B$6-$A12)*(I$3-1)/9) | J12: =I12*(1+$A12+(Inputs!$B$6-$A12)*(J$3-1)/9) | K12: =J12*(1+$A12+(Inputs!$B$6-$A12)*(K$3-1)/9) | L12: =SUMPRODUCT(B12:K12,1/(1+Inputs!$B$4)^$B$3:$K$3)+K12*(1+Inputs!$B$6)/(Inputs!$B$4-Inputs!$B$6)/(1+Inputs!$B$4)^10 | M12: =SUMPRODUCT(B12:K12,1/(1+Inputs!$B$5)^$B$3:$K$3)+K12*(1+Inputs!$B$6)/(Inputs!$B$5-Inputs!$B$6)/(1+Inputs!$B$5)^10
A13: =ROUND(-0.2+9*0.005,4) | B13: =1*(1+$A13+(Inputs!$B$6-$A13)*(B$3-1)/9) | C13: =B13*(1+$A13+(Inputs!$B$6-$A13)*(C$3-1)/9) | D13: =C13*(1+$A13+(Inputs!$B$6-$A13)*(D$3-1)/9) | E13: =D13*(1+$A13+(Inputs!$B$6-$A13)*(E$3-1)/9) | F13: =E13*(1+$A13+(Inputs!$B$6-$A13)*(F$3-1)/9) | G13: =F13*(1+$A13+(Inputs!$B$6-$A13)*(G$3-1)/9) | H13: =G13*(1+$A13+(Inputs!$B$6-$A13)*(H$3-1)/9) | I13: =H13*(1+$A13+(Inputs!$B$6-$A13)*(I$3-1)/9) | J13: =I13*(1+$A13+(Inputs!$B$6-$A13)*(J$3-1)/9) | K13: =J13*(1+$A13+(Inputs!$B$6-$A13)*(K$3-1)/9) | L13: =SUMPRODUCT(B13:K13,1/(1+Inputs!$B$4)^$B$3:$K$3)+K13*(1+Inputs!$B$6)/(Inputs!$B$4-Inputs!$B$6)/(1+Inputs!$B$4)^10 | M13: =SUMPRODUCT(B13:K13,1/(1+Inputs!$B$5)^$B$3:$K$3)+K13*(1+Inputs!$B$6)/(Inputs!$B$5-Inputs!$B$6)/(1+Inputs!$B$5)^10
A14: =ROUND(-0.2+10*0.005,4) | B14: =1*(1+$A14+(Inputs!$B$6-$A14)*(B$3-1)/9) | C14: =B14*(1+$A14+(Inputs!$B$6-$A14)*(C$3-1)/9) | D14: =C14*(1+$A14+(Inputs!$B$6-$A14)*(D$3-1)/9) | E14: =D14*(1+$A14+(Inputs!$B$6-$A14)*(E$3-1)/9) | F14: =E14*(1+$A14+(Inputs!$B$6-$A14)*(F$3-1)/9) | G14: =F14*(1+$A14+(Inputs!$B$6-$A14)*(G$3-1)/9) | H14: =G14*(1+$A14+(Inputs!$B$6-$A14)*(H$3-1)/9) | I14: =H14*(1+$A14+(Inputs!$B$6-$A14)*(I$3-1)/9) | J14: =I14*(1+$A14+(Inputs!$B$6-$A14)*(J$3-1)/9) | K14: =J14*(1+$A14+(Inputs!$B$6-$A14)*(K$3-1)/9) | L14: =SUMPRODUCT(B14:K14,1/(1+Inputs!$B$4)^$B$3:$K$3)+K14*(1+Inputs!$B$6)/(Inputs!$B$4-Inputs!$B$6)/(1+Inputs!$B$4)^10 | M14: =SUMPRODUCT(B14:K14,1/(1+Inputs!$B$5)^$B$3:$K$3)+K14*(1+Inputs!$B$6)/(Inputs!$B$5-Inputs!$B$6)/(1+Inputs!$B$5)^10
A15: =ROUND(-0.2+11*0.005,4) | B15: =1*(1+$A15+(Inputs!$B$6-$A15)*(B$3-1)/9) | C15: =B15*(1+$A15+(Inputs!$B$6-$A15)*(C$3-1)/9) | D15: =C15*(1+$A15+(Inputs!$B$6-$A15)*(D$3-1)/9) | E15: =D15*(1+$A15+(Inputs!$B$6-$A15)*(E$3-1)/9) | F15: =E15*(1+$A15+(Inputs!$B$6-$A15)*(F$3-1)/9) | G15: =F15*(1+$A15+(Inputs!$B$6-$A15)*(G$3-1)/9) | H15: =G15*(1+$A15+(Inputs!$B$6-$A15)*(H$3-1)/9) | I15: =H15*(1+$A15+(Inputs!$B$6-$A15)*(I$3-1)/9) | J15: =I15*(1+$A15+(Inputs!$B$6-$A15)*(J$3-1)/9) | K15: =J15*(1+$A15+(Inputs!$B$6-$A15)*(K$3-1)/9) | L15: =SUMPRODUCT(B15:K15,1/(1+Inputs!$B$4)^$B$3:$K$3)+K15*(1+Inputs!$B$6)/(Inputs!$B$4-Inputs!$B$6)/(1+Inputs!$B$4)^10 | M15: =SUMPRODUCT(B15:K15,1/(1+Inputs!$B$5)^$B$3:$K$3)+K15*(1+Inputs!$B$6)/(Inputs!$B$5-Inputs!$B$6)/(1+Inputs!$B$5)^10
A16: =ROUND(-0.2+12*0.005,4) | B16: =1*(1+$A16+(Inputs!$B$6-$A16)*(B$3-1)/9) | C16: =B16*(1+$A16+(Inputs!$B$6-$A16)*(C$3-1)/9) | D16: =C16*(1+$A16+(Inputs!$B$6-$A16)*(D$3-1)/9) | E16: =D16*(1+$A16+(Inputs!$B$6-$A16)*(E$3-1)/9) | F16: =E16*(1+$A16+(Inputs!$B$6-$A16)*(F$3-1)/9) | G16: =F16*(1+$A16+(Inputs!$B$6-$A16)*(G$3-1)/9) | H16: =G16*(1+$A16+(Inputs!$B$6-$A16)*(H$3-1)/9) | I16: =H16*(1+$A16+(Inputs!$B$6-$A16)*(I$3-1)/9) | J16: =I16*(1+$A16+(Inputs!$B$6-$A16)*(J$3-1)/9) | K16: =J16*(1+$A16+(Inputs!$B$6-$A16)*(K$3-1)/9) | L16: =SUMPRODUCT(B16:K16,1/(1+Inputs!$B$4)^$B$3:$K$3)+K16*(1+Inputs!$B$6)/(Inputs!$B$4-Inputs!$B$6)/(1+Inputs!$B$4)^10 | M16: =SUMPRODUCT(B16:K16,1/(1+Inputs!$B$5)^$B$3:$K$3)+K16*(1+Inputs!$B$6)/(Inputs!$B$5-Inputs!$B$6)/(1+Inputs!$B$5)^10
A17: =ROUND(-0.2+13*0.005,4) | B17: =1*(1+$A17+(Inputs!$B$6-$A17)*(B$3-1)/9) | C17: =B17*(1+$A17+(Inputs!$B$6-$A17)*(C$3-1)/9) | D17: =C17*(1+$A17+(Inputs!$B$6-$A17)*(D$3-1)/9) | E17: =D17*(1+$A17+(Inputs!$B$6-$A17)*(E$3-1)/9) | F17: =E17*(1+$A17+(Inputs!$B$6-$A17)*(F$3-1)/9) | G17: =F17*(1+$A17+(Inputs!$B$6-$A17)*(G$3-1)/9) | H17: =G17*(1+$A17+(Inputs!$B$6-$A17)*(H$3-1)/9) | I17: =H17*(1+$A17+(Inputs!$B$6-$A17)*(I$3-1)/9) | J17: =I17*(1+$A17+(Inputs!$B$6-$A17)*(J$3-1)/9) | K17: =J17*(1+$A17+(Inputs!$B$6-$A17)*(K$3-1)/9) | L17: =SUMPRODUCT(B17:K17,1/(1+Inputs!$B$4)^$B$3:$K$3)+K17*(1+Inputs!$B$6)/(Inputs!$B$4-Inputs!$B$6)/(1+Inputs!$B$4)^10 | M17: =SUMPRODUCT(B17:K17,1/(1+Inputs!$B$5)^$B$3:$K$3)+K17*(1+Inputs!$B$6)/(Inputs!$B$5-Inputs!$B$6)/(1+Inputs!$B$5)^10
A18: =ROUND(-0.2+14*0.005,4) | B18: =1*(1+$A18+(Inputs!$B$6-$A18)*(B$3-1)/9) | C18: =B18*(1+$A18+(Inputs!$B$6-$A18)*(C$3-1)/9) | D18: =C18*(1+$A18+(Inputs!$B$6-$A18)*(D$3-1)/9) | E18: =D18*(1+$A18+(Inputs!$B$6-$A18)*(E$3-1)/9) | F18: =E18*(1+$A18+(Inputs!$B$6-$A18)*(F$3-1)/9) | G18: =F18*(1+$A18+(Inputs!$B$6-$A18)*(G$3-1)/9) | H18: =G18*(1+$A18+(Inputs!$B$6-$A18)*(H$3-1)/9) | I18: =H18*(1+$A18+(Inputs!$B$6-$A18)*(I$3-1)/9) | J18: =I18*(1+$A18+(Inputs!$B$6-$A18)*(J$3-1)/9) | K18: =J18*(1+$A18+(Inputs!$B$6-$A18)*(K$3-1)/9) | L18: =SUMPRODUCT(B18:K18,1/(1+Inputs!$B$4)^$B$3:$K$3)+K18*(1+Inputs!$B$6)/(Inputs!$B$4-Inputs!$B$6)/(1+Inputs!$B$4)^10 | M18: =SUMPRODUCT(B18:K18,1/(1+Inputs!$B$5)^$B$3:$K$3)+K18*(1+Inputs!$B$6)/(Inputs!$B$5-Inputs!$B$6)/(1+Inputs!$B$5)^10
A19: =ROUND(-0.2+15*0.005,4) | B19: =1*(1+$A19+(Inputs!$B$6-$A19)*(B$3-1)/9) | C19: =B19*(1+$A19+(Inputs!$B$6-$A19)*(C$3-1)/9) | D19: =C19*(1+$A19+(Inputs!$B$6-$A19)*(D$3-1)/9) | E19: =D19*(1+$A19+(Inputs!$B$6-$A19)*(E$3-1)/9) | F19: =E19*(1+$A19+(Inputs!$B$6-$A19)*(F$3-1)/9) | G19: =F19*(1+$A19+(Inputs!$B$6-$A19)*(G$3-1)/9) | H19: =G19*(1+$A19+(Inputs!$B$6-$A19)*(H$3-1)/9) | I19: =H19*(1+$A19+(Inputs!$B$6-$A19)*(I$3-1)/9) | J19: =I19*(1+$A19+(Inputs!$B$6-$A19)*(J$3-1)/9) | K19: =J19*(1+$A19+(Inputs!$B$6-$A19)*(K$3-1)/9) | L19: =SUMPRODUCT(B19:K19,1/(1+Inputs!$B$4)^$B$3:$K$3)+K19*(1+Inputs!$B$6)/(Inputs!$B$4-Inputs!$B$6)/(1+Inputs!$B$4)^10 | M19: =SUMPRODUCT(B19:K19,1/(1+Inputs!$B$5)^$B$3:$K$3)+K19*(1+Inputs!$B$6)/(Inputs!$B$5-Inputs!$B$6)/(1+Inputs!$B$5)^10
A20: =ROUND(-0.2+16*0.005,4) | B20: =1*(1+$A20+(Inputs!$B$6-$A20)*(B$3-1)/9) | C20: =B20*(1+$A20+(Inputs!$B$6-$A20)*(C$3-1)/9) | D20: =C20*(1+$A20+(Inputs!$B$6-$A20)*(D$3-1)/9) | E20: =D20*(1+$A20+(Inputs!$B$6-$A20)*(E$3-1)/9) | F20: =E20*(1+$A20+(Inputs!$B$6-$A20)*(F$3-1)/9) | G20: =F20*(1+$A20+(Inputs!$B$6-$A20)*(G$3-1)/9) | H20: =G20*(1+$A20+(Inputs!$B$6-$A20)*(H$3-1)/9) | I20: =H20*(1+$A20+(Inputs!$B$6-$A20)*(I$3-1)/9) | J20: =I20*(1+$A20+(Inputs!$B$6-$A20)*(J$3-1)/9) | K20: =J20*(1+$A20+(Inputs!$B$6-$A20)*(K$3-1)/9) | L20: =SUMPRODUCT(B20:K20,1/(1+Inputs!$B$4)^$B$3:$K$3)+K20*(1+Inputs!$B$6)/(Inputs!$B$4-Inputs!$B$6)/(1+Inputs!$B$4)^10 | M20: =SUMPRODUCT(B20:K20,1/(1+Inputs!$B$5)^$B$3:$K$3)+K20*(1+Inputs!$B$6)/(Inputs!$B$5-Inputs!$B$6)/(1+Inputs!$B$5)^10
A21: =ROUND(-0.2+17*0.005,4) | B21: =1*(1+$A21+(Inputs!$B$6-$A21)*(B$3-1)/9) | C21: =B21*(1+$A21+(Inputs!$B$6-$A21)*(C$3-1)/9) | D21: =C21*(1+$A21+(Inputs!$B$6-$A21)*(D$3-1)/9) | E21: =D21*(1+$A21+(Inputs!$B$6-$A21)*(E$3-1)/9) | F21: =E21*(1+$A21+(Inputs!$B$6-$A21)*(F$3-1)/9) | G21: =F21*(1+$A21+(Inputs!$B$6-$A21)*(G$3-1)/9) | H21: =G21*(1+$A21+(Inputs!$B$6-$A21)*(H$3-1)/9) | I21: =H21*(1+$A21+(Inputs!$B$6-$A21)*(I$3-1)/9) | J21: =I21*(1+$A21+(Inputs!$B$6-$A21)*(J$3-1)/9) | K21: =J21*(1+$A21+(Inputs!$B$6-$A21)*(K$3-1)/9) | L21: =SUMPRODUCT(B21:K21,1/(1+Inputs!$B$4)^$B$3:$K$3)+K21*(1+Inputs!$B$6)/(Inputs!$B$4-Inputs!$B$6)/(1+Inputs!$B$4)^10 | M21: =SUMPRODUCT(B21:K21,1/(1+Inputs!$B$5)^$B$3:$K$3)+K21*(1+Inputs!$B$6)/(Inputs!$B$5-Inputs!$B$6)/(1+Inputs!$B$5)^10
A22: =ROUND(-0.2+18*0.005,4) | B22: =1*(1+$A22+(Inputs!$B$6-$A22)*(B$3-1)/9) | C22: =B22*(1+$A22+(Inputs!$B$6-$A22)*(C$3-1)/9) | D22: =C22*(1+$A22+(Inputs!$B$6-$A22)*(D$3-1)/9) | E22: =D22*(1+$A22+(Inputs!$B$6-$A22)*(E$3-1)/9) | F22: =E22*(1+$A22+(Inputs!$B$6-$A22)*(F$3-1)/9) | G22: =F22*(1+$A22+(Inputs!$B$6-$A22)*(G$3-1)/9) | H22: =G22*(1+$A22+(Inputs!$B$6-$A22)*(H$3-1)/9) | I22: =H22*(1+$A22+(Inputs!$B$6-$A22)*(I$3-1)/9) | J22: =I22*(1+$A22+(Inputs!$B$6-$A22)*(J$3-1)/9) | K22: =J22*(1+$A22+(Inputs!$B$6-$A22)*(K$3-1)/9) | L22: =SUMPRODUCT(B22:K22,1/(1+Inputs!$B$4)^$B$3:$K$3)+K22*(1+Inputs!$B$6)/(Inputs!$B$4-Inputs!$B$6)/(1+Inputs!$B$4)^10 | M22: =SUMPRODUCT(B22:K22,1/(1+Inputs!$B$5)^$B$3:$K$3)+K22*(1+Inputs!$B$6)/(Inputs!$B$5-Inputs!$B$6)/(1+Inputs!$B$5)^10
A23: =ROUND(-0.2+19*0.005,4) | B23: =1*(1+$A23+(Inputs!$B$6-$A23)*(B$3-1)/9) | C23: =B23*(1+$A23+(Inputs!$B$6-$A23)*(C$3-1)/9) | D23: =C23*(1+$A23+(Inputs!$B$6-$A23)*(D$3-1)/9) | E23: =D23*(1+$A23+(Inputs!$B$6-$A23)*(E$3-1)/9) | F23: =E23*(1+$A23+(Inputs!$B$6-$A23)*(F$3-1)/9) | G23: =F23*(1+$A23+(Inputs!$B$6-$A23)*(G$3-1)/9) | H23: =G23*(1+$A23+(Inputs!$B$6-$A23)*(H$3-1)/9) | I23: =H23*(1+$A23+(Inputs!$B$6-$A23)*(I$3-1)/9) | J23: =I23*(1+$A23+(Inputs!$B$6-$A23)*(J$3-1)/9) | K23: =J23*(1+$A23+(Inputs!$B$6-$A23)*(K$3-1)/9) | L23: =SUMPRODUCT(B23:K23,1/(1+Inputs!$B$4)^$B$3:$K$3)+K23*(1+Inputs!$B$6)/(Inputs!$B$4-Inputs!$B$6)/(1+Inputs!$B$4)^10 | M23: =SUMPRODUCT(B23:K23,1/(1+Inputs!$B$5)^$B$3:$K$3)+K23*(1+Inputs!$B$6)/(Inputs!$B$5-Inputs!$B$6)/(1+Inputs!$B$5)^10
A24: =ROUND(-0.2+20*0.005,4) | B24: =1*(1+$A24+(Inputs!$B$6-$A24)*(B$3-1)/9) | C24: =B24*(1+$A24+(Inputs!$B$6-$A24)*(C$3-1)/9) | D24: =C24*(1+$A24+(Inputs!$B$6-$A24)*(D$3-1)/9) | E24: =D24*(1+$A24+(Inputs!$B$6-$A24)*(E$3-1)/9) | F24: =E24*(1+$A24+(Inputs!$B$6-$A24)*(F$3-1)/9) | G24: =F24*(1+$A24+(Inputs!$B$6-$A24)*(G$3-1)/9) | H24: =G24*(1+$A24+(Inputs!$B$6-$A24)*(H$3-1)/9) | I24: =H24*(1+$A24+(Inputs!$B$6-$A24)*(I$3-1)/9) | J24: =I24*(1+$A24+(Inputs!$B$6-$A24)*(J$3-1)/9) | K24: =J24*(1+$A24+(Inputs!$B$6-$A24)*(K$3-1)/9) | L24: =SUMPRODUCT(B24:K24,1/(1+Inputs!$B$4)^$B$3:$K$3)+K24*(1+Inputs!$B$6)/(Inputs!$B$4-Inputs!$B$6)/(1+Inputs!$B$4)^10 | M24: =SUMPRODUCT(B24:K24,1/(1+Inputs!$B$5)^$B$3:$K$3)+K24*(1+Inputs!$B$6)/(Inputs!$B$5-Inputs!$B$6)/(1+Inputs!$B$5)^10
A25: =ROUND(-0.2+21*0.005,4) | B25: =1*(1+$A25+(Inputs!$B$6-$A25)*(B$3-1)/9) | C25: =B25*(1+$A25+(Inputs!$B$6-$A25)*(C$3-1)/9) | D25: =C25*(1+$A25+(Inputs!$B$6-$A25)*(D$3-1)/9) | E25: =D25*(1+$A25+(Inputs!$B$6-$A25)*(E$3-1)/9) | F25: =E25*(1+$A25+(Inputs!$B$6-$A25)*(F$3-1)/9) | G25: =F25*(1+$A25+(Inputs!$B$6-$A25)*(G$3-1)/9) | H25: =G25*(1+$A25+(Inputs!$B$6-$A25)*(H$3-1)/9) | I25: =H25*(1+$A25+(Inputs!$B$6-$A25)*(I$3-1)/9) | J25: =I25*(1+$A25+(Inputs!$B$6-$A25)*(J$3-1)/9) | K25: =J25*(1+$A25+(Inputs!$B$6-$A25)*(K$3-1)/9) | L25: =SUMPRODUCT(B25:K25,1/(1+Inputs!$B$4)^$B$3:$K$3)+K25*(1+Inputs!$B$6)/(Inputs!$B$4-Inputs!$B$6)/(1+Inputs!$B$4)^10 | M25: =SUMPRODUCT(B25:K25,1/(1+Inputs!$B$5)^$B$3:$K$3)+K25*(1+Inputs!$B$6)/(Inputs!$B$5-Inputs!$B$6)/(1+Inputs!$B$5)^10
A26: =ROUND(-0.2+22*0.005,4) | B26: =1*(1+$A26+(Inputs!$B$6-$A26)*(B$3-1)/9) | C26: =B26*(1+$A26+(Inputs!$B$6-$A26)*(C$3-1)/9) | D26: =C26*(1+$A26+(Inputs!$B$6-$A26)*(D$3-1)/9) | E26: =D26*(1+$A26+(Inputs!$B$6-$A26)*(E$3-1)/9) | F26: =E26*(1+$A26+(Inputs!$B$6-$A26)*(F$3-1)/9) | G26: =F26*(1+$A26+(Inputs!$B$6-$A26)*(G$3-1)/9) | H26: =G26*(1+$A26+(Inputs!$B$6-$A26)*(H$3-1)/9) | I26: =H26*(1+$A26+(Inputs!$B$6-$A26)*(I$3-1)/9) | J26: =I26*(1+$A26+(Inputs!$B$6-$A26)*(J$3-1)/9) | K26: =J26*(1+$A26+(Inputs!$B$6-$A26)*(K$3-1)/9) | L26: =SUMPRODUCT(B26:K26,1/(1+Inputs!$B$4)^$B$3:$K$3)+K26*(1+Inputs!$B$6)/(Inputs!$B$4-Inputs!$B$6)/(1+Inputs!$B$4)^10 | M26: =SUMPRODUCT(B26:K26,1/(1+Inputs!$B$5)^$B$3:$K$3)+K26*(1+Inputs!$B$6)/(Inputs!$B$5-Inputs!$B$6)/(1+Inputs!$B$5)^10
A27: =ROUND(-0.2+23*0.005,4) | B27: =1*(1+$A27+(Inputs!$B$6-$A27)*(B$3-1)/9) | C27: =B27*(1+$A27+(Inputs!$B$6-$A27)*(C$3-1)/9) | D27: =C27*(1+$A27+(Inputs!$B$6-$A27)*(D$3-1)/9) | E27: =D27*(1+$A27+(Inputs!$B$6-$A27)*(E$3-1)/9) | F27: =E27*(1+$A27+(Inputs!$B$6-$A27)*(F$3-1)/9) | G27: =F27*(1+$A27+(Inputs!$B$6-$A27)*(G$3-1)/9) | H27: =G27*(1+$A27+(Inputs!$B$6-$A27)*(H$3-1)/9) | I27: =H27*(1+$A27+(Inputs!$B$6-$A27)*(I$3-1)/9) | J27: =I27*(1+$A27+(Inputs!$B$6-$A27)*(J$3-1)/9) | K27: =J27*(1+$A27+(Inputs!$B$6-$A27)*(K$3-1)/9) | L27: =SUMPRODUCT(B27:K27,1/(1+Inputs!$B$4)^$B$3:$K$3)+K27*(1+Inputs!$B$6)/(Inputs!$B$4-Inputs!$B$6)/(1+Inputs!$B$4)^10 | M27: =SUMPRODUCT(B27:K27,1/(1+Inputs!$B$5)^$B$3:$K$3)+K27*(1+Inputs!$B$6)/(Inputs!$B$5-Inputs!$B$6)/(1+Inputs!$B$5)^10
A28: =ROUND(-0.2+24*0.005,4) | B28: =1*(1+$A28+(Inputs!$B$6-$A28)*(B$3-1)/9) | C28: =B28*(1+$A28+(Inputs!$B$6-$A28)*(C$3-1)/9) | D28: =C28*(1+$A28+(Inputs!$B$6-$A28)*(D$3-1)/9) | E28: =D28*(1+$A28+(Inputs!$B$6-$A28)*(E$3-1)/9) | F28: =E28*(1+$A28+(Inputs!$B$6-$A28)*(F$3-1)/9) | G28: =F28*(1+$A28+(Inputs!$B$6-$A28)*(G$3-1)/9) | H28: =G28*(1+$A28+(Inputs!$B$6-$A28)*(H$3-1)/9) | I28: =H28*(1+$A28+(Inputs!$B$6-$A28)*(I$3-1)/9) | J28: =I28*(1+$A28+(Inputs!$B$6-$A28)*(J$3-1)/9) | K28: =J28*(1+$A28+(Inputs!$B$6-$A28)*(K$3-1)/9) | L28: =SUMPRODUCT(B28:K28,1/(1+Inputs!$B$4)^$B$3:$K$3)+K28*(1+Inputs!$B$6)/(Inputs!$B$4-Inputs!$B$6)/(1+Inputs!$B$4)^10 | M28: =SUMPRODUCT(B28:K28,1/(1+Inputs!$B$5)^$B$3:$K$3)+K28*(1+Inputs!$B$6)/(Inputs!$B$5-Inputs!$B$6)/(1+Inputs!$B$5)^10
A29: =ROUND(-0.2+25*0.005,4) | B29: =1*(1+$A29+(Inputs!$B$6-$A29)*(B$3-1)/9) | C29: =B29*(1+$A29+(Inputs!$B$6-$A29)*(C$3-1)/9) | D29: =C29*(1+$A29+(Inputs!$B$6-$A29)*(D$3-1)/9) | E29: =D29*(1+$A29+(Inputs!$B$6-$A29)*(E$3-1)/9) | F29: =E29*(1+$A29+(Inputs!$B$6-$A29)*(F$3-1)/9) | G29: =F29*(1+$A29+(Inputs!$B$6-$A29)*(G$3-1)/9) | H29: =G29*(1+$A29+(Inputs!$B$6-$A29)*(H$3-1)/9) | I29: =H29*(1+$A29+(Inputs!$B$6-$A29)*(I$3-1)/9) | J29: =I29*(1+$A29+(Inputs!$B$6-$A29)*(J$3-1)/9) | K29: =J29*(1+$A29+(Inputs!$B$6-$A29)*(K$3-1)/9) | L29: =SUMPRODUCT(B29:K29,1/(1+Inputs!$B$4)^$B$3:$K$3)+K29*(1+Inputs!$B$6)/(Inputs!$B$4-Inputs!$B$6)/(1+Inputs!$B$4)^10 | M29: =SUMPRODUCT(B29:K29,1/(1+Inputs!$B$5)^$B$3:$K$3)+K29*(1+Inputs!$B$6)/(Inputs!$B$5-Inputs!$B$6)/(1+Inputs!$B$5)^10
A30: =ROUND(-0.2+26*0.005,4) | B30: =1*(1+$A30+(Inputs!$B$6-$A30)*(B$3-1)/9) | C30: =B30*(1+$A30+(Inputs!$B$6-$A30)*(C$3-1)/9) | D30: =C30*(1+$A30+(Inputs!$B$6-$A30)*(D$3-1)/9) | E30: =D30*(1+$A30+(Inputs!$B$6-$A30)*(E$3-1)/9) | F30: =E30*(1+$A30+(Inputs!$B$6-$A30)*(F$3-1)/9) | G30: =F30*(1+$A30+(Inputs!$B$6-$A30)*(G$3-1)/9) | H30: =G30*(1+$A30+(Inputs!$B$6-$A30)*(H$3-1)/9) | I30: =H30*(1+$A30+(Inputs!$B$6-$A30)*(I$3-1)/9) | J30: =I30*(1+$A30+(Inputs!$B$6-$A30)*(J$3-1)/9) | K30: =J30*(1+$A30+(Inputs!$B$6-$A30)*(K$3-1)/9) | L30: =SUMPRODUCT(B30:K30,1/(1+Inputs!$B$4)^$B$3:$K$3)+K30*(1+Inputs!$B$6)/(Inputs!$B$4-Inputs!$B$6)/(1+Inputs!$B$4)^10 | M30: =SUMPRODUCT(B30:K30,1/(1+Inputs!$B$5)^$B$3:$K$3)+K30*(1+Inputs!$B$6)/(Inputs!$B$5-Inputs!$B$6)/(1+Inputs!$B$5)^10
A31: =ROUND(-0.2+27*0.005,4) | B31: =1*(1+$A31+(Inputs!$B$6-$A31)*(B$3-1)/9) | C31: =B31*(1+$A31+(Inputs!$B$6-$A31)*(C$3-1)/9) | D31: =C31*(1+$A31+(Inputs!$B$6-$A31)*(D$3-1)/9) | E31: =D31*(1+$A31+(Inputs!$B$6-$A31)*(E$3-1)/9) | F31: =E31*(1+$A31+(Inputs!$B$6-$A31)*(F$3-1)/9) | G31: =F31*(1+$A31+(Inputs!$B$6-$A31)*(G$3-1)/9) | H31: =G31*(1+$A31+(Inputs!$B$6-$A31)*(H$3-1)/9) | I31: =H31*(1+$A31+(Inputs!$B$6-$A31)*(I$3-1)/9) | J31: =I31*(1+$A31+(Inputs!$B$6-$A31)*(J$3-1)/9) | K31: =J31*(1+$A31+(Inputs!$B$6-$A31)*(K$3-1)/9) | L31: =SUMPRODUCT(B31:K31,1/(1+Inputs!$B$4)^$B$3:$K$3)+K31*(1+Inputs!$B$6)/(Inputs!$B$4-Inputs!$B$6)/(1+Inputs!$B$4)^10 | M31: =SUMPRODUCT(B31:K31,1/(1+Inputs!$B$5)^$B$3:$K$3)+K31*(1+Inputs!$B$6)/(Inputs!$B$5-Inputs!$B$6)/(1+Inputs!$B$5)^10
A32: =ROUND(-0.2+28*0.005,4) | B32: =1*(1+$A32+(Inputs!$B$6-$A32)*(B$3-1)/9) | C32: =B32*(1+$A32+(Inputs!$B$6-$A32)*(C$3-1)/9) | D32: =C32*(1+$A32+(Inputs!$B$6-$A32)*(D$3-1)/9) | E32: =D32*(1+$A32+(Inputs!$B$6-$A32)*(E$3-1)/9) | F32: =E32*(1+$A32+(Inputs!$B$6-$A32)*(F$3-1)/9) | G32: =F32*(1+$A32+(Inputs!$B$6-$A32)*(G$3-1)/9) | H32: =G32*(1+$A32+(Inputs!$B$6-$A32)*(H$3-1)/9) | I32: =H32*(1+$A32+(Inputs!$B$6-$A32)*(I$3-1)/9) | J32: =I32*(1+$A32+(Inputs!$B$6-$A32)*(J$3-1)/9) | K32: =J32*(1+$A32+(Inputs!$B$6-$A32)*(K$3-1)/9) | L32: =SUMPRODUCT(B32:K32,1/(1+Inputs!$B$4)^$B$3:$K$3)+K32*(1+Inputs!$B$6)/(Inputs!$B$4-Inputs!$B$6)/(1+Inputs!$B$4)^10 | M32: =SUMPRODUCT(B32:K32,1/(1+Inputs!$B$5)^$B$3:$K$3)+K32*(1+Inputs!$B$6)/(Inputs!$B$5-Inputs!$B$6)/(1+Inputs!$B$5)^10
A33: =ROUND(-0.2+29*0.005,4) | B33: =1*(1+$A33+(Inputs!$B$6-$A33)*(B$3-1)/9) | C33: =B33*(1+$A33+(Inputs!$B$6-$A33)*(C$3-1)/9) | D33: =C33*(1+$A33+(Inputs!$B$6-$A33)*(D$3-1)/9) | E33: =D33*(1+$A33+(Inputs!$B$6-$A33)*(E$3-1)/9) | F33: =E33*(1+$A33+(Inputs!$B$6-$A33)*(F$3-1)/9) | G33: =F33*(1+$A33+(Inputs!$B$6-$A33)*(G$3-1)/9) | H33: =G33*(1+$A33+(Inputs!$B$6-$A33)*(H$3-1)/9) | I33: =H33*(1+$A33+(Inputs!$B$6-$A33)*(I$3-1)/9) | J33: =I33*(1+$A33+(Inputs!$B$6-$A33)*(J$3-1)/9) | K33: =J33*(1+$A33+(Inputs!$B$6-$A33)*(K$3-1)/9) | L33: =SUMPRODUCT(B33:K33,1/(1+Inputs!$B$4)^$B$3:$K$3)+K33*(1+Inputs!$B$6)/(Inputs!$B$4-Inputs!$B$6)/(1+Inputs!$B$4)^10 | M33: =SUMPRODUCT(B33:K33,1/(1+Inputs!$B$5)^$B$3:$K$3)+K33*(1+Inputs!$B$6)/(Inputs!$B$5-Inputs!$B$6)/(1+Inputs!$B$5)^10
