Workbook

Sheet Summary
A1: SUMMARY - price target, NAV, FCF and replacement cost (recalculates from Inputs)
A2: ="Active scenario: "&Scenario&" | price shift $"&TEXT(PriceShift,"0.0")&"/MWh | gas shift $"&TEXT(GasShift,"0.00")&"/MMBtu | nuclear replacement $"&TEXT(NucRC,"#,##0")&"/kW" -> Active scenario: Base | price shift $0.0/MWh | gas shift $0.00/MMBtu | nuclear replacement $4,500/kW
A4: Item | B4: CEG | C4: VST | E4: Notes
A6: Market
A7: Share price ($) | B7: =CEG_Price -> 263.93 | C7: =VST_Price -> 138.76
A8: Shares incl. pending issuance (mm) | B8: =CEG_Shares+CEG_ExtraShares -> 354.307 | C8: =VST_Shares+VST_ExtraShares -> 341
A9: Market cap ($mm) | B9: =B7*B8 -> 93512.247 | C9: =C7*C8 -> 47317.16
A10: Net debt, preferred & other claims ($mm) | B10: =CEG_Claims*1000 -> 14958 | C10: =VST_Claims*1000 -> 26586
A11: Enterprise value ($mm) | B11: =B9+B10 -> 108470.25 | C11: =C9+C10 -> 73903.16
A12: Owned MW (pro forma) | B12: =CEG_Assets!D20 -> 49970 | C12: =VST_Assets!D16 -> 49141
A13: EV per kW ($) | B13: =B11/B12*1000 -> 2170.7074 | C13: =C11/C12*1000 -> 1503.9002
A15: 1. Asset NAV (sum of asset cash-flow values)
A16: Gross asset value ($mm) | B16: =SUMIF(CEG_Model!$B$35:$B$574,"pv_m",CEG_Model!$C$35:$C$574)+SUMIF(CEG_Model!$B$35:$B$574,"pv_c",CEG_Model!$C$35:$C$574)+SUMIF(CEG_Model!$B$35:$B$574,"fixedval",CEG_Model!$C$35:$C$574) -> 81018.946 | C16: =SUMIF(VST_Model!$B$35:$B$454,"pv_m",VST_Model!$C$35:$C$454)+SUMIF(VST_Model!$B$35:$B$454,"pv_c",VST_Model!$C$35:$C$454)+SUMIF(VST_Model!$B$35:$B$454,"fixedval",VST_Model!$C$35:$C$454) -> 49570.659
A17: GAV per kW ($) | B17: =B16/B12*1000 -> 1621.3517 | C17: =C16/C12*1000 -> 1008.7434
A18: Less: capitalised corporate overhead ($mm) | B18: =CEG_Model!$C$30 -> 4862.064 | C18: =VST_Model!$C$30 -> 3781.6053
A19: Equity NAV - generation only ($mm) | B19: =B16-B18-B10 -> 61198.882 | C19: =C16-C18-C10 -> 19203.054
A20: NAV per share - generation only ($) | B20: =B19/B8 -> 172.7284 | C20: =C19/C8 -> 56.31394
A21: Add: retail/platform value ($mm) | B21: =CEG_PlatEBITDA*CEG_PlatMult -> 6000 | C21: =VST_PlatEBITDA*VST_PlatMult -> 8778 | E21: Earnings-based; shown separately
A22: Add: other value - growth / site options ($mm) | B22: =CEG_OtherVal -> 0 | C22: =VST_OtherVal -> 0 | E22: Input on Inputs; 0 by default
A23: NAV per share incl. platform & other ($) | B23: =(B19+B21+B22)/B8 -> 189.66287 | C23: =(C19+C21+C22)/C8 -> 82.055875
A25: 2. Forward value: FCF generated to horizon + NAV at horizon
A26: Cumulative equity FCF to horizon ($mm, after haircut) | B26: =SUMIF(CEG_Model!$G$3:$AS$3,"<="&Horizon,CEG_Model!$G$29:$AS$29) -> 31012.282 | C26: =SUMIF(VST_Model!$G$3:$AS$3,"<="&Horizon,VST_Model!$G$29:$AS$29) -> 20146.242
A27: Gross asset value at horizon ($mm) | B27: =SUMIF(CEG_Model!$B$35:$B$574,"pv_m",CEG_Model!$E$35:$E$574)+SUMIF(CEG_Model!$B$35:$B$574,"pv_c",CEG_Model!$E$35:$E$574)+SUMIF(CEG_Model!$B$35:$B$574,"fixedval",CEG_Model!$E$35:$E$574) -> 75825.055 | C27: =SUMIF(VST_Model!$B$35:$B$454,"pv_m",VST_Model!$E$35:$E$454)+SUMIF(VST_Model!$B$35:$B$454,"pv_c",VST_Model!$E$35:$E$454)+SUMIF(VST_Model!$B$35:$B$454,"fixedval",VST_Model!$E$35:$E$454) -> 45300.151
A28: Less: overhead at horizon ($mm) | B28: =CEG_Model!$C$31 -> 5371.2924 | C28: =VST_Model!$C$31 -> 4177.6719
A29: Add: platform value at horizon ($mm) | B29: =B21*(1+Infl)^(Horizon-2026) -> 6494.593 | C29: =C21*(1+Infl)^(Horizon-2026) -> 9501.5895
A30: Equity NAV at horizon incl. other value ($mm) | B30: =B27-B28-B10+B29+B22 -> 61990.356 | C30: =C27-C28-C10+C29+C22 -> 24038.069
A31: Value per share at horizon = FCF + NAV ($) | B31: =(B26+B30)/B8 -> 262.49167 | C31: =(C26+C30)/C8 -> 129.57276
A32: Years to horizon | B32: =Horizon+1-ValDate -> 4.25 | C32: =Horizon+1-ValDate -> 4.25
A33: Implied annual return from current price | B33: =IF(B31>0,(B31/B7)^(1/B32)-1,-1) -> -0.0012849521 | C33: =IF(C31>0,(C31/C7)^(1/C32)-1,-1) -> -0.015989202
A34: LEVERED EQUITY VALUE today: PV of FCF to horizon + PV of NAV at horizon ($/share) | B34: =(SUMPRODUCT((CEG_Model!$G$3:$AS$3<=Horizon)*CEG_Model!$G$29:$AS$29*CEG_Model!$G$32:$AS$32)+B30*(1+EquityDisc)^-B32)/B8 -> 194.27658 | C34: =(SUMPRODUCT((VST_Model!$G$3:$AS$3<=Horizon)*VST_Model!$G$29:$AS$29*VST_Model!$G$32:$AS$32)+C30*(1+EquityDisc)^-C32)/C8 -> 98.326549 | E34: Discounted at the equity rate; credits cheap debt and the interest tax shield
A35: of which cheap debt & interest tax shield vs asset NAV ($/share) | B35: =B34-B23 -> 4.6137108 | C35: =C34-C23 -> 16.270673
A36: Entry price for target return (fat pitch, $) | B36: =MAX(0,B31)/(1+TargetReturn)^B32 -> 144.92714 | C36: =MAX(0,C31)/(1+TargetReturn)^C32 -> 71.539828
A38: 3. Replacement cost + FCF
A39: Depreciated replacement cost of fleet ($mm) | B39: =CEG_Assets!AM20 -> 67874.422 | C39: =VST_Assets!AM16 -> 49453.619
A40: Less claims, plus other value = equity replacement value ($mm) | B40: =B39-B10+B22 -> 52916.422 | C40: =C39-C10+C22 -> 22867.619
A41: PV of equity FCF over replacement lead time ($mm) | B41: =SUMPRODUCT((CEG_Model!$G$3:$AS$3<=2026+RCYears)*CEG_Model!$G$29:$AS$29*CEG_Model!$G$32:$AS$32) -> 30313.965 | C41: =SUMPRODUCT((VST_Model!$G$3:$AS$3<=2026+RCYears)*VST_Model!$G$29:$AS$29*VST_Model!$G$32:$AS$32) -> 19838.766
A42: Replacement cost + FCF per share ($) | B42: =(B40+B41)/B8 -> 234.91036 | C42: =(C40+C41)/C8 -> 125.23867
A43: Tobin's q (GAV / replacement cost) | B43: =B16/B39 -> 1.1936595 | C43: =C16/C39 -> 1.0023667
A44: Market EV / replacement cost | B44: =B11/B39 -> 1.598102 | C44: =C11/C39 -> 1.4943934
A46: 4. PRICE TARGET (weighted blend - weights on Inputs)
...

Sheet Inputs
A1: INPUTS - blue = input, yellow = key lever
A3: Control panel
A4: Scenario (Low / Base / High / Extreme) | B4: Base | G4: Selects heat rates, capacity prices, peaker scarcity from the scenario table
A5: ERCOT (Texas) scenario - 'Same' follows the main scenario | B5: Same | G5: Lets ERCOT tighten (or loosen) independently of PJM: sets ERCOT heat rate and ERCOT peaker scarcity
A6: Long-run power price shift ($/MWh, 2026$, all hubs) | B6: 0 | G6: Added to every hub's long-run ATC from 2030 (half in 2029)
A7: Henry Hub shift ($/MMBtu, all years) | B7: 0 | G7: Moves gas costs AND power prices (price = heat rate x gas)
A8: PJM capacity price override ($/MW-day, 2026$; blank = scenario)
A9: Nuclear replacement-cost basis (1-4, see table below) | B9: 2 | G9: 1 gas-equivalent / 2 gas + clean premium / 3 NOAK AP1000 / 4 EPRI next AP1000
A10: FCF / forward-value horizon (last year of FCF) | B10: 2030
A11: Replacement-cost FCF years added (build lead time) | B11: 5 | G11: Years of FCF added on top of depreciated replacement cost
A12: Target return for entry price (fat pitch) | B12: 0.15
A13: Equity discount rate (price-target forward leg, replacement FCF) | B13: 0.09
A15: Global economics
A16: Valuation date (fractional year) | B16: 2026.75 | G16: 30-Sep-2026
A17: Inflation / escalator | B17: 0.02
A18: Cash tax rate on asset cash flow | B18: 0.2 | G18: 21% federal + state less depreciation shield (assumption)
A19: Henry Hub 2027 (2026$/MMBtu) | B19: 3.9 | G19: Between Sep-26 prompt $2.79 and EIA STEO ~$4.60 for 2027
A20: Henry Hub 2028 (2026$/MMBtu) | B20: 3.9
A21: Henry Hub long run (2026$/MMBtu) | B21: 4
A22: Delivered-fuel adder for gas plants ($/MMBtu) | B22: 0.3 | G22: Transport + winter fuel/power mismatch (estimate)
A23: 45U max credit ($/MWh, 2024$) | B23: 15 | G23: CRS IN12557
A24: 45U gross-receipts threshold ($/MWh, 2024$) | B24: 25
A25: 45U base year | B25: 2024
A26: 45U last year | B26: 2032
A27: Corporate overhead discount rate | B27: 0.085
A28: Corporate overhead years capitalised | B28: 30
A30: Forward market (nominal $/MWh ATC; PJM capacity $/MW-day)
A31: Item | B31: 2027 | C31: 2028 | D31: 2029
A32: PJM West ATC forward | B32: 72 | C32: 73 | D32: 70 | G32: Derived from on-peak Cal-27 $83.90 / Cal-28 $85.35 / Cal-29 $81.50 (8-Sep-26) x ~0.86
A33: ERCOT North ATC forward | B33: 49 | C33: 51 | D33: 52 | G33: Estimate: EIA STEO 2027 $47.39; forwards reported >$50
A34: PJM capacity, calendar year (blend of delivery years) | B34: 331.66 | C34: 328.52 | D34: 325 | G34: PJM BRA: 26/27 $329.17, 27/28 $333.44, 28/29 $325 (cap)
A36: Scenario table (long-run, 2026$)
A37: Parameter | B37: Low | C37: Base | D37: High | E37: Extreme | F37: ACTIVE | G37: ACTIVE ERCOT
A38: Implied heat rate PJM (MMBtu/MWh) | B38: 13 | C38: 16.5 | D38: 20 | E38: 25 | F38: =INDEX(B38:E38,MATCH(Scenario,$B$37:$E$37,0)) -> 16.5
A39: Implied heat rate ERCOT | B39: 10.5 | C39: 13 | D39: 16 | E39: 21 | F39: =INDEX(B39:E39,MATCH(Scenario,$B$37:$E$37,0)) -> 13 | G39: =INDEX(B39:E39,MATCH(IF(ERCOTScen="Same",Scenario,ERCOTScen),$B$37:$E$37,0)) -> 13
A40: PJM capacity ($/MW-day) | B40: 120 | C40: 230 | D40: 325 | E40: 475 | F40: =INDEX(B40:E40,MATCH(Scenario,$B$37:$E$37,0)) -> 230
A41: NY/NE/MISO capacity ($/MW-day) | B41: 60 | C41: 110 | D41: 170 | E41: 250 | F41: =INDEX(B41:E41,MATCH(Scenario,$B$37:$E$37,0)) -> 110
A42: CAISO RA capacity ($/MW-day) | B42: 150 | C42: 220 | D42: 280 | E42: 350 | F42: =INDEX(B42:E42,MATCH(Scenario,$B$37:$E$37,0)) -> 220
A43: Peaker scarcity capture (x ATC) | B43: 2 | C43: 2.5 | D43: 3 | E43: 3.6 | F43: =INDEX(B43:E43,MATCH(Scenario,$B$37:$E$37,0)) -> 2.5 | G43: =INDEX(B43:E43,MATCH(IF(ERCOTScen="Same",Scenario,ERCOTScen),$B$37:$E$37,0)) -> 2.5
A44: US data-center TWh 2030 (memo) | B44: 300 | C44: 450 | D44: 650 | E44: 850 | F44: =INDEX(B44:E44,MATCH(Scenario,$B$37:$E$37,0)) -> 450
...

Sheet Prices
A1: PRICE DECK - formulas only (edit on Inputs)
A3: Key | B3: Year | G3: 2027 | H3: 2028 | I3: 2029 | J3: 2030 | K3: 2031 | L3: 2032 | M3: 2033 | N3: 2034 | O3: 2035 | P3: 2036 | Q3: 2037 | R3: 2038 | S3: 2039 | T3: 2040 | U3: 2041 | V3: 2042 | W3: 2043 | X3: 2044 | Y3: 2045 | Z3: 2046 | AA3: 2047 | AB3: 2048 | AC3: 2049 | AD3: 2050 | AE3: 2051 | AF3: 2052 | AG3: 2053 | AH3: 2054 | AI3: 2055 | AJ3: 2056 | AK3: 2057 | AL3: 2058 | AM3: 2059 | AN3: 2060 | AO3: 2061 | AP3: 2062 | AQ3: 2063 | AR3: 2064 | AS3: 2065
A4: INFL | B4: Inflation index (2026 = 1) | G4: =(1+Infl)^(G$3-2026) -> 1.02 | H4: =(1+Infl)^(H$3-2026) -> 1.0404 | I4: =(1+Infl)^(I$3-2026) -> 1.061208 | J4: =(1+Infl)^(J$3-2026) -> 1.0824322 | K4: =(1+Infl)^(K$3-2026) -> 1.1040808 | L4: =(1+Infl)^(L$3-2026) -> 1.1261624 | M4: =(1+Infl)^(M$3-2026) -> 1.1486857 | N4: =(1+Infl)^(N$3-2026) -> 1.1716594 | ... AS4: =(1+Infl)^(AS$3-2026) -> 2.1647448
A5: HH | B5: Henry Hub, real 2026$/MMBtu | G5: =IF(G$3=2027,HH27,IF(G$3=2028,HH28,HHLR))+GasShift -> 3.9 | H5: =IF(H$3=2027,HH27,IF(H$3=2028,HH28,HHLR))+GasShift -> 3.9 | I5: =IF(I$3=2027,HH27,IF(I$3=2028,HH28,HHLR))+GasShift -> 4 | J5: =IF(J$3=2027,HH27,IF(J$3=2028,HH28,HHLR))+GasShift -> 4 | K5: =IF(K$3=2027,HH27,IF(K$3=2028,HH28,HHLR))+GasShift -> 4 | L5: =IF(L$3=2027,HH27,IF(L$3=2028,HH28,HHLR))+GasShift -> 4 | M5: =IF(M$3=2027,HH27,IF(M$3=2028,HH28,HHLR))+GasShift -> 4 | N5: =IF(N$3=2027,HH27,IF(N$3=2028,HH28,HHLR))+GasShift -> 4 | O5: =IF(O$3=2027,HH27,IF(O$3=2028,HH28,HHLR))+GasShift -> 4 | P5: =IF(P$3=2027,HH27,IF(P$3=2028,HH28,HHLR))+GasShift -> 4 | Q5: =IF(Q$3=2027,HH27,IF(Q$3=2028,HH28,HHLR))+GasShift -> 4 | R5: =IF(R$3=2027,HH27,IF(R$3=2028,HH28,HHLR))+GasShift -> 4 | S5: =IF(S$3=2027,HH27,IF(S$3=2028,HH28,HHLR))+GasShift -> 4 | T5: =IF(T$3=2027,HH27,IF(T$3=2028,HH28,HHLR))+GasShift -> 4 | U5: =IF(U$3=2027,HH27,IF(U$3=2028,HH28,HHLR))+GasShift -> 4 | V5: =IF(V$3=2027,HH27,IF(V$3=2028,HH28,HHLR))+GasShift -> 4 | W5: =IF(W$3=2027,HH27,IF(W$3=2028,HH28,HHLR))+GasShift -> 4 | X5: =IF(X$3=2027,HH27,IF(X$3=2028,HH28,HHLR))+GasShift -> 4 | Y5: =IF(Y$3=2027,HH27,IF(Y$3=2028,HH28,HHLR))+GasShift -> 4 | Z5: =IF(Z$3=2027,HH27,IF(Z$3=2028,HH28,HHLR))+GasShift -> 4 | AA5: =IF(AA$3=2027,HH27,IF(AA$3=2028,HH28,HHLR))+GasShift -> 4 | AB5: =IF(AB$3=2027,HH27,IF(AB$3=2028,HH28,HHLR))+GasShift -> 4 | AC5: =IF(AC$3=2027,HH27,IF(AC$3=2028,HH28,HHLR))+GasShift -> 4 | AD5: =IF(AD$3=2027,HH27,IF(AD$3=2028,HH28,HHLR))+GasShift -> 4 | AE5: =IF(AE$3=2027,HH27,IF(AE$3=2028,HH28,HHLR))+GasShift -> 4 | AF5: =IF(AF$3=2027,HH27,IF(AF$3=2028,HH28,HHLR))+GasShift -> 4 | AG5: =IF(AG$3=2027,HH27,IF(AG$3=2028,HH28,HHLR))+GasShift -> 4 | AH5: =IF(AH$3=2027,HH27,IF(AH$3=2028,HH28,HHLR))+GasShift -> 4 | AI5: =IF(AI$3=2027,HH27,IF(AI$3=2028,HH28,HHLR))+GasShift -> 4 | AJ5: =IF(AJ$3=2027,HH27,IF(AJ$3=2028,HH28,HHLR))+GasShift -> 4 | AK5: =IF(AK$3=2027,HH27,IF(AK$3=2028,HH28,HHLR))+GasShift -> 4 | AL5: =IF(AL$3=2027,HH27,IF(AL$3=2028,HH28,HHLR))+GasShift -> 4 | AM5: =IF(AM$3=2027,HH27,IF(AM$3=2028,HH28,HHLR))+GasShift -> 4 | AN5: =IF(AN$3=2027,HH27,IF(AN$3=2028,HH28,HHLR))+GasShift -> 4 | AO5: =IF(AO$3=2027,HH27,IF(AO$3=2028,HH28,HHLR))+GasShift -> 4 | AP5: =IF(AP$3=2027,HH27,IF(AP$3=2028,HH28,HHLR))+GasShift -> 4 | AQ5: =IF(AQ$3=2027,HH27,IF(AQ$3=2028,HH28,HHLR))+GasShift -> 4 | AR5: =IF(AR$3=2027,HH27,IF(AR$3=2028,HH28,HHLR))+GasShift -> 4 | AS5: =IF(AS$3=2027,HH27,IF(AS$3=2028,HH28,HHLR))+GasShift -> 4
A7: Long-run ATC (2026$/MWh) by hub
A8: LR|PJMW | B8: PJMW long-run ATC, 2026$ | C8: =IHRPJM*(HHLR+GasShift+Inputs!$C$50)*Inputs!$B$50+PriceShift -> 60.225
A9: LR|PJMA | B9: PJMA long-run ATC, 2026$ | C9: =IHRPJM*(HHLR+GasShift+Inputs!$C$50)*Inputs!$B$51+PriceShift -> 58.41825
A10: LR|NIHUB | B10: NIHUB long-run ATC, 2026$ | C10: =IHRPJM*(HHLR+GasShift+Inputs!$C$50)*Inputs!$B$52+PriceShift -> 51.19125
A11: LR|MISO | B11: MISO long-run ATC, 2026$ | C11: =IHRPJM*(HHLR+GasShift+Inputs!$C$50)*Inputs!$B$53+PriceShift -> 49.98675
A12: LR|NY | B12: NY long-run ATC, 2026$ | C12: =IHRPJM*(HHLR+GasShift+Inputs!$C$50)*Inputs!$B$54+PriceShift -> 54.2025
A13: LR|NE | B13: NE long-run ATC, 2026$ | C13: =IHRPJM*(HHLR+GasShift+Inputs!$C$50)*Inputs!$B$55+PriceShift -> 65.043
A14: LR|WEST | B14: WEST long-run ATC, 2026$ | C14: =IHRPJM*(HHLR+GasShift+Inputs!$C$50)*Inputs!$B$56+PriceShift -> 55.407
A15: LR|ERCOT | B15: ERCOT long-run ATC, 2026$ | C15: =IHRERC*(HHLR+GasShift+Inputs!$C$57)+PriceShift -> 50.05
A16: LR|PJMW_BASE | B16: PJM West long-run ATC in Base scenario, no shifts (for $/kW-valued renewables) | C16: =IHRPJMBase*(HHLR+Inputs!$C$50) -> 60.225
A18: Annual deck (nominal)
A19: GAS|PJMW | B19: PJMW gas, nominal $/MMBtu | G19: =(G$5+Inputs!$C$50)*G$4 -> 3.621 | H19: =(H$5+Inputs!$C$50)*H$4 -> 3.69342 | I19: =(I$5+Inputs!$C$50)*I$4 -> 3.8734092 | J19: =(J$5+Inputs!$C$50)*J$4 -> 3.9508774 | K19: =(K$5+Inputs!$C$50)*K$4 -> 4.0298949 | L19: =(L$5+Inputs!$C$50)*L$4 -> 4.1104928 | M19: =(M$5+Inputs!$C$50)*M$4 -> 4.1927027 | N19: =(N$5+Inputs!$C$50)*N$4 -> 4.2765567 | ... AS19: =(AS$5+Inputs!$C$50)*AS$4 -> 7.9013184
A20: ATC|PJMW | B20: PJMW ATC power, nominal $/MWh | G20: =IF(G$3<=2028,IF(G$3=2027,FwdPJM27,FwdPJM28)*Inputs!$B$50,IF(G$3=2029,0.5*FwdPJM29*Inputs!$B$50+0.5*$C$8*G$4,$C$8*G$4)) -> 72 | H20: =IF(H$3<=2028,IF(H$3=2027,FwdPJM27,FwdPJM28)*Inputs!$B$50,IF(H$3=2029,0.5*FwdPJM29*Inputs!$B$50+0.5*$C$8*H$4,$C$8*H$4)) -> 73 | I20: =IF(I$3<=2028,IF(I$3=2027,FwdPJM27,FwdPJM28)*Inputs!$B$50,IF(I$3=2029,0.5*FwdPJM29*Inputs!$B$50+0.5*$C$8*I$4,$C$8*I$4)) -> 66.955626 | J20: =IF(J$3<=2028,IF(J$3=2027,FwdPJM27,FwdPJM28)*Inputs!$B$50,IF(J$3=2029,0.5*FwdPJM29*Inputs!$B$50+0.5*$C$8*J$4,$C$8*J$4)) -> 65.189477 | K20: =IF(K$3<=2028,IF(K$3=2027,FwdPJM27,FwdPJM28)*Inputs!$B$50,IF(K$3=2029,0.5*FwdPJM29*Inputs!$B$50+0.5*$C$8*K$4,$C$8*K$4)) -> 66.493266 | L20: =IF(L$3<=2028,IF(L$3=2027,FwdPJM27,FwdPJM28)*Inputs!$B$50,IF(L$3=2029,0.5*FwdPJM29*Inputs!$B$50+0.5*$C$8*L$4,$C$8*L$4)) -> 67.823132 | M20: =IF(M$3<=2028,IF(M$3=2027,FwdPJM27,FwdPJM28)*Inputs!$B$50,IF(M$3=2029,0.5*FwdPJM29*Inputs!$B$50+0.5*$C$8*M$4,$C$8*M$4)) -> 69.179594 | N20: =IF(N$3<=2028,IF(N$3=2027,FwdPJM27,FwdPJM28)*Inputs!$B$50,IF(N$3=2029,0.5*FwdPJM29*Inputs!$B$50+0.5*$C$8*N$4,$C$8*N$4)) -> 70.563186 | ... AS20: =IF(AS$3<=2028,IF(AS$3=2027,FwdPJM27,FwdPJM28)*Inputs!$B$50,IF(AS$3=2029,0.5*FwdPJM29*Inputs!$B$50+0.5*$C$8*AS$4,$C$8*AS$4)) -> 130.37175
A21: CAP|PJMW | B21: PJMW capacity, nominal $/MW-day | G21: =IF(G$3=2027,CapCY27,IF(G$3=2028,CapCY28,IF(G$3=2029,5/12*CapDY2829+7/12*PJMCap*G$4,PJMCap*G$4))) -> 331.66 | H21: =IF(H$3=2027,CapCY27,IF(H$3=2028,CapCY28,IF(H$3=2029,5/12*CapDY2829+7/12*PJMCap*H$4,PJMCap*H$4))) -> 328.52 | I21: =IF(I$3=2027,CapCY27,IF(I$3=2028,CapCY28,IF(I$3=2029,5/12*CapDY2829+7/12*PJMCap*I$4,PJMCap*I$4))) -> 277.79541 | J21: =IF(J$3=2027,CapCY27,IF(J$3=2028,CapCY28,IF(J$3=2029,5/12*CapDY2829+7/12*PJMCap*J$4,PJMCap*J$4))) -> 248.9594 | K21: =IF(K$3=2027,CapCY27,IF(K$3=2028,CapCY28,IF(K$3=2029,5/12*CapDY2829+7/12*PJMCap*K$4,PJMCap*K$4))) -> 253.93858 | L21: =IF(L$3=2027,CapCY27,IF(L$3=2028,CapCY28,IF(L$3=2029,5/12*CapDY2829+7/12*PJMCap*L$4,PJMCap*L$4))) -> 259.01736 | M21: =IF(M$3=2027,CapCY27,IF(M$3=2028,CapCY28,IF(M$3=2029,5/12*CapDY2829+7/12*PJMCap*M$4,PJMCap*M$4))) -> 264.1977 | N21: =IF(N$3=2027,CapCY27,IF(N$3=2028,CapCY28,IF(N$3=2029,5/12*CapDY2829+7/12*PJMCap*N$4,PJMCap*N$4))) -> 269.48166 | ... AS21: =IF(AS$3=2027,CapCY27,IF(AS$3=2028,CapCY28,IF(AS$3=2029,5/12*CapDY2829+7/12*PJMCap*AS$4,PJMCap*AS$4))) -> 497.8913
A22: GAS|PJMA | B22: PJMA gas, nominal $/MMBtu | G22: =(G$5+Inputs!$C$51)*G$4 -> 3.621 | H22: =(H$5+Inputs!$C$51)*H$4 -> 3.69342 | I22: =(I$5+Inputs!$C$51)*I$4 -> 3.8734092 | J22: =(J$5+Inputs!$C$51)*J$4 -> 3.9508774 | K22: =(K$5+Inputs!$C$51)*K$4 -> 4.0298949 | L22: =(L$5+Inputs!$C$51)*L$4 -> 4.1104928 | M22: =(M$5+Inputs!$C$51)*M$4 -> 4.1927027 | N22: =(N$5+Inputs!$C$51)*N$4 -> 4.2765567 | ... AS22: =(AS$5+Inputs!$C$51)*AS$4 -> 7.9013184
A23: ATC|PJMA | B23: PJMA ATC power, nominal $/MWh | G23: =IF(G$3<=2028,IF(G$3=2027,FwdPJM27,FwdPJM28)*Inputs!$B$51,IF(G$3=2029,0.5*FwdPJM29*Inputs!$B$51+0.5*$C$9*G$4,$C$9*G$4)) -> 69.84 | H23: =IF(H$3<=2028,IF(H$3=2027,FwdPJM27,FwdPJM28)*Inputs!$B$51,IF(H$3=2029,0.5*FwdPJM29*Inputs!$B$51+0.5*$C$9*H$4,$C$9*H$4)) -> 70.81 | I23: =IF(I$3<=2028,IF(I$3=2027,FwdPJM27,FwdPJM28)*Inputs!$B$51,IF(I$3=2029,0.5*FwdPJM29*Inputs!$B$51+0.5*$C$9*I$4,$C$9*I$4)) -> 64.946957 | J23: =IF(J$3<=2028,IF(J$3=2027,FwdPJM27,FwdPJM28)*Inputs!$B$51,IF(J$3=2029,0.5*FwdPJM29*Inputs!$B$51+0.5*$C$9*J$4,$C$9*J$4)) -> 63.233793 | K23: =IF(K$3<=2028,IF(K$3=2027,FwdPJM27,FwdPJM28)*Inputs!$B$51,IF(K$3=2029,0.5*FwdPJM29*Inputs!$B$51+0.5*$C$9*K$4,$C$9*K$4)) -> 64.498468 | L23: =IF(L$3<=2028,IF(L$3=2027,FwdPJM27,FwdPJM28)*Inputs!$B$51,IF(L$3=2029,0.5*FwdPJM29*Inputs!$B$51+0.5*$C$9*L$4,$C$9*L$4)) -> 65.788438 | M23: =IF(M$3<=2028,IF(M$3=2027,FwdPJM27,FwdPJM28)*Inputs!$B$51,IF(M$3=2029,0.5*FwdPJM29*Inputs!$B$51+0.5*$C$9*M$4,$C$9*M$4)) -> 67.104207 | N23: =IF(N$3<=2028,IF(N$3=2027,FwdPJM27,FwdPJM28)*Inputs!$B$51,IF(N$3=2029,0.5*FwdPJM29*Inputs!$B$51+0.5*$C$9*N$4,$C$9*N$4)) -> 68.446291 | ... AS23: =IF(AS$3<=2028,IF(AS$3=2027,FwdPJM27,FwdPJM28)*Inputs!$B$51,IF(AS$3=2029,0.5*FwdPJM29*Inputs!$B$51+0.5*$C$9*AS$4,$C$9*AS$4)) -> 126.4606
A24: CAP|PJMA | B24: PJMA capacity, nominal $/MW-day | G24: =IF(G$3=2027,CapCY27,IF(G$3=2028,CapCY28,IF(G$3=2029,5/12*CapDY2829+7/12*PJMCap*G$4,PJMCap*G$4))) -> 331.66 | H24: =IF(H$3=2027,CapCY27,IF(H$3=2028,CapCY28,IF(H$3=2029,5/12*CapDY2829+7/12*PJMCap*H$4,PJMCap*H$4))) -> 328.52 | I24: =IF(I$3=2027,CapCY27,IF(I$3=2028,CapCY28,IF(I$3=2029,5/12*CapDY2829+7/12*PJMCap*I$4,PJMCap*I$4))) -> 277.79541 | J24: =IF(J$3=2027,CapCY27,IF(J$3=2028,CapCY28,IF(J$3=2029,5/12*CapDY2829+7/12*PJMCap*J$4,PJMCap*J$4))) -> 248.9594 | K24: =IF(K$3=2027,CapCY27,IF(K$3=2028,CapCY28,IF(K$3=2029,5/12*CapDY2829+7/12*PJMCap*K$4,PJMCap*K$4))) -> 253.93858 | L24: =IF(L$3=2027,CapCY27,IF(L$3=2028,CapCY28,IF(L$3=2029,5/12*CapDY2829+7/12*PJMCap*L$4,PJMCap*L$4))) -> 259.01736 | M24: =IF(M$3=2027,CapCY27,IF(M$3=2028,CapCY28,IF(M$3=2029,5/12*CapDY2829+7/12*PJMCap*M$4,PJMCap*M$4))) -> 264.1977 | N24: =IF(N$3=2027,CapCY27,IF(N$3=2028,CapCY28,IF(N$3=2029,5/12*CapDY2829+7/12*PJMCap*N$4,PJMCap*N$4))) -> 269.48166 | ... AS24: =IF(AS$3=2027,CapCY27,IF(AS$3=2028,CapCY28,IF(AS$3=2029,5/12*CapDY2829+7/12*PJMCap*AS$4,PJMCap*AS$4))) -> 497.8913
A25: GAS|NIHUB | B25: NIHUB gas, nominal $/MMBtu | G25: =(G$5+Inputs!$C$52)*G$4 -> 3.723 | H25: =(H$5+Inputs!$C$52)*H$4 -> 3.79746 | I25: =(I$5+Inputs!$C$52)*I$4 -> 3.97953 | J25: =(J$5+Inputs!$C$52)*J$4 -> 4.0591206 | K25: =(K$5+Inputs!$C$52)*K$4 -> 4.140303 | L25: =(L$5+Inputs!$C$52)*L$4 -> 4.2231091 | M25: =(M$5+Inputs!$C$52)*M$4 -> 4.3075713 | N25: =(N$5+Inputs!$C$52)*N$4 -> 4.3937227 | ... AS25: =(AS$5+Inputs!$C$52)*AS$4 -> 8.1177929
A26: ATC|NIHUB | B26: NIHUB ATC power, nominal $/MWh | G26: =IF(G$3<=2028,IF(G$3=2027,FwdPJM27,FwdPJM28)*Inputs!$B$52,IF(G$3=2029,0.5*FwdPJM29*Inputs!$B$52+0.5*$C$10*G$4,$C$10*G$4)) -> 61.2 | H26: =IF(H$3<=2028,IF(H$3=2027,FwdPJM27,FwdPJM28)*Inputs!$B$52,IF(H$3=2029,0.5*FwdPJM29*Inputs!$B$52+0.5*$C$10*H$4,$C$10*H$4)) -> 62.05 | I26: =IF(I$3<=2028,IF(I$3=2027,FwdPJM27,FwdPJM28)*Inputs!$B$52,IF(I$3=2029,0.5*FwdPJM29*Inputs!$B$52+0.5*$C$10*I$4,$C$10*I$4)) -> 56.912282 | J26: =IF(J$3<=2028,IF(J$3=2027,FwdPJM27,FwdPJM28)*Inputs!$B$52,IF(J$3=2029,0.5*FwdPJM29*Inputs!$B$52+0.5*$C$10*J$4,$C$10*J$4)) -> 55.411055 | K26: =IF(K$3<=2028,IF(K$3=2027,FwdPJM27,FwdPJM28)*Inputs!$B$52,IF(K$3=2029,0.5*FwdPJM29*Inputs!$B$52+0.5*$C$10*K$4,$C$10*K$4)) -> 56.519276 | L26: =IF(L$3<=2028,IF(L$3=2027,FwdPJM27,FwdPJM28)*Inputs!$B$52,IF(L$3=2029,0.5*FwdPJM29*Inputs!$B$52+0.5*$C$10*L$4,$C$10*L$4)) -> 57.649662 | M26: =IF(M$3<=2028,IF(M$3=2027,FwdPJM27,FwdPJM28)*Inputs!$B$52,IF(M$3=2029,0.5*FwdPJM29*Inputs!$B$52+0.5*$C$10*M$4,$C$10*M$4)) -> 58.802655 | N26: =IF(N$3<=2028,IF(N$3=2027,FwdPJM27,FwdPJM28)*Inputs!$B$52,IF(N$3=2029,0.5*FwdPJM29*Inputs!$B$52+0.5*$C$10*N$4,$C$10*N$4)) -> 59.978708 | ... AS26: =IF(AS$3<=2028,IF(AS$3=2027,FwdPJM27,FwdPJM28)*Inputs!$B$52,IF(AS$3=2029,0.5*FwdPJM29*Inputs!$B$52+0.5*$C$10*AS$4,$C$10*AS$4)) -> 110.81599
A27: CAP|NIHUB | B27: NIHUB capacity, nominal $/MW-day | G27: =IF(G$3=2027,CapCY27,IF(G$3=2028,CapCY28,IF(G$3=2029,5/12*CapDY2829+7/12*PJMCap*G$4,PJMCap*G$4))) -> 331.66 | H27: =IF(H$3=2027,CapCY27,IF(H$3=2028,CapCY28,IF(H$3=2029,5/12*CapDY2829+7/12*PJMCap*H$4,PJMCap*H$4))) -> 328.52 | I27: =IF(I$3=2027,CapCY27,IF(I$3=2028,CapCY28,IF(I$3=2029,5/12*CapDY2829+7/12*PJMCap*I$4,PJMCap*I$4))) -> 277.79541 | J27: =IF(J$3=2027,CapCY27,IF(J$3=2028,CapCY28,IF(J$3=2029,5/12*CapDY2829+7/12*PJMCap*J$4,PJMCap*J$4))) -> 248.9594 | K27: =IF(K$3=2027,CapCY27,IF(K$3=2028,CapCY28,IF(K$3=2029,5/12*CapDY2829+7/12*PJMCap*K$4,PJMCap*K$4))) -> 253.93858 | L27: =IF(L$3=2027,CapCY27,IF(L$3=2028,CapCY28,IF(L$3=2029,5/12*CapDY2829+7/12*PJMCap*L$4,PJMCap*L$4))) -> 259.01736 | M27: =IF(M$3=2027,CapCY27,IF(M$3=2028,CapCY28,IF(M$3=2029,5/12*CapDY2829+7/12*PJMCap*M$4,PJMCap*M$4))) -> 264.1977 | N27: =IF(N$3=2027,CapCY27,IF(N$3=2028,CapCY28,IF(N$3=2029,5/12*CapDY2829+7/12*PJMCap*N$4,PJMCap*N$4))) -> 269.48166 | ... AS27: =IF(AS$3=2027,CapCY27,IF(AS$3=2028,CapCY28,IF(AS$3=2029,5/12*CapDY2829+7/12*PJMCap*AS$4,PJMCap*AS$4))) -> 497.8913
A28: GAS|MISO | B28: MISO gas, nominal $/MMBtu | G28: =(G$5+Inputs!$C$53)*G$4 -> 3.774 | H28: =(H$5+Inputs!$C$53)*H$4 -> 3.84948 | I28: =(I$5+Inputs!$C$53)*I$4 -> 4.0325904 | J28: =(J$5+Inputs!$C$53)*J$4 -> 4.1132422 | K28: =(K$5+Inputs!$C$53)*K$4 -> 4.1955071 | L28: =(L$5+Inputs!$C$53)*L$4 -> 4.2794172 | M28: =(M$5+Inputs!$C$53)*M$4 -> 4.3650055 | N28: =(N$5+Inputs!$C$53)*N$4 -> 4.4523056 | ... AS28: =(AS$5+Inputs!$C$53)*AS$4 -> 8.2260301
A29: ATC|MISO | B29: MISO ATC power, nominal $/MWh | G29: =IF(G$3<=2028,IF(G$3=2027,FwdPJM27,FwdPJM28)*Inputs!$B$53,IF(G$3=2029,0.5*FwdPJM29*Inputs!$B$53+0.5*$C$11*G$4,$C$11*G$4)) -> 59.76 | H29: =IF(H$3<=2028,IF(H$3=2027,FwdPJM27,FwdPJM28)*Inputs!$B$53,IF(H$3=2029,0.5*FwdPJM29*Inputs!$B$53+0.5*$C$11*H$4,$C$11*H$4)) -> 60.59 | I29: =IF(I$3<=2028,IF(I$3=2027,FwdPJM27,FwdPJM28)*Inputs!$B$53,IF(I$3=2029,0.5*FwdPJM29*Inputs!$B$53+0.5*$C$11*I$4,$C$11*I$4)) -> 55.573169 | J29: =IF(J$3<=2028,IF(J$3=2027,FwdPJM27,FwdPJM28)*Inputs!$B$53,IF(J$3=2029,0.5*FwdPJM29*Inputs!$B$53+0.5*$C$11*J$4,$C$11*J$4)) -> 54.107266 | K29: =IF(K$3<=2028,IF(K$3=2027,FwdPJM27,FwdPJM28)*Inputs!$B$53,IF(K$3=2029,0.5*FwdPJM29*Inputs!$B$53+0.5*$C$11*K$4,$C$11*K$4)) -> 55.189411 | L29: =IF(L$3<=2028,IF(L$3=2027,FwdPJM27,FwdPJM28)*Inputs!$B$53,IF(L$3=2029,0.5*FwdPJM29*Inputs!$B$53+0.5*$C$11*L$4,$C$11*L$4)) -> 56.293199 | M29: =IF(M$3<=2028,IF(M$3=2027,FwdPJM27,FwdPJM28)*Inputs!$B$53,IF(M$3=2029,0.5*FwdPJM29*Inputs!$B$53+0.5*$C$11*M$4,$C$11*M$4)) -> 57.419063 | N29: =IF(N$3<=2028,IF(N$3=2027,FwdPJM27,FwdPJM28)*Inputs!$B$53,IF(N$3=2029,0.5*FwdPJM29*Inputs!$B$53+0.5*$C$11*N$4,$C$11*N$4)) -> 58.567445 | ... AS29: =IF(AS$3<=2028,IF(AS$3=2027,FwdPJM27,FwdPJM28)*Inputs!$B$53,IF(AS$3=2029,0.5*FwdPJM29*Inputs!$B$53+0.5*$C$11*AS$4,$C$11*AS$4)) -> 108.20856
A30: CAP|MISO | B30: MISO capacity, nominal $/MW-day | G30: =IF(G$3<=2028,OtherCapBase,OtherCap)*G$4 -> 112.2 | H30: =IF(H$3<=2028,OtherCapBase,OtherCap)*H$4 -> 114.444 | I30: =IF(I$3<=2028,OtherCapBase,OtherCap)*I$4 -> 116.73288 | J30: =IF(J$3<=2028,OtherCapBase,OtherCap)*J$4 -> 119.06754 | K30: =IF(K$3<=2028,OtherCapBase,OtherCap)*K$4 -> 121.44889 | L30: =IF(L$3<=2028,OtherCapBase,OtherCap)*L$4 -> 123.87787 | M30: =IF(M$3<=2028,OtherCapBase,OtherCap)*M$4 -> 126.35542 | N30: =IF(N$3<=2028,OtherCapBase,OtherCap)*N$4 -> 128.88253 | ... AS30: =IF(AS$3<=2028,OtherCapBase,OtherCap)*AS$4 -> 238.12192
A31: GAS|NY | B31: NY gas, nominal $/MMBtu | G31: =(G$5+Inputs!$C$54)*G$4 -> 3.978 | H31: =(H$5+Inputs!$C$54)*H$4 -> 4.05756 | I31: =(I$5+Inputs!$C$54)*I$4 -> 4.244832 | J31: =(J$5+Inputs!$C$54)*J$4 -> 4.3297286 | K31: =(K$5+Inputs!$C$54)*K$4 -> 4.4163232 | L31: =(L$5+Inputs!$C$54)*L$4 -> 4.5046497 | M31: =(M$5+Inputs!$C$54)*M$4 -> 4.5947427 | N31: =(N$5+Inputs!$C$54)*N$4 -> 4.6866375 | ... AS31: =(AS$5+Inputs!$C$54)*AS$4 -> 8.6589791
A32: ATC|NY | B32: NY ATC power, nominal $/MWh | G32: =IF(G$3<=2028,IF(G$3=2027,FwdPJM27,FwdPJM28)*Inputs!$B$54,IF(G$3=2029,0.5*FwdPJM29*Inputs!$B$54+0.5*$C$12*G$4,$C$12*G$4)) -> 64.8 | H32: =IF(H$3<=2028,IF(H$3=2027,FwdPJM27,FwdPJM28)*Inputs!$B$54,IF(H$3=2029,0.5*FwdPJM29*Inputs!$B$54+0.5*$C$12*H$4,$C$12*H$4)) -> 65.7 | I32: =IF(I$3<=2028,IF(I$3=2027,FwdPJM27,FwdPJM28)*Inputs!$B$54,IF(I$3=2029,0.5*FwdPJM29*Inputs!$B$54+0.5*$C$12*I$4,$C$12*I$4)) -> 60.260063 | J32: =IF(J$3<=2028,IF(J$3=2027,FwdPJM27,FwdPJM28)*Inputs!$B$54,IF(J$3=2029,0.5*FwdPJM29*Inputs!$B$54+0.5*$C$12*J$4,$C$12*J$4)) -> 58.670529 | K32: =IF(K$3<=2028,IF(K$3=2027,FwdPJM27,FwdPJM28)*Inputs!$B$54,IF(K$3=2029,0.5*FwdPJM29*Inputs!$B$54+0.5*$C$12*K$4,$C$12*K$4)) -> 59.84394 | L32: =IF(L$3<=2028,IF(L$3=2027,FwdPJM27,FwdPJM28)*Inputs!$B$54,IF(L$3=2029,0.5*FwdPJM29*Inputs!$B$54+0.5*$C$12*L$4,$C$12*L$4)) -> 61.040819 | M32: =IF(M$3<=2028,IF(M$3=2027,FwdPJM27,FwdPJM28)*Inputs!$B$54,IF(M$3=2029,0.5*FwdPJM29*Inputs!$B$54+0.5*$C$12*M$4,$C$12*M$4)) -> 62.261635 | N32: =IF(N$3<=2028,IF(N$3=2027,FwdPJM27,FwdPJM28)*Inputs!$B$54,IF(N$3=2029,0.5*FwdPJM29*Inputs!$B$54+0.5*$C$12*N$4,$C$12*N$4)) -> 63.506868 | ... AS32: =IF(AS$3<=2028,IF(AS$3=2027,FwdPJM27,FwdPJM28)*Inputs!$B$54,IF(AS$3=2029,0.5*FwdPJM29*Inputs!$B$54+0.5*$C$12*AS$4,$C$12*AS$4)) -> 117.33458
A33: CAP|NY | B33: NY capacity, nominal $/MW-day | G33: =IF(G$3<=2028,OtherCapBase,OtherCap)*G$4 -> 112.2 | H33: =IF(H$3<=2028,OtherCapBase,OtherCap)*H$4 -> 114.444 | I33: =IF(I$3<=2028,OtherCapBase,OtherCap)*I$4 -> 116.73288 | J33: =IF(J$3<=2028,OtherCapBase,OtherCap)*J$4 -> 119.06754 | K33: =IF(K$3<=2028,OtherCapBase,OtherCap)*K$4 -> 121.44889 | L33: =IF(L$3<=2028,OtherCapBase,OtherCap)*L$4 -> 123.87787 | M33: =IF(M$3<=2028,OtherCapBase,OtherCap)*M$4 -> 126.35542 | N33: =IF(N$3<=2028,OtherCapBase,OtherCap)*N$4 -> 128.88253 | ... AS33: =IF(AS$3<=2028,OtherCapBase,OtherCap)*AS$4 -> 238.12192
A34: GAS|NE | B34: NE gas, nominal $/MMBtu | G34: =(G$5+Inputs!$C$55)*G$4 -> 5.406 | H34: =(H$5+Inputs!$C$55)*H$4 -> 5.51412 | I34: =(I$5+Inputs!$C$55)*I$4 -> 5.7305232 | J34: =(J$5+Inputs!$C$55)*J$4 -> 5.8451337 | K34: =(K$5+Inputs!$C$55)*K$4 -> 5.9620363 | L34: =(L$5+Inputs!$C$55)*L$4 -> 6.0812771 | M34: =(M$5+Inputs!$C$55)*M$4 -> 6.2029026 | N34: =(N$5+Inputs!$C$55)*N$4 -> 6.3269607 | ... AS34: =(AS$5+Inputs!$C$55)*AS$4 -> 11.689622
A35: ATC|NE | B35: NE ATC power, nominal $/MWh | G35: =IF(G$3<=2028,IF(G$3=2027,FwdPJM27,FwdPJM28)*Inputs!$B$55,IF(G$3=2029,0.5*FwdPJM29*Inputs!$B$55+0.5*$C$13*G$4,$C$13*G$4)) -> 77.76 | H35: =IF(H$3<=2028,IF(H$3=2027,FwdPJM27,FwdPJM28)*Inputs!$B$55,IF(H$3=2029,0.5*FwdPJM29*Inputs!$B$55+0.5*$C$13*H$4,$C$13*H$4)) -> 78.84 | I35: =IF(I$3<=2028,IF(I$3=2027,FwdPJM27,FwdPJM28)*Inputs!$B$55,IF(I$3=2029,0.5*FwdPJM29*Inputs!$B$55+0.5*$C$13*I$4,$C$13*I$4)) -> 72.312076 | J35: =IF(J$3<=2028,IF(J$3=2027,FwdPJM27,FwdPJM28)*Inputs!$B$55,IF(J$3=2029,0.5*FwdPJM29*Inputs!$B$55+0.5*$C$13*J$4,$C$13*J$4)) -> 70.404635 | K35: =IF(K$3<=2028,IF(K$3=2027,FwdPJM27,FwdPJM28)*Inputs!$B$55,IF(K$3=2029,0.5*FwdPJM29*Inputs!$B$55+0.5*$C$13*K$4,$C$13*K$4)) -> 71.812728 | L35: =IF(L$3<=2028,IF(L$3=2027,FwdPJM27,FwdPJM28)*Inputs!$B$55,IF(L$3=2029,0.5*FwdPJM29*Inputs!$B$55+0.5*$C$13*L$4,$C$13*L$4)) -> 73.248982 | M35: =IF(M$3<=2028,IF(M$3=2027,FwdPJM27,FwdPJM28)*Inputs!$B$55,IF(M$3=2029,0.5*FwdPJM29*Inputs!$B$55+0.5*$C$13*M$4,$C$13*M$4)) -> 74.713962 | N35: =IF(N$3<=2028,IF(N$3=2027,FwdPJM27,FwdPJM28)*Inputs!$B$55,IF(N$3=2029,0.5*FwdPJM29*Inputs!$B$55+0.5*$C$13*N$4,$C$13*N$4)) -> 76.208241 | ... AS35: =IF(AS$3<=2028,IF(AS$3=2027,FwdPJM27,FwdPJM28)*Inputs!$B$55,IF(AS$3=2029,0.5*FwdPJM29*Inputs!$B$55+0.5*$C$13*AS$4,$C$13*AS$4)) -> 140.80149
A36: CAP|NE | B36: NE capacity, nominal $/MW-day | G36: =IF(G$3<=2028,OtherCapBase,OtherCap)*G$4 -> 112.2 | H36: =IF(H$3<=2028,OtherCapBase,OtherCap)*H$4 -> 114.444 | I36: =IF(I$3<=2028,OtherCapBase,OtherCap)*I$4 -> 116.73288 | J36: =IF(J$3<=2028,OtherCapBase,OtherCap)*J$4 -> 119.06754 | K36: =IF(K$3<=2028,OtherCapBase,OtherCap)*K$4 -> 121.44889 | L36: =IF(L$3<=2028,OtherCapBase,OtherCap)*L$4 -> 123.87787 | M36: =IF(M$3<=2028,OtherCapBase,OtherCap)*M$4 -> 126.35542 | N36: =IF(N$3<=2028,OtherCapBase,OtherCap)*N$4 -> 128.88253 | ... AS36: =IF(AS$3<=2028,OtherCapBase,OtherCap)*AS$4 -> 238.12192
A37: GAS|WEST | B37: WEST gas, nominal $/MMBtu | G37: =(G$5+Inputs!$C$56)*G$4 -> 4.59 | H37: =(H$5+Inputs!$C$56)*H$4 -> 4.6818 | I37: =(I$5+Inputs!$C$56)*I$4 -> 4.8815568 | J37: =(J$5+Inputs!$C$56)*J$4 -> 4.9791879 | K37: =(K$5+Inputs!$C$56)*K$4 -> 5.0787717 | L37: =(L$5+Inputs!$C$56)*L$4 -> 5.1803471 | M37: =(M$5+Inputs!$C$56)*M$4 -> 5.2839541 | N37: =(N$5+Inputs!$C$56)*N$4 -> 5.3896332 | ... AS37: =(AS$5+Inputs!$C$56)*AS$4 -> 9.9578259
A38: ATC|WEST | B38: WEST ATC power, nominal $/MWh | G38: =IF(G$3<=2028,IF(G$3=2027,FwdPJM27,FwdPJM28)*Inputs!$B$56,IF(G$3=2029,0.5*FwdPJM29*Inputs!$B$56+0.5*$C$14*G$4,$C$14*G$4)) -> 66.24 | H38: =IF(H$3<=2028,IF(H$3=2027,FwdPJM27,FwdPJM28)*Inputs!$B$56,IF(H$3=2029,0.5*FwdPJM29*Inputs!$B$56+0.5*$C$14*H$4,$C$14*H$4)) -> 67.16 | I38: =IF(I$3<=2028,IF(I$3=2027,FwdPJM27,FwdPJM28)*Inputs!$B$56,IF(I$3=2029,0.5*FwdPJM29*Inputs!$B$56+0.5*$C$14*I$4,$C$14*I$4)) -> 61.599176 | J38: =IF(J$3<=2028,IF(J$3=2027,FwdPJM27,FwdPJM28)*Inputs!$B$56,IF(J$3=2029,0.5*FwdPJM29*Inputs!$B$56+0.5*$C$14*J$4,$C$14*J$4)) -> 59.974319 | K38: =IF(K$3<=2028,IF(K$3=2027,FwdPJM27,FwdPJM28)*Inputs!$B$56,IF(K$3=2029,0.5*FwdPJM29*Inputs!$B$56+0.5*$C$14*K$4,$C$14*K$4)) -> 61.173805 | L38: =IF(L$3<=2028,IF(L$3=2027,FwdPJM27,FwdPJM28)*Inputs!$B$56,IF(L$3=2029,0.5*FwdPJM29*Inputs!$B$56+0.5*$C$14*L$4,$C$14*L$4)) -> 62.397281 | M38: =IF(M$3<=2028,IF(M$3=2027,FwdPJM27,FwdPJM28)*Inputs!$B$56,IF(M$3=2029,0.5*FwdPJM29*Inputs!$B$56+0.5*$C$14*M$4,$C$14*M$4)) -> 63.645227 | N38: =IF(N$3<=2028,IF(N$3=2027,FwdPJM27,FwdPJM28)*Inputs!$B$56,IF(N$3=2029,0.5*FwdPJM29*Inputs!$B$56+0.5*$C$14*N$4,$C$14*N$4)) -> 64.918131 | ... AS38: =IF(AS$3<=2028,IF(AS$3=2027,FwdPJM27,FwdPJM28)*Inputs!$B$56,IF(AS$3=2029,0.5*FwdPJM29*Inputs!$B$56+0.5*$C$14*AS$4,$C$14*AS$4)) -> 119.94201
A39: CAP|WEST | B39: WEST capacity, nominal $/MW-day | G39: =IF(G$3<=2028,WestCapBase,WestCap)*G$4 -> 224.4 | H39: =IF(H$3<=2028,WestCapBase,WestCap)*H$4 -> 228.888 | I39: =IF(I$3<=2028,WestCapBase,WestCap)*I$4 -> 233.46576 | J39: =IF(J$3<=2028,WestCapBase,WestCap)*J$4 -> 238.13508 | K39: =IF(K$3<=2028,WestCapBase,WestCap)*K$4 -> 242.89778 | L39: =IF(L$3<=2028,WestCapBase,WestCap)*L$4 -> 247.75573 | M39: =IF(M$3<=2028,WestCapBase,WestCap)*M$4 -> 252.71085 | N39: =IF(N$3<=2028,WestCapBase,WestCap)*N$4 -> 257.76506 | ... AS39: =IF(AS$3<=2028,WestCapBase,WestCap)*AS$4 -> 476.24385
A40: GAS|ERCOT | B40: ERCOT gas, nominal $/MMBtu | G40: =(G$5+Inputs!$C$57)*G$4 -> 3.825 | H40: =(H$5+Inputs!$C$57)*H$4 -> 3.9015 | I40: =(I$5+Inputs!$C$57)*I$4 -> 4.0856508 | J40: =(J$5+Inputs!$C$57)*J$4 -> 4.1673638 | K40: =(K$5+Inputs!$C$57)*K$4 -> 4.2507111 | L40: =(L$5+Inputs!$C$57)*L$4 -> 4.3357253 | M40: =(M$5+Inputs!$C$57)*M$4 -> 4.4224398 | N40: =(N$5+Inputs!$C$57)*N$4 -> 4.5108886 | ... AS40: =(AS$5+Inputs!$C$57)*AS$4 -> 8.3342674
A41: ATC|ERCOT | B41: ERCOT ATC power, nominal $/MWh | G41: =IF(G$3<=2028,IF(G$3=2027,FwdERC27,FwdERC28)*1,IF(G$3=2029,0.5*FwdERC29*1+0.5*$C$15*G$4,$C$15*G$4)) -> 49 | H41: =IF(H$3<=2028,IF(H$3=2027,FwdERC27,FwdERC28)*1,IF(H$3=2029,0.5*FwdERC29*1+0.5*$C$15*H$4,$C$15*H$4)) -> 51 | I41: =IF(I$3<=2028,IF(I$3=2027,FwdERC27,FwdERC28)*1,IF(I$3=2029,0.5*FwdERC29*1+0.5*$C$15*I$4,$C$15*I$4)) -> 52.55673 | J41: =IF(J$3<=2028,IF(J$3=2027,FwdERC27,FwdERC28)*1,IF(J$3=2029,0.5*FwdERC29*1+0.5*$C$15*J$4,$C$15*J$4)) -> 54.17573 | K41: =IF(K$3<=2028,IF(K$3=2027,FwdERC27,FwdERC28)*1,IF(K$3=2029,0.5*FwdERC29*1+0.5*$C$15*K$4,$C$15*K$4)) -> 55.259244 | L41: =IF(L$3<=2028,IF(L$3=2027,FwdERC27,FwdERC28)*1,IF(L$3=2029,0.5*FwdERC29*1+0.5*$C$15*L$4,$C$15*L$4)) -> 56.364429 | M41: =IF(M$3<=2028,IF(M$3=2027,FwdERC27,FwdERC28)*1,IF(M$3=2029,0.5*FwdERC29*1+0.5*$C$15*M$4,$C$15*M$4)) -> 57.491718 | N41: =IF(N$3<=2028,IF(N$3=2027,FwdERC27,FwdERC28)*1,IF(N$3=2029,0.5*FwdERC29*1+0.5*$C$15*N$4,$C$15*N$4)) -> 58.641552 | ... AS41: =IF(AS$3<=2028,IF(AS$3=2027,FwdERC27,FwdERC28)*1,IF(AS$3=2029,0.5*FwdERC29*1+0.5*$C$15*AS$4,$C$15*AS$4)) -> 108.34548
A42: CAP|ERCOT | B42: ERCOT capacity, nominal $/MW-day | G42: =0 -> 0 | H42: =0 -> 0 | I42: =0 -> 0 | J42: =0 -> 0 | K42: =0 -> 0 | L42: =0 -> 0 | M42: =0 -> 0 | N42: =0 -> 0 | ... AS42: =0 -> 0

Sheet CEG_Assets
A1: Asset | B1: Tech | C1: Hub | D1: MW | E1: Start year | F1: End year | G1: Avg in-service year (COD) | H1: Method (Cashflow / $/kW) | I1: Capacity factor | J1: Capture (x ATC) | K1: Heat rate | L1: Fuel price override (2026$/MMBtu) | M1: Variable O&M ($/MWh) | N1: Fuel ($/MWh) | O1: O&M ($/MWh) | P1: Capex ($/MWh) | Q1: Per-MWh cost escalator | R1: Fixed O&M ($/kW-yr) | S1: Sust. capex ($/kW-yr) | T1: Capacity accreditation | U1: ZEC ($/MWh) | V1: ZEC last year | W1: 45U eligible | X1: Dispatch check | Y1: Mothball floor | Z1: Contract MW | AA1: Contract start | AB1: Contract end | AC1: Contract ramp (yrs) | AD1: PPA price ($/MWh, nominal flat) | AE1: Merchant discount rate | AF1: Contract discount rate | AG1: One-off capex ($mm) | AH1: One-off capex year | AI1: $/kW value (if $/kW method) | AJ1: Replacement cost ($/kW) | AK1: Remaining-life override | AL1: Remaining-life fraction | AM1: Depreciated replacement cost ($mm) | AN1: ATC row | AO1: Gas row | AP1: Cap row | AQ1: Asset NAV ($mm) | AR1: NAV $/kW
A2: Nuclear - PJM East (Limerick, Peach Bottom 50%, Calvert Cliffs, Salem 42.6%) | B2: nuclear | C2: PJMW | D2: 6430 | E2: 2027 | F2: 2055 | G2: 1979 | H2: Cashflow | I2: =Inputs!$B$61 -> 0.935 | J2: =Inputs!$F$50 -> 0.99 | K2: =Inputs!$D$61 -> 0 | M2: =Inputs!$F$61 -> 0 | N2: =Inputs!$G$61 -> 5.5 | O2: =Inputs!$H$61 -> 22.3 | P2: =Inputs!$I$61 -> 7.7 | Q2: =Inputs!$J$61 -> 0.025 | R2: =Inputs!$K$61 -> 0 | S2: =Inputs!$L$61 -> 0 | T2: =Inputs!$M$61 -> 0.95 | U2: 0 | V2: 2026 | W2: =Inputs!$R$61 -> 1 | X2: =Inputs!$P$61 -> 0 | Y2: =Inputs!$Q$61 -> 0 | Z2: 0 | AA2: 2026 | AB2: 2026 | AC2: 1 | AD2: 0 | AE2: =Inputs!$N$61 -> 0.08 | AF2: =Inputs!$O$61 -> 0.0675 | AG2: 0 | AH2: 2026 | AJ2: =NucRC -> 4500 | AL2: =IF(ISNUMBER(AK2),AK2,MAX(0,MIN(1,(F2+1-ValDate)/(F2+1-G2)))) -> 0.37987013 | AM2: =D2*AJ2*AL2/1000 -> 10991.542 | AN2: =MATCH("ATC|"&C2,Prices!$A:$A,0) -> 20 | AO2: =MATCH("GAS|"&C2,Prices!$A:$A,0) -> 19 | AP2: =MATCH("CAP|"&C2,Prices!$A:$A,0) -> 21 | AQ2: =CEG_Model!C61+CEG_Model!C62+CEG_Model!C63 -> 20063.905 | AR2: =IF(D2=0,0,AQ2/D2*1000) -> 3120.3584
A3: Nuclear - PJM ComEd (Byron, Braidwood, LaSalle, Dresden, Quad Cities 75%) | B3: nuclear | C3: NIHUB | D3: 10300 | E3: 2027 | F3: 2055 | G3: 1980 | H3: Cashflow | I3: =Inputs!$B$61 -> 0.935 | J3: =Inputs!$F$52 -> 0.99 | K3: =Inputs!$D$61 -> 0 | M3: =Inputs!$F$61 -> 0 | N3: =Inputs!$G$61 -> 5.5 | O3: =Inputs!$H$61 -> 22.3 | P3: =Inputs!$I$61 -> 7.7 | Q3: =Inputs!$J$61 -> 0.025 | R3: =Inputs!$K$61 -> 0 | S3: =Inputs!$L$61 -> 0 | T3: =Inputs!$M$61 -> 0.95 | U3: 0 | V3: 2026 | W3: =Inputs!$R$61 -> 1 | X3: =Inputs!$P$61 -> 0 | Y3: =Inputs!$Q$61 -> 0 | Z3: 920 | AA3: 2027 | AB3: 2046 | AC3: 1 | AD3: 85 | AE3: =Inputs!$N$61 -> 0.08 | AF3: =Inputs!$O$61 -> 0.0675 | AG3: 0 | AH3: 2026 | AJ3: =NucRC -> 4500 | AL3: =IF(ISNUMBER(AK3),AK3,MAX(0,MIN(1,(F3+1-ValDate)/(F3+1-G3)))) -> 0.38486842 | AM3: =D3*AJ3*AL3/1000 -> 17838.651 | AN3: =MATCH("ATC|"&C3,Prices!$A:$A,0) -> 26 | AO3: =MATCH("GAS|"&C3,Prices!$A:$A,0) -> 25 | AP3: =MATCH("CAP|"&C3,Prices!$A:$A,0) -> 27 | AQ3: =CEG_Model!C91+CEG_Model!C92+CEG_Model!C93 -> 24343.611 | AR3: =IF(D3=0,0,AQ3/D3*1000) -> 2363.4574
A4: Nuclear - Clinton (MISO) - Meta 20-yr PPA | B4: nuclear | C4: MISO | D4: 1080 | E4: 2027 | F4: 2055 | G4: 1987 | H4: Cashflow | I4: =Inputs!$B$61 -> 0.935 | J4: =Inputs!$F$53 -> 0.99 | K4: =Inputs!$D$61 -> 0 | M4: =Inputs!$F$61 -> 0 | N4: =Inputs!$G$61 -> 5.5 | O4: =Inputs!$H$61 -> 22.3 | P4: =Inputs!$I$61 -> 7.7 | Q4: =Inputs!$J$61 -> 0.025 | R4: =Inputs!$K$61 -> 0 | S4: =Inputs!$L$61 -> 0 | T4: =Inputs!$M$61 -> 0.95 | U4: 0 | V4: 2026 | W4: =Inputs!$R$61 -> 1 | X4: =Inputs!$P$61 -> 0 | Y4: =Inputs!$Q$61 -> 0 | Z4: 1080 | AA4: 2027 | AB4: 2046 | AC4: 1 | AD4: 80 | AE4: =Inputs!$N$61 -> 0.08 | AF4: =Inputs!$O$61 -> 0.0675 | AG4: 0 | AH4: 2026 | AJ4: =NucRC -> 4500 | AL4: =IF(ISNUMBER(AK4),AK4,MAX(0,MIN(1,(F4+1-ValDate)/(F4+1-G4)))) -> 0.42391304 | AM4: =D4*AJ4*AL4/1000 -> 2060.2174 | AN4: =MATCH("ATC|"&C4,Prices!$A:$A,0) -> 29 | AO4: =MATCH("GAS|"&C4,Prices!$A:$A,0) -> 28 | AP4: =MATCH("CAP|"&C4,Prices!$A:$A,0) -> 30 | AQ4: =CEG_Model!C121+CEG_Model!C122+CEG_Model!C123 -> 3012.4773 | AR4: =IF(D4=0,0,AQ4/D4*1000) -> 2789.3308
A5: Nuclear - New York (Nine Mile Pt, Ginna, FitzPatrick) | B5: nuclear | C5: NY | D5: 3000 | E5: 2027 | F5: 2055 | G5: 1974 | H5: Cashflow | I5: =Inputs!$B$61 -> 0.935 | J5: =Inputs!$F$54 -> 0.99 | K5: =Inputs!$D$61 -> 0 | M5: =Inputs!$F$61 -> 0 | N5: =Inputs!$G$61 -> 5.5 | O5: =Inputs!$H$61 -> 22.3 | P5: =Inputs!$I$61 -> 7.7 | Q5: =Inputs!$J$61 -> 0.025 | R5: =Inputs!$K$61 -> 0 | S5: =Inputs!$L$61 -> 0 | T5: =Inputs!$M$61 -> 0.95 | U5: 18 | V5: 2029 | W5: =Inputs!$R$61 -> 1 | X5: =Inputs!$P$61 -> 0 | Y5: =Inputs!$Q$61 -> 0 | Z5: 0 | AA5: 2026 | AB5: 2026 | AC5: 1 | AD5: 0 | AE5: =Inputs!$N$61 -> 0.08 | AF5: =Inputs!$O$61 -> 0.0675 | AG5: 0 | AH5: 2026 | AJ5: =NucRC -> 4500 | AL5: =IF(ISNUMBER(AK5),AK5,MAX(0,MIN(1,(F5+1-ValDate)/(F5+1-G5)))) -> 0.35670732 | AM5: =D5*AJ5*AL5/1000 -> 4815.5488 | AN5: =MATCH("ATC|"&C5,Prices!$A:$A,0) -> 32 | AO5: =MATCH("GAS|"&C5,Prices!$A:$A,0) -> 31 | AP5: =MATCH("CAP|"&C5,Prices!$A:$A,0) -> 33 | AQ5: =CEG_Model!C151+CEG_Model!C152+CEG_Model!C153 -> 7040.1687 | AR5: =IF(D5=0,0,AQ5/D5*1000) -> 2346.7229
A6: Nuclear - South Texas Project 44% (ERCOT) | B6: nuclear | C6: ERCOT | D6: 1165 | E6: 2027 | F6: 2055 | G6: 1988 | H6: Cashflow | I6: =Inputs!$B$61 -> 0.935 | J6: =Inputs!$F$57 -> 0.95 | K6: =Inputs!$D$61 -> 0 | M6: =Inputs!$F$61 -> 0 | N6: =Inputs!$G$61 -> 5.5 | O6: =Inputs!$H$61 -> 22.3 | P6: =Inputs!$I$61 -> 7.7 | Q6: =Inputs!$J$61 -> 0.025 | R6: =Inputs!$K$61 -> 0 | S6: =Inputs!$L$61 -> 0 | T6: =Inputs!$M$61 -> 0.95 | U6: 0 | V6: 2026 | W6: =Inputs!$R$61 -> 1 | X6: =Inputs!$P$61 -> 0 | Y6: =Inputs!$Q$61 -> 0 | Z6: 0 | AA6: 2026 | AB6: 2026 | AC6: 1 | AD6: 0 | AE6: =Inputs!$N$61 -> 0.08 | AF6: =Inputs!$O$61 -> 0.0675 | AG6: 0 | AH6: 2026 | AJ6: =NucRC -> 4500 | AL6: =IF(ISNUMBER(AK6),AK6,MAX(0,MIN(1,(F6+1-ValDate)/(F6+1-G6)))) -> 0.43014706 | AM6: =D6*AJ6*AL6/1000 -> 2255.046 | AN6: =MATCH("ATC|"&C6,Prices!$A:$A,0) -> 41 | AO6: =MATCH("GAS|"&C6,Prices!$A:$A,0) -> 40 | AP6: =MATCH("CAP|"&C6,Prices!$A:$A,0) -> 42 | AQ6: =CEG_Model!C181+CEG_Model!C182+CEG_Model!C183 -> 1049.5306 | AR6: =IF(D6=0,0,AQ6/D6*1000) -> 900.8846
A7: Nuclear - Crane restart (TMI-1) - Microsoft 20-yr PPA | B7: nuclear | C7: PJMW | D7: 835 | E7: 2028 | F7: 2054 | G7: 1974 | H7: Cashflow | I7: =Inputs!$B$61 -> 0.935 | J7: =Inputs!$F$50 -> 0.99 | K7: =Inputs!$D$61 -> 0 | M7: =Inputs!$F$61 -> 0 | N7: =Inputs!$G$61 -> 5.5 | O7: =Inputs!$H$61 -> 22.3 | P7: =Inputs!$I$61 -> 7.7 | Q7: =Inputs!$J$61 -> 0.025 | R7: =Inputs!$K$61 -> 0 | S7: =Inputs!$L$61 -> 0 | T7: =Inputs!$M$61 -> 0.95 | U7: 0 | V7: 2026 | W7: =Inputs!$R$61 -> 1 | X7: =Inputs!$P$61 -> 0 | Y7: =Inputs!$Q$61 -> 0 | Z7: 835 | AA7: 2028 | AB7: 2047 | AC7: 1 | AD7: 100 | AE7: =Inputs!$N$61 -> 0.08 | AF7: =Inputs!$O$61 -> 0.0675 | AG7: 500 | AH7: 2027 | AJ7: =NucRC -> 4500 | AL7: =IF(ISNUMBER(AK7),AK7,MAX(0,MIN(1,(F7+1-ValDate)/(F7+1-G7)))) -> 0.34876543 | AM7: =D7*AJ7*AL7/1000 -> 1310.4861 | AN7: =MATCH("ATC|"&C7,Prices!$A:$A,0) -> 20 | AO7: =MATCH("GAS|"&C7,Prices!$A:$A,0) -> 19 | AP7: =MATCH("CAP|"&C7,Prices!$A:$A,0) -> 21 | AQ7: =CEG_Model!C211+CEG_Model!C212+CEG_Model!C213 -> 2982.9966 | AR7: =IF(D7=0,0,AQ7/D7*1000) -> 3572.451
A8: Hydro - Conowingo + Muddy Run pumped storage (PJM) | B8: hydro | C8: PJMW | D8: 1642 | E8: 2027 | F8: 2055 | H8: Cashflow | I8: =Inputs!$B$65 -> 0.2 | J8: =Inputs!$C$65 -> 1.3 | K8: =Inputs!$D$65 -> 0 | M8: =Inputs!$F$65 -> 0 | N8: =Inputs!$G$65 -> 0 | O8: =Inputs!$H$65 -> 0 | P8: =Inputs!$I$65 -> 0 | Q8: =Inputs!$J$65 -> 0 | R8: =Inputs!$K$65 -> 40 | S8: =Inputs!$L$65 -> 0 | T8: =Inputs!$M$65 -> 0.7 | U8: 0 | V8: 2026 | W8: =Inputs!$R$65 -> 0 | X8: =Inputs!$P$65 -> 0 | Y8: =Inputs!$Q$65 -> 0 | Z8: 0 | AA8: 2026 | AB8: 2026 | AC8: 1 | AD8: 0 | AE8: =Inputs!$N$65 -> 0.08 | AF8: =Inputs!$O$65 -> 0.08 | AG8: 0 | AH8: 2026 | AJ8: =Inputs!$S$65 -> 3500 | AK8: 0.5 | AL8: =IF(ISNUMBER(AK8),AK8,MAX(0,MIN(1,(F8+1-ValDate)/(F8+1-G8)))) -> 0.5 | AM8: =D8*AJ8*AL8/1000 -> 2873.5 | AN8: =MATCH("ATC|"&C8,Prices!$A:$A,0) -> 20 | AO8: =MATCH("GAS|"&C8,Prices!$A:$A,0) -> 19 | AP8: =MATCH("CAP|"&C8,Prices!$A:$A,0) -> 21 | AQ8: =CEG_Model!C241+CEG_Model!C242+CEG_Model!C243 -> 3003.5869 | AR8: =IF(D8=0,0,AQ8/D8*1000) -> 1829.2247
A9: Wind & solar (legacy CEG, ~1.9 GW) | B9: renewable | C9: PJMW | D9: 1900 | E9: 2027 | F9: 2026 | H9: $/kW | I9: 0 | J9: 0 | K9: 0 | M9: 0 | N9: 0 | O9: 0 | P9: 0 | Q9: 0 | R9: 0 | S9: 0 | T9: 0 | U9: 0 | V9: 2026 | W9: 0 | X9: 0 | Y9: 0 | Z9: 0 | AA9: 2026 | AB9: 2026 | AC9: 1 | AD9: 0 | AE9: 0.08 | AF9: 0.08 | AG9: 0 | AH9: 2026 | AI9: 450 | AJ9: =Inputs!$S$67 -> 1600 | AK9: 0.35 | AL9: =IF(ISNUMBER(AK9),AK9,MAX(0,MIN(1,(F9+1-ValDate)/(F9+1-G9)))) -> 0.35 | AM9: =D9*AJ9*AL9/1000 -> 1064 | AN9: =MATCH("ATC|"&C9,Prices!$A:$A,0) -> 20 | AO9: =MATCH("GAS|"&C9,Prices!$A:$A,0) -> 19 | AP9: =MATCH("CAP|"&C9,Prices!$A:$A,0) -> 21 | AQ9: =CEG_Model!C271+CEG_Model!C272+CEG_Model!C273 -> 855 | AR9: =IF(D9=0,0,AQ9/D9*1000) -> 450
A10: Gas - ERCOT CCGT (Colorado Bend II, Wolf Hollow II, etc.) | B10: ccgt | C10: ERCOT | D10: 2300 | E10: 2027 | F10: 2050 | G10: 2017 | H10: Cashflow | I10: =Inputs!$D$57 -> 0.55 | J10: =Inputs!$E$57 -> 1.2 | K10: =Inputs!$D$62 -> 7.2 | M10: =Inputs!$F$62 -> 3.5 | N10: =Inputs!$G$62 -> 0 | O10: =Inputs!$H$62 -> 0 | P10: =Inputs!$I$62 -> 0 | Q10: =Inputs!$J$62 -> 0 | R10: =Inputs!$K$62 -> 32 | S10: =Inputs!$L$62 -> 12 | T10: =Inputs!$M$62 -> 0.78 | U10: 0 | V10: 2026 | W10: =Inputs!$R$62 -> 0 | X10: =Inputs!$P$62 -> 1 | Y10: =Inputs!$Q$62 -> 1 | Z10: 0 | AA10: 2026 | AB10: 2026 | AC10: 1 | AD10: 0 | AE10: =Inputs!$N$62 -> 0.095 | AF10: =Inputs!$O$62 -> 0.095 | AG10: 0 | AH10: 2026 | AJ10: =Inputs!$S$62 -> 2350 | AL10: =IF(ISNUMBER(AK10),AK10,MAX(0,MIN(1,(F10+1-ValDate)/(F10+1-G10)))) -> 0.71323529 | AM10: =D10*AJ10*AL10/1000 -> 3855.0368 | AN10: =MATCH("ATC|"&C10,Prices!$A:$A,0) -> 41 | AO10: =MATCH("GAS|"&C10,Prices!$A:$A,0) -> 40 | AP10: =MATCH("CAP|"&C10,Prices!$A:$A,0) -> 42 | AQ10: =CEG_Model!C301+CEG_Model!C302+CEG_Model!C303 -> 1746.9661 | AR10: =IF(D10=0,0,AQ10/D10*1000) -> 759.55047
A11: Gas/oil - ERCOT peakers & steam (legacy CEG) | B11: peaker | C11: ERCOT | D11: 1277 | E11: 2027 | F11: 2038 | G11: 1990 | H11: Cashflow | I11: =Inputs!$B$63 -> 0.06 | J11: =ScarcityERC -> 2.5 | K11: =Inputs!$D$63 -> 10.5 | M11: =Inputs!$F$63 -> 5 | N11: =Inputs!$G$63 -> 0 | O11: =Inputs!$H$63 -> 0 | P11: =Inputs!$I$63 -> 0 | Q11: =Inputs!$J$63 -> 0 | R11: =Inputs!$K$63 -> 18 | S11: =Inputs!$L$63 -> 5 | T11: =Inputs!$M$63 -> 0.6 | U11: 0 | V11: 2026 | W11: =Inputs!$R$63 -> 0 | X11: =Inputs!$P$63 -> 1 | Y11: =Inputs!$Q$63 -> 1 | Z11: 0 | AA11: 2026 | AB11: 2026 | AC11: 1 | AD11: 0 | AE11: =Inputs!$N$63 -> 0.1 | AF11: =Inputs!$O$63 -> 0.1 | AG11: 0 | AH11: 2026 | AJ11: =Inputs!$S$63 -> 1970 | AL11: =IF(ISNUMBER(AK11),AK11,MAX(0,MIN(1,(F11+1-ValDate)/(F11+1-G11)))) -> 0.25 | AM11: =D11*AJ11*AL11/1000 -> 628.9225 | AN11: =MATCH("ATC|"&C11,Prices!$A:$A,0) -> 41 | AO11: =MATCH("GAS|"&C11,Prices!$A:$A,0) -> 40 | AP11: =MATCH("CAP|"&C11,Prices!$A:$A,0) -> 42 | AQ11: =CEG_Model!C331+CEG_Model!C332+CEG_Model!C333 -> 133.67387 | AR11: =IF(D11=0,0,AQ11/D11*1000) -> 104.67805
A12: Gas/oil - PJM/NE/other peakers & oil (legacy CEG) | B12: peaker | C12: PJMW | D12: 2582 | E12: 2027 | F12: 2038 | G12: 1995 | H12: Cashflow | I12: =Inputs!$B$63 -> 0.06 | J12: =Scarcity -> 2.5 | K12: =Inputs!$D$63 -> 10.5 | M12: =Inputs!$F$63 -> 5 | N12: =Inputs!$G$63 -> 0 | O12: =Inputs!$H$63 -> 0 | P12: =Inputs!$I$63 -> 0 | Q12: =Inputs!$J$63 -> 0 | R12: =Inputs!$K$63 -> 18 | S12: =Inputs!$L$63 -> 5 | T12: =Inputs!$M$63 -> 0.6 | U12: 0 | V12: 2026 | W12: =Inputs!$R$63 -> 0 | X12: =Inputs!$P$63 -> 1 | Y12: =Inputs!$Q$63 -> 1 | Z12: 0 | AA12: 2026 | AB12: 2026 | AC12: 1 | AD12: 0 | AE12: =Inputs!$N$63 -> 0.1 | AF12: =Inputs!$O$63 -> 0.1 | AG12: 0 | AH12: 2026 | AJ12: =Inputs!$S$63 -> 1970 | AL12: =IF(ISNUMBER(AK12),AK12,MAX(0,MIN(1,(F12+1-ValDate)/(F12+1-G12)))) -> 0.27840909 | AM12: =D12*AJ12*AL12/1000 -> 1416.139 | AN12: =MATCH("ATC|"&C12,Prices!$A:$A,0) -> 20 | AO12: =MATCH("GAS|"&C12,Prices!$A:$A,0) -> 19 | AP12: =MATCH("CAP|"&C12,Prices!$A:$A,0) -> 21 | AQ12: =CEG_Model!C361+CEG_Model!C362+CEG_Model!C363 -> 1464.8758 | AR12: =IF(D12=0,0,AQ12/D12*1000) -> 567.34152
A13: Calpine - ERCOT CCGT (Deer Park, Freestone, Channel, Baytown, etc.) | B13: ccgt | C13: ERCOT | D13: 7000 | E13: 2027 | F13: 2045 | G13: 2002 | H13: Cashflow | I13: =Inputs!$D$57 -> 0.55 | J13: =Inputs!$E$57 -> 1.2 | K13: =Inputs!$D$62 -> 7.2 | M13: =Inputs!$F$62 -> 3.5 | N13: =Inputs!$G$62 -> 0 | O13: =Inputs!$H$62 -> 0 | P13: =Inputs!$I$62 -> 0 | Q13: =Inputs!$J$62 -> 0 | R13: =Inputs!$K$62 -> 32 | S13: =Inputs!$L$62 -> 12 | T13: =Inputs!$M$62 -> 0.78 | U13: 0 | V13: 2026 | W13: =Inputs!$R$62 -> 0 | X13: =Inputs!$P$62 -> 1 | Y13: =Inputs!$Q$62 -> 1 | Z13: 0 | AA13: 2026 | AB13: 2026 | AC13: 1 | AD13: 0 | AE13: =Inputs!$N$62 -> 0.095 | AF13: =Inputs!$O$62 -> 0.095 | AG13: 0 | AH13: 2026 | AJ13: =Inputs!$S$62 -> 2350 | AL13: =IF(ISNUMBER(AK13),AK13,MAX(0,MIN(1,(F13+1-ValDate)/(F13+1-G13)))) -> 0.4375 | AM13: =D13*AJ13*AL13/1000 -> 7196.875 | AN13: =MATCH("ATC|"&C13,Prices!$A:$A,0) -> 41 | AO13: =MATCH("GAS|"&C13,Prices!$A:$A,0) -> 40 | AP13: =MATCH("CAP|"&C13,Prices!$A:$A,0) -> 42 | AQ13: =CEG_Model!C391+CEG_Model!C392+CEG_Model!C393 -> 4805.91 | AR13: =IF(D13=0,0,AQ13/D13*1000) -> 686.55857
A14: Calpine - ERCOT peakers/cogen | B14: peaker | C14: ERCOT | D14: 400 | E14: 2027 | F14: 2040 | G14: 2000 | H14: Cashflow | I14: =Inputs!$B$63 -> 0.06 | J14: =ScarcityERC -> 2.5 | K14: =Inputs!$D$63 -> 10.5 | M14: =Inputs!$F$63 -> 5 | N14: =Inputs!$G$63 -> 0 | O14: =Inputs!$H$63 -> 0 | P14: =Inputs!$I$63 -> 0 | Q14: =Inputs!$J$63 -> 0 | R14: =Inputs!$K$63 -> 18 | S14: =Inputs!$L$63 -> 5 | T14: =Inputs!$M$63 -> 0.6 | U14: 0 | V14: 2026 | W14: =Inputs!$R$63 -> 0 | X14: =Inputs!$P$63 -> 1 | Y14: =Inputs!$Q$63 -> 1 | Z14: 0 | AA14: 2026 | AB14: 2026 | AC14: 1 | AD14: 0 | AE14: =Inputs!$N$63 -> 0.1 | AF14: =Inputs!$O$63 -> 0.1 | AG14: 0 | AH14: 2026 | AJ14: =Inputs!$S$63 -> 1970 | AL14: =IF(ISNUMBER(AK14),AK14,MAX(0,MIN(1,(F14+1-ValDate)/(F14+1-G14)))) -> 0.34756098 | AM14: =D14*AJ14*AL14/1000 -> 273.87805 | AN14: =MATCH("ATC|"&C14,Prices!$A:$A,0) -> 41 | AO14: =MATCH("GAS|"&C14,Prices!$A:$A,0) -> 40 | AP14: =MATCH("CAP|"&C14,Prices!$A:$A,0) -> 42 | AQ14: =CEG_Model!C421+CEG_Model!C422+CEG_Model!C423 -> 45.950107 | AR14: =IF(D14=0,0,AQ14/D14*1000) -> 114.87527
A15: Calpine - West CCGT (CAISO) | B15: ccgt | C15: WEST | D15: 5000 | E15: 2027 | F15: 2045 | G15: 2003 | H15: Cashflow | I15: =Inputs!$D$56 -> 0.45 | J15: =Inputs!$E$56 -> 1.15 | K15: =Inputs!$D$62 -> 7.2 | M15: =Inputs!$F$62 -> 3.5 | N15: =Inputs!$G$62 -> 0 | O15: =Inputs!$H$62 -> 0 | P15: =Inputs!$I$62 -> 0 | Q15: =Inputs!$J$62 -> 0 | R15: =Inputs!$K$62 -> 32 | S15: =Inputs!$L$62 -> 12 | T15: =Inputs!$M$62 -> 0.78 | U15: 0 | V15: 2026 | W15: =Inputs!$R$62 -> 0 | X15: =Inputs!$P$62 -> 1 | Y15: =Inputs!$Q$62 -> 1 | Z15: 0 | AA15: 2026 | AB15: 2026 | AC15: 1 | AD15: 0 | AE15: =Inputs!$N$62 -> 0.095 | AF15: =Inputs!$O$62 -> 0.095 | AG15: 0 | AH15: 2026 | AJ15: =Inputs!$S$62 -> 2350 | AL15: =IF(ISNUMBER(AK15),AK15,MAX(0,MIN(1,(F15+1-ValDate)/(F15+1-G15)))) -> 0.44767442 | AM15: =D15*AJ15*AL15/1000 -> 5260.1744 | AN15: =MATCH("ATC|"&C15,Prices!$A:$A,0) -> 38 | AO15: =MATCH("GAS|"&C15,Prices!$A:$A,0) -> 37 | AP15: =MATCH("CAP|"&C15,Prices!$A:$A,0) -> 39 | AQ15: =CEG_Model!C451+CEG_Model!C452+CEG_Model!C453 -> 5189.6616 | AR15: =IF(D15=0,0,AQ15/D15*1000) -> 1037.9323
A16: Calpine - West peakers | B16: peaker | C16: WEST | D16: 800 | E16: 2027 | F16: 2040 | G16: 2002 | H16: Cashflow | I16: =Inputs!$B$63 -> 0.06 | J16: =Scarcity -> 2.5 | K16: =Inputs!$D$63 -> 10.5 | M16: =Inputs!$F$63 -> 5 | N16: =Inputs!$G$63 -> 0 | O16: =Inputs!$H$63 -> 0 | P16: =Inputs!$I$63 -> 0 | Q16: =Inputs!$J$63 -> 0 | R16: =Inputs!$K$63 -> 18 | S16: =Inputs!$L$63 -> 5 | T16: =Inputs!$M$63 -> 0.6 | U16: 0 | V16: 2026 | W16: =Inputs!$R$63 -> 0 | X16: =Inputs!$P$63 -> 1 | Y16: =Inputs!$Q$63 -> 1 | Z16: 0 | AA16: 2026 | AB16: 2026 | AC16: 1 | AD16: 0 | AE16: =Inputs!$N$63 -> 0.1 | AF16: =Inputs!$O$63 -> 0.1 | AG16: 0 | AH16: 2026 | AJ16: =Inputs!$S$63 -> 1970 | AL16: =IF(ISNUMBER(AK16),AK16,MAX(0,MIN(1,(F16+1-ValDate)/(F16+1-G16)))) -> 0.36538462 | AM16: =D16*AJ16*AL16/1000 -> 575.84615 | AN16: =MATCH("ATC|"&C16,Prices!$A:$A,0) -> 38 | AO16: =MATCH("GAS|"&C16,Prices!$A:$A,0) -> 37 | AP16: =MATCH("CAP|"&C16,Prices!$A:$A,0) -> 39 | AQ16: =CEG_Model!C481+CEG_Model!C482+CEG_Model!C483 -> 389.37341 | AR16: =IF(D16=0,0,AQ16/D16*1000) -> 486.71676
A17: Calpine - The Geysers geothermal | B17: geothermal | C17: WEST | D17: 750 | E17: 2027 | F17: 2055 | G17: 1985 | H17: Cashflow | I17: =Inputs!$B$66 -> 0.85 | J17: =Inputs!$C$66 -> 1.1 | K17: =Inputs!$D$66 -> 0 | M17: =Inputs!$F$66 -> 0 | N17: =Inputs!$G$66 -> 0 | O17: =Inputs!$H$66 -> 38 | P17: =Inputs!$I$66 -> 0 | Q17: =Inputs!$J$66 -> 0.025 | R17: =Inputs!$K$66 -> 0 | S17: =Inputs!$L$66 -> 0 | T17: =Inputs!$M$66 -> 0.9 | U17: 0 | V17: 2026 | W17: =Inputs!$R$66 -> 0 | X17: =Inputs!$P$66 -> 0 | Y17: =Inputs!$Q$66 -> 0 | Z17: 750 | AA17: 2027 | AB17: 2035 | AC17: 1 | AD17: 85 | AE17: =Inputs!$N$66 -> 0.075 | AF17: =Inputs!$O$66 -> 0.075 | AG17: 0 | AH17: 2026 | AJ17: =Inputs!$S$66 -> 5500 | AL17: =IF(ISNUMBER(AK17),AK17,MAX(0,MIN(1,(F17+1-ValDate)/(F17+1-G17)))) -> 0.41197183 | AM17: =D17*AJ17*AL17/1000 -> 1699.3838 | AN17: =MATCH("ATC|"&C17,Prices!$A:$A,0) -> 38 | AO17: =MATCH("GAS|"&C17,Prices!$A:$A,0) -> 37 | AP17: =MATCH("CAP|"&C17,Prices!$A:$A,0) -> 39 | AQ17: =CEG_Model!C511+CEG_Model!C512+CEG_Model!C513 -> 2229.0568 | AR17: =IF(D17=0,0,AQ17/D17*1000) -> 2972.0758
A18: Calpine - East CCGT (NE/NY/PJM residual/SE) | B18: ccgt | C18: NE | D18: 2900 | E18: 2027 | F18: 2045 | G18: 2003 | H18: Cashflow | I18: =Inputs!$D$55 -> 0.45 | J18: =Inputs!$E$55 -> 1.05 | K18: =Inputs!$D$62 -> 7.2 | M18: =Inputs!$F$62 -> 3.5 | N18: =Inputs!$G$62 -> 0 | O18: =Inputs!$H$62 -> 0 | P18: =Inputs!$I$62 -> 0 | Q18: =Inputs!$J$62 -> 0 | R18: =Inputs!$K$62 -> 32 | S18: =Inputs!$L$62 -> 12 | T18: =Inputs!$M$62 -> 0.78 | U18: 0 | V18: 2026 | W18: =Inputs!$R$62 -> 0 | X18: =Inputs!$P$62 -> 1 | Y18: =Inputs!$Q$62 -> 1 | Z18: 0 | AA18: 2026 | AB18: 2026 | AC18: 1 | AD18: 0 | AE18: =Inputs!$N$62 -> 0.095 | AF18: =Inputs!$O$62 -> 0.095 | AG18: 0 | AH18: 2026 | AJ18: =Inputs!$S$62 -> 2350 | AL18: =IF(ISNUMBER(AK18),AK18,MAX(0,MIN(1,(F18+1-ValDate)/(F18+1-G18)))) -> 0.44767442 | AM18: =D18*AJ18*AL18/1000 -> 3050.9012 | AN18: =MATCH("ATC|"&C18,Prices!$A:$A,0) -> 35 | AO18: =MATCH("GAS|"&C18,Prices!$A:$A,0) -> 34 | AP18: =MATCH("CAP|"&C18,Prices!$A:$A,0) -> 36 | AQ18: =CEG_Model!C541+CEG_Model!C542+CEG_Model!C543 -> 2164.9878 | AR18: =IF(D18=0,0,AQ18/D18*1000) -> 746.54751
A19: RISEC (609 MW CCGT, ISO-NE) - pending, $715mm | B19: ccgt | C19: NE | D19: 609 | E19: 2027 | F19: 2050 | G19: 2002 | H19: Cashflow | I19: =Inputs!$D$55 -> 0.45 | J19: =Inputs!$E$55 -> 1.05 | K19: =Inputs!$D$62 -> 7.2 | M19: =Inputs!$F$62 -> 3.5 | N19: =Inputs!$G$62 -> 0 | O19: =Inputs!$H$62 -> 0 | P19: =Inputs!$I$62 -> 0 | Q19: =Inputs!$J$62 -> 0 | R19: =Inputs!$K$62 -> 32 | S19: =Inputs!$L$62 -> 12 | T19: =Inputs!$M$62 -> 0.78 | U19: 0 | V19: 2026 | W19: =Inputs!$R$62 -> 0 | X19: =Inputs!$P$62 -> 1 | Y19: =Inputs!$Q$62 -> 1 | Z19: 0 | AA19: 2026 | AB19: 2026 | AC19: 1 | AD19: 0 | AE19: =Inputs!$N$62 -> 0.095 | AF19: =Inputs!$O$62 -> 0.095 | AG19: 0 | AH19: 2026 | AJ19: =Inputs!$S$62 -> 2350 | AL19: =IF(ISNUMBER(AK19),AK19,MAX(0,MIN(1,(F19+1-ValDate)/(F19+1-G19)))) -> 0.49489796 | AM19: =D19*AJ19*AL19/1000 -> 708.27321 | AN19: =MATCH("ATC|"&C19,Prices!$A:$A,0) -> 35 | AO19: =MATCH("GAS|"&C19,Prices!$A:$A,0) -> 34 | AP19: =MATCH("CAP|"&C19,Prices!$A:$A,0) -> 36 | AQ19: =CEG_Model!C571+CEG_Model!C572+CEG_Model!C573 -> 497.21486 | AR19: =IF(D19=0,0,AQ19/D19*1000) -> 816.44475
A20: Total | D20: =SUM(D2:D19) -> 49970 | AM20: =SUM(AM2:AM19) -> 67874.422 | AQ20: =SUM(AQ2:AQ19) -> 81018.946

Sheet CEG_Model
A1: CEG - annual asset cash flows and consolidated FCF ($mm, nominal). Formulas only.
A3: Line | B3: Key | C3: PV / total | D3: PV to horizon | E3: Value at horizon | G3: 2027 | H3: 2028 | I3: 2029 | J3: 2030 | K3: 2031 | L3: 2032 | M3: 2033 | N3: 2034 | O3: 2035 | P3: 2036 | Q3: 2037 | R3: 2038 | S3: 2039 | T3: 2040 | U3: 2041 | V3: 2042 | W3: 2043 | X3: 2044 | Y3: 2045 | Z3: 2046 | AA3: 2047 | AB3: 2048 | AC3: 2049 | AD3: 2050 | AE3: 2051 | AF3: 2052 | AG3: 2053 | AH3: 2054 | AI3: 2055 | AJ3: 2056 | AK3: 2057 | AL3: 2058 | AM3: 2059 | AN3: 2060 | AO3: 2061 | AP3: 2062 | AQ3: 2063 | AR3: 2064 | AS3: 2065
A4: Inflation index | G4: =Prices!G$4 -> 1.02 | H4: =Prices!H$4 -> 1.0404 | I4: =Prices!I$4 -> 1.061208 | J4: =Prices!J$4 -> 1.0824322 | K4: =Prices!K$4 -> 1.1040808 | L4: =Prices!L$4 -> 1.1261624 | M4: =Prices!M$4 -> 1.1486857 | N4: =Prices!N$4 -> 1.1716594 | ... AS4: =Prices!AS$4 -> 2.1647448
A5: CONSOLIDATED
A6: Merchant energy revenue | B6: c_energy | C6: =SUM(G6:AS6) -> 514082.27 | G6: =SUMIF($B$35:$B$574,"energy",G$35:G$574) -> 16386.008 | H6: =SUMIF($B$35:$B$574,"energy",H$35:H$574) -> 16699.404 | I6: =SUMIF($B$35:$B$574,"energy",I$35:I$574) -> 15692.584 | J6: =SUMIF($B$35:$B$574,"energy",J$35:J$574) -> 15474.106 | K6: =SUMIF($B$35:$B$574,"energy",K$35:K$574) -> 15783.588 | L6: =SUMIF($B$35:$B$574,"energy",L$35:L$574) -> 16099.26 | M6: =SUMIF($B$35:$B$574,"energy",M$35:M$574) -> 16421.245 | N6: =SUMIF($B$35:$B$574,"energy",N$35:N$574) -> 16749.67 | ... AS6: =SUMIF($B$35:$B$574,"energy",AS$35:AS$574) -> 0
A7: Capacity revenue | B7: c_capacity | C7: =SUM(G7:AS7) -> 76134.872 | G7: =SUMIF($B$35:$B$574,"capacity",G$35:G$574) -> 2732.4341 | H7: =SUMIF($B$35:$B$574,"capacity",H$35:H$574) -> 2723.8784 | I7: =SUMIF($B$35:$B$574,"capacity",I$35:I$574) -> 2407.8232 | J7: =SUMIF($B$35:$B$574,"capacity",J$35:J$574) -> 2233.5634 | K7: =SUMIF($B$35:$B$574,"capacity",K$35:K$574) -> 2278.2347 | L7: =SUMIF($B$35:$B$574,"capacity",L$35:L$574) -> 2323.7994 | M7: =SUMIF($B$35:$B$574,"capacity",M$35:M$574) -> 2370.2754 | N7: =SUMIF($B$35:$B$574,"capacity",N$35:N$574) -> 2417.6809 | ... AS7: =SUMIF($B$35:$B$574,"capacity",AS$35:AS$574) -> 0
A8: Long-term PPA revenue | B8: c_ppa | C8: =SUM(G8:AS8) -> 44913.9 | G8: =SUMIF($B$35:$B$574,"ppa",G$35:G$574) -> 1822.8553 | H8: =SUMIF($B$35:$B$574,"ppa",H$35:H$574) -> 2506.7704 | I8: =SUMIF($B$35:$B$574,"ppa",I$35:I$574) -> 2506.7704 | J8: =SUMIF($B$35:$B$574,"ppa",J$35:J$574) -> 2506.7704 | K8: =SUMIF($B$35:$B$574,"ppa",K$35:K$574) -> 2506.7704 | L8: =SUMIF($B$35:$B$574,"ppa",L$35:L$574) -> 2506.7704 | M8: =SUMIF($B$35:$B$574,"ppa",M$35:M$574) -> 2506.7704 | N8: =SUMIF($B$35:$B$574,"ppa",N$35:N$574) -> 2506.7704 | ... AS8: =SUMIF($B$35:$B$574,"ppa",AS$35:AS$574) -> 0
A9: ZEC revenue | B9: c_zec | C9: =SUM(G9:AS9) -> 1326.8772 | G9: =SUMIF($B$35:$B$574,"zec",G$35:G$574) -> 442.2924 | H9: =SUMIF($B$35:$B$574,"zec",H$35:H$574) -> 442.2924 | I9: =SUMIF($B$35:$B$574,"zec",I$35:I$574) -> 442.2924 | J9: =SUMIF($B$35:$B$574,"zec",J$35:J$574) -> 0 | K9: =SUMIF($B$35:$B$574,"zec",K$35:K$574) -> 0 | L9: =SUMIF($B$35:$B$574,"zec",L$35:L$574) -> 0 | M9: =SUMIF($B$35:$B$574,"zec",M$35:M$574) -> 0 | N9: =SUMIF($B$35:$B$574,"zec",N$35:N$574) -> 0 | ... AS9: =SUMIF($B$35:$B$574,"zec",AS$35:AS$574) -> 0
A10: TOTAL REVENUE | B10: c_rev | C10: =SUM(G10:AS10) -> 636457.92 | G10: =SUMIF($B$35:$B$574,"revenue",G$35:G$574) -> 21383.59 | H10: =SUMIF($B$35:$B$574,"revenue",H$35:H$574) -> 22372.346 | I10: =SUMIF($B$35:$B$574,"revenue",I$35:I$574) -> 21049.47 | J10: =SUMIF($B$35:$B$574,"revenue",J$35:J$574) -> 20214.44 | K10: =SUMIF($B$35:$B$574,"revenue",K$35:K$574) -> 20568.593 | L10: =SUMIF($B$35:$B$574,"revenue",L$35:L$574) -> 20929.83 | M10: =SUMIF($B$35:$B$574,"revenue",M$35:M$574) -> 21298.291 | N10: =SUMIF($B$35:$B$574,"revenue",N$35:N$574) -> 21674.121 | ... AS10: =SUMIF($B$35:$B$574,"revenue",AS$35:AS$574) -> 0
A11: Fuel & variable cost | B11: c_fuel | C11: =SUM(G11:AS11) -> 116402.58 | G11: =SUMIF($B$35:$B$574,"fuelvar",G$35:G$574) -> 4020.158 | H11: =SUMIF($B$35:$B$574,"fuelvar",H$35:H$574) -> 4145.1541 | I11: =SUMIF($B$35:$B$574,"fuelvar",I$35:I$574) -> 4296.2827 | J11: =SUMIF($B$35:$B$574,"fuelvar",J$35:J$574) -> 4387.7412 | K11: =SUMIF($B$35:$B$574,"fuelvar",K$35:K$574) -> 4481.1671 | L11: =SUMIF($B$35:$B$574,"fuelvar",L$35:L$574) -> 4576.6034 | M11: =SUMIF($B$35:$B$574,"fuelvar",M$35:M$574) -> 4674.0937 | N11: =SUMIF($B$35:$B$574,"fuelvar",N$35:N$574) -> 4773.6827 | ... AS11: =SUMIF($B$35:$B$574,"fuelvar",AS$35:AS$574) -> 0
A12: GROSS MARGIN | B12: c_gm | C12: =SUM(G12:AS12) -> 520055.34 | G12: =SUMIF($B$35:$B$574,"gm",G$35:G$574) -> 17363.432 | H12: =SUMIF($B$35:$B$574,"gm",H$35:H$574) -> 18227.192 | I12: =SUMIF($B$35:$B$574,"gm",I$35:I$574) -> 16753.187 | J12: =SUMIF($B$35:$B$574,"gm",J$35:J$574) -> 15826.699 | K12: =SUMIF($B$35:$B$574,"gm",K$35:K$574) -> 16087.426 | L12: =SUMIF($B$35:$B$574,"gm",L$35:L$574) -> 16353.226 | M12: =SUMIF($B$35:$B$574,"gm",M$35:M$574) -> 16624.197 | N12: =SUMIF($B$35:$B$574,"gm",N$35:N$574) -> 16900.438 | ... AS12: =SUMIF($B$35:$B$574,"gm",AS$35:AS$574) -> 0
A13: Gross margin % | B13: c_gmpct | G13: =IF(G10=0,0,G12/G10) -> 0.81199798 | H13: =IF(H10=0,0,H12/H10) -> 0.81471973 | I13: =IF(I10=0,0,I12/I10) -> 0.79589592 | J13: =IF(J10=0,0,J12/J10) -> 0.78294025 | K13: =IF(K10=0,0,K12/K10) -> 0.78213546 | L13: =IF(L10=0,0,L12/L10) -> 0.78133585 | M13: =IF(M10=0,0,M12/M10) -> 0.78054137 | N13: =IF(N10=0,0,N12/N10) -> 0.77975196 | ... AS13: =IF(AS10=0,0,AS12/AS10) -> 0
