Workbook

Sheet Summary
A1: VIST - SUMMARY (recalculates from Inputs)
A2: ="Scenario: "&Scenario&" | long-run Brent $"&TEXT(BrentLR,"0")&" (2026$) | discount "&TEXT(Disc,"0.0%")&" | unbooked risk "&TEXT(UnbRisk,"0%") -> Scenario: Base | long-run Brent $72 (2026$) | discount 12.0% | unbooked risk 60%
A4: PV producing base ($mm) | B4: =Model!$B$29 -> 6469.4054
A5: PV proved undeveloped wells ($mm) | B5: =Model!$B$42-Model!$B$29 -> 3078.7328
A6: PV unbooked inventory, unrisked ($mm) | B6: =Model!$B$55-Model!$B$42 -> 4357.9187
A7: PV unbooked inventory, risked ($mm) | B7: =B6*UnbRisk -> 2614.7512
A8: Gross asset value, risked ($mm) | B8: =B4+B5+B7 -> 12162.889
A9: Less: net debt & other claims ($mm) | B9: =(NetDebt+OtherClaims)*1000 -> 3360
A10: Equity NAV, risked ($mm) | B10: =B8-B9 -> 8802.8894
A11: NAV per ADS - risked ($) | B11: =B10/Shares -> 79.577738
A12: NAV per ADS - unrisked inventory ($) | B12: =(Model!$B$55-B9)/Shares -> 95.335897
A13: Hard floor: producing base only, per ADS ($) | B13: =(Model!$B$29-B9)/Shares -> 28.10889
A14: Share price ($/ADS) | B14: =Price -> 73.35
A15: Upside / (downside) to risked NAV | B15: =B11/B14-1 -> 0.084904407
A16: Entry at 30% margin of safety to risked NAV ($) | B16: =0.7*B11 -> 55.704417
A18: Market cap ($mm) | B18: =Price*Shares -> 8113.977
A19: Enterprise value ($mm) | B19: =B18+B9 -> 11473.977
A20: EV / P1 EBITDA (full plan) | B20: =B19/Model!G50 -> 3.3672665
A21: EV per flowing boe/d ($) | B21: =B19*1000/FlowRate -> 69539.255
A22: EV per boe of 1P reserves (588 MMboe YE-25) ($) | B22: =B19/588.1 -> 19.510248
A23: P1 equity-level FCF yield (unlevered FCF / market cap) | B23: =Model!G54/B18 -> 0.11718448
A25: Production, EBITDA and FCF (full plan)
B26: P1 (Sep-2027) | C26: P2 (Sep-2028) | D26: P3 (Sep-2029) | E26: P4 (Sep-2030) | F26: P6 (Sep-2032) | G26: P9 (Sep-2035)
A27: Production (kboe/d) | B27: =Model!G48 -> 176.80993 | C27: =Model!H48 -> 192.14712 | D27: =Model!I48 -> 215.2152 | E27: =Model!J48 -> 236.73487 | F27: =Model!L48 -> 269.23841 | G27: =Model!O48 -> 304.12186
A28: Revenue ($mm) | B28: =Model!G49 -> 4950.3448 | C28: =Model!H49 -> 4590.4125 | D28: =Model!I49 -> 5043.4169 | E28: =Model!J49 -> 5678.0094 | F28: =Model!L49 -> 6735.7537 | G28: =Model!O49 -> 8103.7151
A29: EBITDA ($mm) | B29: =Model!G50 -> 3407.5049 | C29: =Model!H50 -> 3041.6563 | D29: =Model!I50 -> 3310.1985 | E29: =Model!J50 -> 3729.8724 | F29: =Model!L50 -> 4427.5192 | G29: =Model!O50 -> 5331.5104
A30: Capex ($mm) | B30: =Model!G51 -> 1735.5334 | C30: =Model!H51 -> 1779.2446 | D30: =Model!I51 -> 1732.621 | E30: =Model!J51 -> 1792.5286 | F30: =Model!L51 -> 1904.6335 | G30: =Model!O51 -> 2066.412
A31: Unlevered FCF ($mm) | B31: =Model!G54 -> 950.83216 | C31: =Model!H54 -> 793.86648 | D31: =Model!I54 -> 1136.3259 | E31: =Model!J54 -> 1474.6834 | F31: =Model!L54 -> 1957.3092 | G31: =Model!O54 -> 2084.5147
A32: Brent ($/bbl) | B32: =Model!G7 -> 90 | C32: =Model!H7 -> 77 | D32: =Model!I7 -> 75.5 | E32: =Model!J7 -> 77.167263 | F32: =Model!L7 -> 80.284821 | G32: =Model!O7 -> 85.198894
A34: Scenario snapshot at default inputs (STATIC - rerun build_vista_excel.py to refresh)
A35: Scenario | B35: Risked NAV/ADS | C35: Unrisked NAV/ADS | D35: Producing-base floor | E35: Up/(down)side
A36: Low | B36: 51.6669 | C36: 60.8206 | D36: 20.0179 | E36: -0.2956
A37: Base | B37: 79.5777 | C37: 95.3359 | D37: 28.1089 | E37: 0.0849
A38: High | B38: 109.5305 | C38: 132.7275 | D38: 36.173 | E38: 0.4933
A39: Extreme | B39: 144.0913 | C39: 175.8716 | D39: 44.5951 | E39: 0.9644
A41: Risked NAV/ADS: long-run Brent (2026$, rows) x discount rate (cols) - STATIC
A42: Brent LR \ discount | B42: 0.1 | C42: 0.12 | D42: 0.15 | E42: 0.18
A43: 55 | B43: 50.35 | C43: 39.71 | D43: 27.65 | E43: 18.8
A44: 60 | B44: 64.09 | C44: 51.67 | D44: 37.53 | E44: 27.12
A45: 65 | B45: 77.65 | C45: 63.45 | D45: 47.26 | E45: 35.3
...

Sheet README
A1: Vista Energy (VIST) - asset-based NAV model (E&P method), editable
A3: NAV = PV(producing base, no new wells) + PV(proved undeveloped wells) + risk factor x PV(unbooked inventory) - net debt & other claims.
A4: Edit blue cells / yellow levers on 'Inputs'. 'Model' holds annual periods (P1 = Oct-26..Sep-27), 'Cohorts' the well-by-vintage production, 'Summary' the results.
A5: Colours: blue = input, yellow = key lever, green = link, black = formula.
A6: Units: $mm unless stated; production MMboe per period and kboe/d; prices nominal $/bbl (long-run inputs in 2026$).
A7: Main levers: Scenario (Brent long run), Brent shift, discount rate (Argentina risk), unbooked-inventory risk factor, export duty, EUR, well-cost multiplier, inventory.
A8: Calibration: P1 ~177 kboe/d and ~237 kboe/d by 2030 (guidance 158 kboe/d 2026, target 250 by 2030); EBITDA/boe matches Q2-26 (~$56.7 at ~$95 Brent).
A9: Sources: Vista Q2-26 results/call (production, net debt $3.06bn, lifting $4.5/boe, realized $89.4/bbl), YE-25 reserves (588 MMboe 1P, PV-10 $6.61bn),
A10: well cost $14.2mm (Q4-25) -> $11mm target 2028, >1,320 locations, Equinor deal ($712mm, closed May-26); Brent futures Sep-26. Other items are estimates (see comments).

Sheet Inputs
A1: INPUTS - blue = input, yellow = key lever
A3: Control panel
A4: Scenario (Low / Base / High / Extreme) | B4: Base | G4: Selects long-run Brent from the scenario table
A5: Long-run Brent shift ($/bbl, 2026$) | B5: 0
A6: Discount rate (unlevered, Argentina-risked) | B6: 0.12 | G6: 10% = investment-grade path; 15%+ = macro relapse / capital controls
A7: Risk factor on unbooked inventory (beyond proved wells) | B7: 0.6 | G7: Industry practice ~50-75% for unproved locations
A8: Export duty on crude | B8: 0 | G8: 0% today; historically up to 8%
A9: Net EUR per well (MMboe) | B9: 0.9 | G9: Calibrated to guidance; Vaca Muerta type curves ~1.0-1.5 MMboe gross
A10: Well-cost multiplier | B10: 1
A11: Total drilling inventory (net wells) | B11: 1470 | G11: >1,320 ready-to-drill (company) + ~150 net Equinor (estimate)
A12: Wells to develop proved undeveloped (PUD) reserves | B12: 450 | G12: 355.7 MMboe PUD (YE-25) + Equinor, at ~0.9 MMboe/well
A14: Brent deck (nominal $/bbl)
A15: Futures: P1 (Oct-26..Sep-27), P2, P3 | B15: 90 | C15: 77 | D15: 75.5 | G15: Spot ~$101-105 late Sep-26 (Hormuz); Aug-27 $78.4; 2028 ~$75-76
A16: Inflation / escalator | B16: 0.02
A18: Scenario | B18: Low | C18: Base | D18: High | E18: Extreme
A19: Long-run Brent (2026$/bbl) | B19: 60 | C19: 72 | D19: 85 | E19: 100 | F19: =INDEX(B19:E19,MATCH(Scenario,B18:E18,0))+BrentShift -> 72 | G19: Active = scenario + shift
A20: Scenario description | B20: War premium fully unwinds; OPEC+ spare capacity returns; pre-war 2025 levels | C20: Futures curve: ~$75 in 2028, roughly flat real thereafter | D20: Lasting risk premium + post-war underinvestment | E20: Prolonged Hormuz disruption / structural shortage
A22: Operations and costs
A23: Oil share of production | B23: 0.87
A24: Realized oil discount to Brent ($/bbl) | B24: 5 | G24: Q2-26 realized $89.4/bbl
A25: Gas price ($/boe, 2026$) | B25: 21 | G25: ~$3.5/MMBtu - estimate
A26: Royalties (% revenue) | B26: 0.15 | G26: Neuquen 12% + extension premia - estimate
A27: Provincial turnover tax (% revenue) | B27: 0.03
A28: Lifting cost ($/boe, 2026$) | B28: 4.5 | G28: Q2-26 $4.5; Q1 $4.3
A29: Transport, storage & selling ($/boe) | B29: 4 | G29: Estimate
A30: G&A ($/boe) | B30: 1.5 | G30: Estimate
A31: Cost escalator | B31: 0.02
A32: Facilities / infrastructure capex ($/boe) | B32: 3 | G32: Estimate
A33: Well cost ($mm/well): P1, P2, P3 (then escalates) | B33: 14 | C33: 12.5 | D33: 11 | G33: $14.2mm Q4-25; company targets $11mm by 2028
A34: Production at 1-Oct-2026 from existing wells (kboe/d) | B34: 165 | G34: Q3 guide 160, Q4 170
A35: Base decline by period: P1..P5, then terminal | B35: 0.35 | C35: 0.24 | D35: 0.18 | E35: 0.14 | F35: 0.12 | G35: 0.09
A36: New-well profile (share of EUR by period of life): P1..P10, then tail decline below | B36: 0.15 | C36: 0.19 | D36: 0.12 | E36: 0.09 | F36: 0.07 | G36: 0.06 | H36: 0.05 | I36: 0.045 | J36: 0.04 | K36: 0.035
A37: Well profile tail decline (after P10) | B37: 0.1
A39: Tax and balance sheet
A40: Income tax rate | B40: 0.35
A41: Existing tax basis ($bn, amortised over 7 periods) | B41: 7 | G41: Estimate
A42: Tax life of new capex (periods) | B42: 5
A43: Net debt ($bn, 30-Jun-26) | B43: 3.06 | G43: Q2-26 results
A44: Other claims ($bn: leases, abandonment) | B44: 0.3 | G44: Estimate
A45: ADS outstanding (mm) | B45: 110.62 | G45: incl. ADS issued to Equinor
...

Sheet Model
A1: VIST - annual model ($mm unless stated; P1 = Oct-26..Sep-27). Formulas only.
A3: Period | G3: 1 | H3: 2 | I3: 3 | J3: 4 | K3: 5 | L3: 6 | M3: 7 | N3: 8 | O3: 9 | P3: 10 | Q3: 11 | R3: 12 | S3: 13 | T3: 14 | U3: 15 | V3: 16 | W3: 17 | X3: 18 | Y3: 19 | Z3: 20 | AA3: 21 | AB3: 22 | AC3: 23 | AD3: 24 | AE3: 25 | AF3: 26 | AG3: 27 | AH3: 28 | AI3: 29
A4: Ends Sep- | G4: 2027 | H4: 2028 | I4: 2029 | J4: 2030 | K4: 2031 | L4: 2032 | M4: 2033 | N4: 2034 | O4: 2035 | P4: 2036 | Q4: 2037 | R4: 2038 | S4: 2039 | T4: 2040 | U4: 2041 | V4: 2042 | W4: 2043 | X4: 2044 | Y4: 2045 | Z4: 2046 | AA4: 2047 | AB4: 2048 | AC4: 2049 | AD4: 2050 | AE4: 2051 | AF4: 2052 | AG4: 2053 | AH4: 2054 | AI4: 2055
A5: Escalator (mid-period) | G5: =(1+Infl)^(G3-0.5) -> 1.0099505 | H5: =(1+Infl)^(H3-0.5) -> 1.0301495 | I5: =(1+Infl)^(I3-0.5) -> 1.0507525 | J5: =(1+Infl)^(J3-0.5) -> 1.0717675 | K5: =(1+Infl)^(K3-0.5) -> 1.0932029 | L5: =(1+Infl)^(L3-0.5) -> 1.115067 | M5: =(1+Infl)^(M3-0.5) -> 1.1373683 | N5: =(1+Infl)^(N3-0.5) -> 1.1601157 | ... AI5: =(1+Infl)^(AI3-0.5) -> 1.7583483
A6: Cost escalator (mid-period) | G6: =(1+CostEsc)^(G3-0.5) -> 1.0099505 | H6: =(1+CostEsc)^(H3-0.5) -> 1.0301495 | I6: =(1+CostEsc)^(I3-0.5) -> 1.0507525 | J6: =(1+CostEsc)^(J3-0.5) -> 1.0717675 | K6: =(1+CostEsc)^(K3-0.5) -> 1.0932029 | L6: =(1+CostEsc)^(L3-0.5) -> 1.115067 | M6: =(1+CostEsc)^(M3-0.5) -> 1.1373683 | N6: =(1+CostEsc)^(N3-0.5) -> 1.1601157 | ... AI6: =(1+CostEsc)^(AI3-0.5) -> 1.7583483
A7: Brent ($/bbl, nominal) | G7: =Fut1 -> 90 | H7: =Fut2+0.5*(BrentLR*H5-BrentLRBase*H5) -> 77 | I7: =Fut3+(BrentLR*I5-BrentLRBase*I5) -> 75.5 | J7: =BrentLR*J5 -> 77.167263 | K7: =BrentLR*K5 -> 78.710608 | L7: =BrentLR*L5 -> 80.284821 | M7: =BrentLR*M5 -> 81.890517 | N7: =BrentLR*N5 -> 83.528327 | O7: =BrentLR*O5 -> 85.198894 | P7: =BrentLR*P5 -> 86.902872 | Q7: =BrentLR*Q5 -> 88.640929 | ... AI7: =BrentLR*AI5 -> 126.60107
A8: Revenue per boe ($) | G8: =OilShare*(G7-OilDisc)+(1-OilShare)*GasBoe*G6 -> 76.707165 | H8: =OilShare*(H7-OilDisc)+(1-OilShare)*GasBoe*H6 -> 65.452308 | I8: =OilShare*(I7-OilDisc)+(1-OilShare)*GasBoe*I6 -> 64.203554 | J8: =OilShare*(J7-OilDisc)+(1-OilShare)*GasBoe*J6 -> 65.711444 | K8: =OilShare*(K7-OilDisc)+(1-OilShare)*GasBoe*K6 -> 67.112673 | L8: =OilShare*(L7-OilDisc)+(1-OilShare)*GasBoe*L6 -> 68.541927 | M8: =OilShare*(M7-OilDisc)+(1-OilShare)*GasBoe*M6 -> 69.999765 | N8: =OilShare*(N7-OilDisc)+(1-OilShare)*GasBoe*N6 -> 71.486761 | ... AI8: =OilShare*(AI7-OilDisc)+(1-OilShare)*GasBoe*AI6 -> 110.59323
A9: EBITDA per boe ($) | G9: =G8*(1-Royalty-Turnover-ExportDuty)-(Lifting+Transport+GNA)*G6 -> 52.80037 | H9: =H8*(1-Royalty-Turnover-ExportDuty)-(Lifting+Transport+GNA)*H6 -> 43.369398 | I9: =I8*(1-Royalty-Turnover-ExportDuty)-(Lifting+Transport+GNA)*I6 -> 42.13939 | J9: =J8*(1-Royalty-Turnover-ExportDuty)-(Lifting+Transport+GNA)*J6 -> 43.165709 | K9: =K8*(1-Royalty-Turnover-ExportDuty)-(Lifting+Transport+GNA)*K6 -> 44.100363 | L9: =L8*(1-Royalty-Turnover-ExportDuty)-(Lifting+Transport+GNA)*L6 -> 45.05371 | M9: =M8*(1-Royalty-Turnover-ExportDuty)-(Lifting+Transport+GNA)*M6 -> 46.026125 | N9: =N8*(1-Royalty-Turnover-ExportDuty)-(Lifting+Transport+GNA)*N6 -> 47.017987 | ... AI9: =AI8*(1-Royalty-Turnover-ExportDuty)-(Lifting+Transport+GNA)*AI6 -> 73.102962
A10: Well cost ($mm/well) | G10: =WC1*WellCostMult -> 14 | H10: =WC2*WellCostMult -> 12.5 | I10: =WC3*WellCostMult -> 11 | J10: =WC3*(1+CostEsc)^(J3-3)*WellCostMult -> 11.22 | K10: =WC3*(1+CostEsc)^(K3-3)*WellCostMult -> 11.4444 | L10: =WC3*(1+CostEsc)^(L3-3)*WellCostMult -> 11.673288 | M10: =WC3*(1+CostEsc)^(M3-3)*WellCostMult -> 11.906754 | N10: =WC3*(1+CostEsc)^(N3-3)*WellCostMult -> 12.144889 | O10: =WC3*(1+CostEsc)^(O3-3)*WellCostMult -> 12.387787 | P10: =WC3*(1+CostEsc)^(P3-3)*WellCostMult -> 12.635542 | Q10: =WC3*(1+CostEsc)^(Q3-3)*WellCostMult -> 12.888253 | R10: =WC3*(1+CostEsc)^(R3-3)*WellCostMult -> 13.146018 | S10: =WC3*(1+CostEsc)^(S3-3)*WellCostMult -> 13.408939 | T10: =WC3*(1+CostEsc)^(T3-3)*WellCostMult -> 13.677117 | U10: =WC3*(1+CostEsc)^(U3-3)*WellCostMult -> 13.95066 | V10: =WC3*(1+CostEsc)^(V3-3)*WellCostMult -> 14.229673 | W10: =WC3*(1+CostEsc)^(W3-3)*WellCostMult -> 14.514266 | X10: =WC3*(1+CostEsc)^(X3-3)*WellCostMult -> 14.804552 | Y10: =WC3*(1+CostEsc)^(Y3-3)*WellCostMult -> 15.100643 | Z10: =WC3*(1+CostEsc)^(Z3-3)*WellCostMult -> 15.402656 | AA10: =WC3*(1+CostEsc)^(AA3-3)*WellCostMult -> 15.710709 | AB10: =WC3*(1+CostEsc)^(AB3-3)*WellCostMult -> 16.024923 | AC10: =WC3*(1+CostEsc)^(AC3-3)*WellCostMult -> 16.345421 | AD10: =WC3*(1+CostEsc)^(AD3-3)*WellCostMult -> 16.67233 | AE10: =WC3*(1+CostEsc)^(AE3-3)*WellCostMult -> 17.005776 | AF10: =WC3*(1+CostEsc)^(AF3-3)*WellCostMult -> 17.345892 | AG10: =WC3*(1+CostEsc)^(AG3-3)*WellCostMult -> 17.69281 | AH10: =WC3*(1+CostEsc)^(AH3-3)*WellCostMult -> 18.046666 | AI10: =WC3*(1+CostEsc)^(AI3-3)*WellCostMult -> 18.407599
A11: Well plan (net wells per period) - EDIT | G11: 110 | H11: 125 | I11: 135 | J11: 135 | K11: 135 | L11: 135 | M11: 135 | N11: 135 | O11: 135 | P11: 135 | Q11: 135 | R11: 135 | S11: 135 | T11: 135 | U11: 135 | V11: 135 | W11: 135 | X11: 135 | Y11: 135 | Z11: 135 | AA11: 135 | AB11: 135 | AC11: 135 | AD11: 135 | AE11: 135 | AF11: 135 | AG11: 135 | AH11: 135 | AI11: 135
A12: Base decline | G12: =Inputs!$B$35 -> 0.35 | H12: =Inputs!$C$35 -> 0.24 | I12: =Inputs!$D$35 -> 0.18 | J12: =Inputs!$E$35 -> 0.14 | K12: =Inputs!$F$35 -> 0.12 | L12: =Inputs!$G$35 -> 0.09 | M12: =Inputs!$G$35 -> 0.09 | N12: =Inputs!$G$35 -> 0.09 | O12: =Inputs!$G$35 -> 0.09 | P12: =Inputs!$G$35 -> 0.09 | Q12: =Inputs!$G$35 -> 0.09 | R12: =Inputs!$G$35 -> 0.09 | S12: =Inputs!$G$35 -> 0.09 | ... AI12: =Inputs!$G$35 -> 0.09
A13: Base rate at start of period (kboe/d) | G13: =BaseRate -> 165 | H13: =G13*(1-G12) -> 107.25 | I13: =H13*(1-H12) -> 81.51 | J13: =I13*(1-I12) -> 66.8382 | K13: =J13*(1-J12) -> 57.480852 | L13: =K13*(1-K12) -> 50.58315 | M13: =L13*(1-L12) -> 46.030666 | N13: =M13*(1-M12) -> 41.887906 | O13: =N13*(1-N12) -> 38.117995 | ... AI13: =AH13*(1-AH12) -> 5.7804
A14: Base production (MMboe) | G14: =G13*(1-G12/2)*365/1000 -> 49.685625 | H14: =H13*(1-H12/2)*365/1000 -> 34.4487 | I14: =I13*(1-I12/2)*365/1000 -> 27.073546 | J14: =J13*(1-J12/2)*365/1000 -> 22.688227 | K14: =K13*(1-K12/2)*365/1000 -> 19.72168 | L14: =L13*(1-L12/2)*365/1000 -> 17.632021 | M14: =M13*(1-M12/2)*365/1000 -> 16.045139 | N14: =N13*(1-N12/2)*365/1000 -> 14.601077 | ... AI14: =AI13*(1-AI12/2)*365/1000 -> 2.0149029
A15: Well profile by age (share of EUR) | G15: =Inputs!$B$36 -> 0.15 | H15: =Inputs!$C$36 -> 0.19 | I15: =Inputs!$D$36 -> 0.12 | J15: =Inputs!$E$36 -> 0.09 | K15: =Inputs!$F$36 -> 0.07 | L15: =Inputs!$G$36 -> 0.06 | M15: =Inputs!$H$36 -> 0.05 | N15: =Inputs!$I$36 -> 0.045 | O15: =Inputs!$J$36 -> 0.04 | P15: =Inputs!$K$36 -> 0.035 | Q15: =P15*(1-TailDecl) -> 0.0315 | R15: =Q15*(1-TailDecl) -> 0.02835 | S15: =R15*(1-TailDecl) -> 0.025515 | T15: =S15*(1-TailDecl) -> 0.0229635 | U15: =T15*(1-TailDecl) -> 0.02066715 | V15: =U15*(1-TailDecl) -> 0.018600435 | W15: =V15*(1-TailDecl) -> 0.016740392 | X15: =W15*(1-TailDecl) -> 0.015066352 | ... AI15: =AH15*(1-TailDecl) -> 0.004727981
A18: PRODUCING BASE ONLY (no new wells)
A19: Wells tied in | G19: =MAX(0,MIN(G$11,0)) -> 0 | H19: =MAX(0,MIN(H$11,0-SUM($G19:G19))) -> 0 | I19: =MAX(0,MIN(I$11,0-SUM($G19:H19))) -> 0 | J19: =MAX(0,MIN(J$11,0-SUM($G19:I19))) -> 0 | K19: =MAX(0,MIN(K$11,0-SUM($G19:J19))) -> 0 | L19: =MAX(0,MIN(L$11,0-SUM($G19:K19))) -> 0 | M19: =MAX(0,MIN(M$11,0-SUM($G19:L19))) -> 0 | N19: =MAX(0,MIN(N$11,0-SUM($G19:M19))) -> 0 | O19: =MAX(0,MIN(O$11,0-SUM($G19:N19))) -> 0 | ... AI19: =MAX(0,MIN(AI$11,0-SUM($G19:AH19))) -> 0
A20: New-well production (MMboe) | G20: =SUM(Cohorts!G4:G32) -> 0 | H20: =SUM(Cohorts!H4:H32) -> 0 | I20: =SUM(Cohorts!I4:I32) -> 0 | J20: =SUM(Cohorts!J4:J32) -> 0 | K20: =SUM(Cohorts!K4:K32) -> 0 | L20: =SUM(Cohorts!L4:L32) -> 0 | M20: =SUM(Cohorts!M4:M32) -> 0 | N20: =SUM(Cohorts!N4:N32) -> 0 | ... AI20: =SUM(Cohorts!AI4:AI32) -> 0
A21: Total production (MMboe) | G21: =G$14+G20 -> 49.685625 | H21: =H$14+H20 -> 34.4487 | I21: =I$14+I20 -> 27.073546 | J21: =J$14+J20 -> 22.688227 | K21: =K$14+K20 -> 19.72168 | L21: =L$14+L20 -> 17.632021 | M21: =M$14+M20 -> 16.045139 | N21: =N$14+N20 -> 14.601077 | ... AI21: =AI$14+AI20 -> 2.0149029
A22: Production (kboe/d) | G22: =G21/0.365 -> 136.125 | H22: =H21/0.365 -> 94.38 | I22: =I21/0.365 -> 74.1741 | J22: =J21/0.365 -> 62.159526 | K22: =K21/0.365 -> 54.032001 | L22: =L21/0.365 -> 48.306908 | M22: =M21/0.365 -> 43.959286 | N22: =N21/0.365 -> 40.002951 | ... AI22: =AI21/0.365 -> 5.520282
A23: Revenue ($mm) | G23: =G21*G$8 -> 3811.2434 | H23: =H21*H$8 -> 2254.7469 | I23: =I21*I$8 -> 1738.2179 | J23: =J21*J$8 -> 1490.8762 | K23: =K21*K$8 -> 1323.5747 | L23: =L21*L$8 -> 1208.5327 | M23: =M21*M$8 -> 1123.156 | N23: =N21*N$8 -> 1043.7837 | ... AI23: =AI21*AI$8 -> 222.83461
A24: EBITDA ($mm) | G24: =G21*G$9 -> 2623.4194 | H24: =H21*H$9 -> 1494.0194 | I24: =I21*I$9 -> 1140.8627 | J24: =J21*J$9 -> 979.3534 | K24: =K21*K$9 -> 869.73326 | L24: =L21*L$9 -> 794.38799 | M24: =M21*M$9 -> 738.49559 | N24: =N21*N$9 -> 686.51325 | ... AI24: =AI21*AI$9 -> 147.29537
A25: Capex: wells + facilities ($mm) | G25: =G19*G$10+G21*Facilities*G$6 -> 150.54006 | H25: =H19*H$10+H21*Facilities*H$6 -> 106.46193 | I25: =I19*I$10+I21*Facilities*I$6 -> 85.34279 | J25: =J19*J$10+J21*Facilities*J$6 -> 72.949516 | K25: =K19*K$10+K21*Facilities*K$6 -> 64.679394 | L25: =L19*L$10+L21*Facilities*L$6 -> 58.982653 | M25: =M19*M$10+M21*Facilities*M$6 -> 54.747699 | N25: =N19*N$10+N21*Facilities*N$6 -> 50.816814 | ... AI25: =AI19*AI$10+AI21*Facilities*AI$6 -> 10.628703
A26: Tax depreciation ($mm) | G26: =IF(G$3<=7,TaxBasis*1000/7,0)+SUM(G25:G25)/TaxLife -> 1030.108 | H26: =IF(H$3<=7,TaxBasis*1000/7,0)+SUM(G25:H25)/TaxLife -> 1051.4004 | I26: =IF(I$3<=7,TaxBasis*1000/7,0)+SUM(G25:I25)/TaxLife -> 1068.469 | J26: =IF(J$3<=7,TaxBasis*1000/7,0)+SUM(G25:J25)/TaxLife -> 1083.0589 | K26: =IF(K$3<=7,TaxBasis*1000/7,0)+SUM(G25:K25)/TaxLife -> 1095.9947 | L26: =IF(L$3<=7,TaxBasis*1000/7,0)+SUM(H25:L25)/TaxLife -> 1077.6833 | M26: =IF(M$3<=7,TaxBasis*1000/7,0)+SUM(I25:M25)/TaxLife -> 1067.3404 | N26: =IF(N$3<=7,TaxBasis*1000/7,0)+SUM(J25:N25)/TaxLife -> 60.435215 | O26: =IF(O$3<=7,TaxBasis*1000/7,0)+SUM(K25:O25)/TaxLife -> 55.278945 | P26: =IF(P$3<=7,TaxBasis*1000/7,0)+SUM(L25:P25)/TaxLife -> 51.099365 | Q26: =IF(Q$3<=7,TaxBasis*1000/7,0)+SUM(M25:Q25)/TaxLife -> 47.430431 | R26: =IF(R$3<=7,TaxBasis*1000/7,0)+SUM(N25:R25)/TaxLife -> 44.024926 | ... AI26: =IF(AI$3<=7,TaxBasis*1000/7,0)+SUM(AE25:AI25)/TaxLife -> 12.405241
A27: Cash tax ($mm) | G27: =TaxRate*MAX(0,G24-G26) -> 557.65898 | H27: =TaxRate*MAX(0,H24-H26) -> 154.91664 | I27: =TaxRate*MAX(0,I24-I26) -> 25.337818 | J27: =TaxRate*MAX(0,J24-J26) -> 0 | K27: =TaxRate*MAX(0,K24-K26) -> 0 | L27: =TaxRate*MAX(0,L24-L26) -> 0 | M27: =TaxRate*MAX(0,M24-M26) -> 0 | N27: =TaxRate*MAX(0,N24-N26) -> 219.12731 | ... AI27: =TaxRate*MAX(0,AI24-AI26) -> 47.211546
A28: Unlevered free cash flow ($mm) | G28: =G24-G25-G27 -> 1915.2203 | H28: =H24-H25-H27 -> 1232.6408 | I28: =I24-I25-I27 -> 1030.1821 | J28: =J24-J25-J27 -> 906.40389 | K28: =K24-K25-K27 -> 805.05387 | L28: =L24-L25-L27 -> 735.40533 | M28: =M24-M25-M27 -> 683.74789 | N28: =N24-N25-N27 -> 416.56912 | ... AI28: =AI24-AI25-AI27 -> 89.455124
A29: PV at discount rate ($mm) | B29: =SUM(G29:AI29) -> 6469.4054 | G29: =G28*(1+Disc)^-(G$3-0.5) -> 1809.7131 | H29: =H28*(1+Disc)^-(H$3-0.5) -> 1039.9429 | I29: =I28*(1+Disc)^-(I$3-0.5) -> 776.01292 | J29: =J28*(1+Disc)^-(J$3-0.5) -> 609.61926 | K29: =K28*(1+Disc)^-(K$3-0.5) -> 483.4414 | L29: =L28*(1+Disc)^-(L$3-0.5) -> 394.30079 | M29: =M28*(1+Disc)^-(M$3-0.5) -> 327.32476 | N29: =N28*(1+Disc)^-(N$3-0.5) -> 178.05407 | ... AI29: =AI28*(1+Disc)^-(AI$3-0.5) -> 3.5390897
A31: PRODUCING + PROVED UNDEVELOPED WELLS
A32: Wells tied in | G32: =MAX(0,MIN(G$11,MIN(PUDWells,Inventory))) -> 110 | H32: =MAX(0,MIN(H$11,MIN(PUDWells,Inventory)-SUM($G32:G32))) -> 125 | I32: =MAX(0,MIN(I$11,MIN(PUDWells,Inventory)-SUM($G32:H32))) -> 135 | J32: =MAX(0,MIN(J$11,MIN(PUDWells,Inventory)-SUM($G32:I32))) -> 80 | K32: =MAX(0,MIN(K$11,MIN(PUDWells,Inventory)-SUM($G32:J32))) -> 0 | L32: =MAX(0,MIN(L$11,MIN(PUDWells,Inventory)-SUM($G32:K32))) -> 0 | M32: =MAX(0,MIN(M$11,MIN(PUDWells,Inventory)-SUM($G32:L32))) -> 0 | N32: =MAX(0,MIN(N$11,MIN(PUDWells,Inventory)-SUM($G32:M32))) -> 0 | O32: =MAX(0,MIN(O$11,MIN(PUDWells,Inventory)-SUM($G32:N32))) -> 0 | ... AI32: =MAX(0,MIN(AI$11,MIN(PUDWells,Inventory)-SUM($G32:AH32))) -> 0
A33: New-well production (MMboe) | G33: =SUM(Cohorts!G35:G63) -> 14.85 | H33: =SUM(Cohorts!H35:H63) -> 35.685 | I33: =SUM(Cohorts!I35:I63) -> 51.48 | J33: =SUM(Cohorts!J35:J63) -> 56.295 | K33: =SUM(Cohorts!K35:K63) -> 45.315 | L33: =SUM(Cohorts!L35:L63) -> 33.39 | M33: =SUM(Cohorts!M35:M63) -> 26.685 | N33: =SUM(Cohorts!N35:N63) -> 22.41 | ... AI33: =SUM(Cohorts!AI35:AI63) -> 2.235226
A34: Total production (MMboe) | G34: =G$14+G33 -> 64.535625 | H34: =H$14+H33 -> 70.1337 | I34: =I$14+I33 -> 78.553546 | J34: =J$14+J33 -> 78.983227 | K34: =K$14+K33 -> 65.03668 | L34: =L$14+L33 -> 51.022021 | M34: =M$14+M33 -> 42.730139 | N34: =N$14+N33 -> 37.011077 | ... AI34: =AI$14+AI33 -> 4.2501289
A35: Production (kboe/d) | G35: =G34/0.365 -> 176.80993 | H35: =H34/0.365 -> 192.14712 | I35: =I34/0.365 -> 215.2152 | J35: =J34/0.365 -> 216.3924 | K35: =K34/0.365 -> 178.18269 | L35: =L34/0.365 -> 139.78636 | M35: =M34/0.365 -> 117.06888 | N35: =N34/0.365 -> 101.40021 | ... AI35: =AI34/0.365 -> 11.644189
A36: Revenue ($mm) | G36: =G34*G$8 -> 4950.3448 | H36: =H34*H$8 -> 4590.4125 | I36: =I34*I$8 -> 5043.4169 | J36: =J34*J$8 -> 5190.1019 | K36: =K34*K$8 -> 4364.7855 | L36: =L34*L$8 -> 3497.1477 | M36: =M34*M$8 -> 2991.0997 | N36: =N34*N$8 -> 2645.802 | ... AI36: =AI34*AI$8 -> 470.03547
A37: EBITDA ($mm) | G37: =G34*G$9 -> 3407.5049 | H37: =H34*H$9 -> 3041.6563 | I37: =I34*I$9 -> 3310.1985 | J37: =J34*J$9 -> 3409.367 | K37: =K34*K$9 -> 2868.1412 | L37: =L34*L$9 -> 2298.7314 | M37: =M34*M$9 -> 1966.7027 | N37: =N34*N$9 -> 1740.1863 | ... AI37: =AI34*AI$9 -> 310.69701
A38: Capex: wells + facilities ($mm) | G38: =G32*G$10+G34*Facilities*G$6 -> 1735.5334 | H38: =H32*H$10+H34*Facilities*H$6 -> 1779.2446 | I38: =I32*I$10+I34*Facilities*I$6 -> 1732.621 | J38: =J32*J$10+J34*Facilities*J$6 -> 1151.555 | K38: =K32*K$10+K34*Facilities*K$6 -> 213.29486 | L38: =L32*L$10+L34*Facilities*L$6 -> 170.67891 | M38: =M32*M$10+M34*Facilities*M$6 -> 145.79972 | N38: =N32*N$10+N34*Facilities*N$6 -> 128.81139 | ... AI38: =AI32*AI$10+AI34*Facilities*AI$6 -> 22.41962
A39: Tax depreciation ($mm) | G39: =IF(G$3<=7,TaxBasis*1000/7,0)+SUM(G38:G38)/TaxLife -> 1347.1067 | H39: =IF(H$3<=7,TaxBasis*1000/7,0)+SUM(G38:H38)/TaxLife -> 1702.9556 | I39: =IF(I$3<=7,TaxBasis*1000/7,0)+SUM(G38:I38)/TaxLife -> 2049.4798 | J39: =IF(J$3<=7,TaxBasis*1000/7,0)+SUM(G38:J38)/TaxLife -> 2279.7908 | K39: =IF(K$3<=7,TaxBasis*1000/7,0)+SUM(G38:K38)/TaxLife -> 2322.4498 | L39: =IF(L$3<=7,TaxBasis*1000/7,0)+SUM(H38:L38)/TaxLife -> 2009.4789 | M39: =IF(M$3<=7,TaxBasis*1000/7,0)+SUM(I38:M38)/TaxLife -> 1682.7899 | N39: =IF(N$3<=7,TaxBasis*1000/7,0)+SUM(J38:N38)/TaxLife -> 362.02797 | O39: =IF(O$3<=7,TaxBasis*1000/7,0)+SUM(K38:O38)/TaxLife -> 154.93685 | P39: =IF(P$3<=7,TaxBasis*1000/7,0)+SUM(L38:P38)/TaxLife -> 133.36896 | Q39: =IF(Q$3<=7,TaxBasis*1000/7,0)+SUM(M38:Q38)/TaxLife -> 118.55612 | R39: =IF(R$3<=7,TaxBasis*1000/7,0)+SUM(N38:R38)/TaxLife -> 107.09888 | ... AI39: =IF(AI$3<=7,TaxBasis*1000/7,0)+SUM(AE38:AI38)/TaxLife -> 26.499307
A40: Cash tax ($mm) | G40: =TaxRate*MAX(0,G37-G39) -> 721.13938 | H40: =TaxRate*MAX(0,H37-H39) -> 468.54526 | I40: =TaxRate*MAX(0,I37-I39) -> 441.25155 | J40: =TaxRate*MAX(0,J37-J39) -> 395.35167 | K40: =TaxRate*MAX(0,K37-K39) -> 190.99201 | L40: =TaxRate*MAX(0,L37-L39) -> 101.23838 | M40: =TaxRate*MAX(0,M37-M39) -> 99.36949 | N40: =TaxRate*MAX(0,N37-N39) -> 482.35543 | ... AI40: =TaxRate*MAX(0,AI37-AI39) -> 99.469197
A41: Unlevered free cash flow ($mm) | G41: =G37-G38-G40 -> 950.83216 | H41: =H37-H38-H40 -> 793.86648 | I41: =I37-I38-I40 -> 1136.3259 | J41: =J37-J38-J40 -> 1862.4603 | K41: =K37-K38-K40 -> 2463.8543 | L41: =L37-L38-L40 -> 2026.8141 | M41: =M37-M38-M40 -> 1721.5335 | N41: =N37-N38-N40 -> 1129.0195 | ... AI41: =AI37-AI38-AI40 -> 188.8082
A42: PV at discount rate ($mm) | B42: =SUM(G42:AI42) -> 9548.1382 | G42: =G41*(1+Disc)^-(G$3-0.5) -> 898.45194 | H42: =H41*(1+Disc)^-(H$3-0.5) -> 669.76189 | I42: =I41*(1+Disc)^-(I$3-0.5) -> 855.96867 | J42: =J41*(1+Disc)^-(J$3-0.5) -> 1252.6333 | K42: =K41*(1+Disc)^-(K$3-0.5) -> 1479.5646 | L42: =L41*(1+Disc)^-(L$3-0.5) -> 1086.7128 | M42: =M41*(1+Disc)^-(M$3-0.5) -> 824.13496 | N42: =N41*(1+Disc)^-(N$3-0.5) -> 482.57662 | ... AI42: =AI41*(1+Disc)^-(AI$3-0.5) -> 7.4697695
A44: PRODUCING + FULL INVENTORY
A45: Wells tied in | G45: =MAX(0,MIN(G$11,Inventory)) -> 110 | H45: =MAX(0,MIN(H$11,Inventory-SUM($G45:G45))) -> 125 | I45: =MAX(0,MIN(I$11,Inventory-SUM($G45:H45))) -> 135 | J45: =MAX(0,MIN(J$11,Inventory-SUM($G45:I45))) -> 135 | K45: =MAX(0,MIN(K$11,Inventory-SUM($G45:J45))) -> 135 | L45: =MAX(0,MIN(L$11,Inventory-SUM($G45:K45))) -> 135 | M45: =MAX(0,MIN(M$11,Inventory-SUM($G45:L45))) -> 135 | N45: =MAX(0,MIN(N$11,Inventory-SUM($G45:M45))) -> 135 | O45: =MAX(0,MIN(O$11,Inventory-SUM($G45:N45))) -> 135 | ... AI45: =MAX(0,MIN(AI$11,Inventory-SUM($G45:AH45))) -> 0
...

Sheet Cohorts
A1: New-well production by vintage (MMboe) = wells in vintage x EUR x profile(age)
A3: PRODUCING BASE ONLY (no new wells)
A4: Vintage P1 | G4: =Model!$G$19*EUR*Model!G$15 -> 0 | H4: =Model!$G$19*EUR*Model!H$15 -> 0 | I4: =Model!$G$19*EUR*Model!I$15 -> 0 | J4: =Model!$G$19*EUR*Model!J$15 -> 0 | K4: =Model!$G$19*EUR*Model!K$15 -> 0 | L4: =Model!$G$19*EUR*Model!L$15 -> 0 | M4: =Model!$G$19*EUR*Model!M$15 -> 0 | N4: =Model!$G$19*EUR*Model!N$15 -> 0 | ... AI4: =Model!$G$19*EUR*Model!AI$15 -> 0
A5: Vintage P2 | G5: 0 | H5: =Model!$H$19*EUR*Model!G$15 -> 0 | I5: =Model!$H$19*EUR*Model!H$15 -> 0 | J5: =Model!$H$19*EUR*Model!I$15 -> 0 | K5: =Model!$H$19*EUR*Model!J$15 -> 0 | L5: =Model!$H$19*EUR*Model!K$15 -> 0 | M5: =Model!$H$19*EUR*Model!L$15 -> 0 | N5: =Model!$H$19*EUR*Model!M$15 -> 0 | O5: =Model!$H$19*EUR*Model!N$15 -> 0 | ... AI5: =Model!$H$19*EUR*Model!AH$15 -> 0
A6: Vintage P3 | G6: 0 | H6: 0 | I6: =Model!$I$19*EUR*Model!G$15 -> 0 | J6: =Model!$I$19*EUR*Model!H$15 -> 0 | K6: =Model!$I$19*EUR*Model!I$15 -> 0 | L6: =Model!$I$19*EUR*Model!J$15 -> 0 | M6: =Model!$I$19*EUR*Model!K$15 -> 0 | N6: =Model!$I$19*EUR*Model!L$15 -> 0 | O6: =Model!$I$19*EUR*Model!M$15 -> 0 | P6: =Model!$I$19*EUR*Model!N$15 -> 0 | ... AI6: =Model!$I$19*EUR*Model!AG$15 -> 0
A7: Vintage P4 | G7: 0 | H7: 0 | I7: 0 | J7: =Model!$J$19*EUR*Model!G$15 -> 0 | K7: =Model!$J$19*EUR*Model!H$15 -> 0 | L7: =Model!$J$19*EUR*Model!I$15 -> 0 | M7: =Model!$J$19*EUR*Model!J$15 -> 0 | N7: =Model!$J$19*EUR*Model!K$15 -> 0 | O7: =Model!$J$19*EUR*Model!L$15 -> 0 | P7: =Model!$J$19*EUR*Model!M$15 -> 0 | Q7: =Model!$J$19*EUR*Model!N$15 -> 0 | ... AI7: =Model!$J$19*EUR*Model!AF$15 -> 0
A8: Vintage P5 | G8: 0 | H8: 0 | I8: 0 | J8: 0 | K8: =Model!$K$19*EUR*Model!G$15 -> 0 | L8: =Model!$K$19*EUR*Model!H$15 -> 0 | M8: =Model!$K$19*EUR*Model!I$15 -> 0 | N8: =Model!$K$19*EUR*Model!J$15 -> 0 | O8: =Model!$K$19*EUR*Model!K$15 -> 0 | P8: =Model!$K$19*EUR*Model!L$15 -> 0 | Q8: =Model!$K$19*EUR*Model!M$15 -> 0 | R8: =Model!$K$19*EUR*Model!N$15 -> 0 | ... AI8: =Model!$K$19*EUR*Model!AE$15 -> 0
A9: Vintage P6 | G9: 0 | H9: 0 | I9: 0 | J9: 0 | K9: 0 | L9: =Model!$L$19*EUR*Model!G$15 -> 0 | M9: =Model!$L$19*EUR*Model!H$15 -> 0 | N9: =Model!$L$19*EUR*Model!I$15 -> 0 | O9: =Model!$L$19*EUR*Model!J$15 -> 0 | P9: =Model!$L$19*EUR*Model!K$15 -> 0 | Q9: =Model!$L$19*EUR*Model!L$15 -> 0 | R9: =Model!$L$19*EUR*Model!M$15 -> 0 | S9: =Model!$L$19*EUR*Model!N$15 -> 0 | ... AI9: =Model!$L$19*EUR*Model!AD$15 -> 0
A10: Vintage P7 | G10: 0 | H10: 0 | I10: 0 | J10: 0 | K10: 0 | L10: 0 | M10: =Model!$M$19*EUR*Model!G$15 -> 0 | N10: =Model!$M$19*EUR*Model!H$15 -> 0 | O10: =Model!$M$19*EUR*Model!I$15 -> 0 | P10: =Model!$M$19*EUR*Model!J$15 -> 0 | Q10: =Model!$M$19*EUR*Model!K$15 -> 0 | R10: =Model!$M$19*EUR*Model!L$15 -> 0 | S10: =Model!$M$19*EUR*Model!M$15 -> 0 | T10: =Model!$M$19*EUR*Model!N$15 -> 0 | ... AI10: =Model!$M$19*EUR*Model!AC$15 -> 0
A11: Vintage P8 | G11: 0 | H11: 0 | I11: 0 | J11: 0 | K11: 0 | L11: 0 | M11: 0 | N11: =Model!$N$19*EUR*Model!G$15 -> 0 | O11: =Model!$N$19*EUR*Model!H$15 -> 0 | P11: =Model!$N$19*EUR*Model!I$15 -> 0 | Q11: =Model!$N$19*EUR*Model!J$15 -> 0 | R11: =Model!$N$19*EUR*Model!K$15 -> 0 | S11: =Model!$N$19*EUR*Model!L$15 -> 0 | T11: =Model!$N$19*EUR*Model!M$15 -> 0 | U11: =Model!$N$19*EUR*Model!N$15 -> 0 | ... AI11: =Model!$N$19*EUR*Model!AB$15 -> 0
A12: Vintage P9 | G12: 0 | H12: 0 | I12: 0 | J12: 0 | K12: 0 | L12: 0 | M12: 0 | N12: 0 | O12: =Model!$O$19*EUR*Model!G$15 -> 0 | P12: =Model!$O$19*EUR*Model!H$15 -> 0 | Q12: =Model!$O$19*EUR*Model!I$15 -> 0 | R12: =Model!$O$19*EUR*Model!J$15 -> 0 | S12: =Model!$O$19*EUR*Model!K$15 -> 0 | T12: =Model!$O$19*EUR*Model!L$15 -> 0 | U12: =Model!$O$19*EUR*Model!M$15 -> 0 | V12: =Model!$O$19*EUR*Model!N$15 -> 0 | ... AI12: =Model!$O$19*EUR*Model!AA$15 -> 0
A13: Vintage P10 | G13: 0 | H13: 0 | I13: 0 | J13: 0 | K13: 0 | L13: 0 | M13: 0 | N13: 0 | O13: 0 | P13: =Model!$P$19*EUR*Model!G$15 -> 0 | Q13: =Model!$P$19*EUR*Model!H$15 -> 0 | R13: =Model!$P$19*EUR*Model!I$15 -> 0 | S13: =Model!$P$19*EUR*Model!J$15 -> 0 | T13: =Model!$P$19*EUR*Model!K$15 -> 0 | U13: =Model!$P$19*EUR*Model!L$15 -> 0 | V13: =Model!$P$19*EUR*Model!M$15 -> 0 | W13: =Model!$P$19*EUR*Model!N$15 -> 0 | ... AI13: =Model!$P$19*EUR*Model!Z$15 -> 0
A14: Vintage P11 | G14: 0 | H14: 0 | I14: 0 | J14: 0 | K14: 0 | L14: 0 | M14: 0 | N14: 0 | O14: 0 | P14: 0 | Q14: =Model!$Q$19*EUR*Model!G$15 -> 0 | R14: =Model!$Q$19*EUR*Model!H$15 -> 0 | S14: =Model!$Q$19*EUR*Model!I$15 -> 0 | T14: =Model!$Q$19*EUR*Model!J$15 -> 0 | U14: =Model!$Q$19*EUR*Model!K$15 -> 0 | V14: =Model!$Q$19*EUR*Model!L$15 -> 0 | W14: =Model!$Q$19*EUR*Model!M$15 -> 0 | X14: =Model!$Q$19*EUR*Model!N$15 -> 0 | ... AI14: =Model!$Q$19*EUR*Model!Y$15 -> 0
A15: Vintage P12 | G15: 0 | H15: 0 | I15: 0 | J15: 0 | K15: 0 | L15: 0 | M15: 0 | N15: 0 | O15: 0 | P15: 0 | Q15: 0 | R15: =Model!$R$19*EUR*Model!G$15 -> 0 | S15: =Model!$R$19*EUR*Model!H$15 -> 0 | T15: =Model!$R$19*EUR*Model!I$15 -> 0 | U15: =Model!$R$19*EUR*Model!J$15 -> 0 | V15: =Model!$R$19*EUR*Model!K$15 -> 0 | W15: =Model!$R$19*EUR*Model!L$15 -> 0 | X15: =Model!$R$19*EUR*Model!M$15 -> 0 | Y15: =Model!$R$19*EUR*Model!N$15 -> 0 | ... AI15: =Model!$R$19*EUR*Model!X$15 -> 0
A16: Vintage P13 | G16: 0 | H16: 0 | I16: 0 | J16: 0 | K16: 0 | L16: 0 | M16: 0 | N16: 0 | O16: 0 | P16: 0 | Q16: 0 | R16: 0 | S16: =Model!$S$19*EUR*Model!G$15 -> 0 | T16: =Model!$S$19*EUR*Model!H$15 -> 0 | U16: =Model!$S$19*EUR*Model!I$15 -> 0 | V16: =Model!$S$19*EUR*Model!J$15 -> 0 | W16: =Model!$S$19*EUR*Model!K$15 -> 0 | X16: =Model!$S$19*EUR*Model!L$15 -> 0 | Y16: =Model!$S$19*EUR*Model!M$15 -> 0 | Z16: =Model!$S$19*EUR*Model!N$15 -> 0 | ... AI16: =Model!$S$19*EUR*Model!W$15 -> 0
A17: Vintage P14 | G17: 0 | H17: 0 | I17: 0 | J17: 0 | K17: 0 | L17: 0 | M17: 0 | N17: 0 | O17: 0 | P17: 0 | Q17: 0 | R17: 0 | S17: 0 | T17: =Model!$T$19*EUR*Model!G$15 -> 0 | U17: =Model!$T$19*EUR*Model!H$15 -> 0 | V17: =Model!$T$19*EUR*Model!I$15 -> 0 | W17: =Model!$T$19*EUR*Model!J$15 -> 0 | X17: =Model!$T$19*EUR*Model!K$15 -> 0 | Y17: =Model!$T$19*EUR*Model!L$15 -> 0 | Z17: =Model!$T$19*EUR*Model!M$15 -> 0 | AA17: =Model!$T$19*EUR*Model!N$15 -> 0 | ... AI17: =Model!$T$19*EUR*Model!V$15 -> 0
A18: Vintage P15 | G18: 0 | H18: 0 | I18: 0 | J18: 0 | K18: 0 | L18: 0 | M18: 0 | N18: 0 | O18: 0 | P18: 0 | Q18: 0 | R18: 0 | S18: 0 | T18: 0 | U18: =Model!$U$19*EUR*Model!G$15 -> 0 | V18: =Model!$U$19*EUR*Model!H$15 -> 0 | W18: =Model!$U$19*EUR*Model!I$15 -> 0 | X18: =Model!$U$19*EUR*Model!J$15 -> 0 | Y18: =Model!$U$19*EUR*Model!K$15 -> 0 | Z18: =Model!$U$19*EUR*Model!L$15 -> 0 | AA18: =Model!$U$19*EUR*Model!M$15 -> 0 | AB18: =Model!$U$19*EUR*Model!N$15 -> 0 | ... AI18: =Model!$U$19*EUR*Model!U$15 -> 0
A19: Vintage P16 | G19: 0 | H19: 0 | I19: 0 | J19: 0 | K19: 0 | L19: 0 | M19: 0 | N19: 0 | O19: 0 | P19: 0 | Q19: 0 | R19: 0 | S19: 0 | T19: 0 | U19: 0 | V19: =Model!$V$19*EUR*Model!G$15 -> 0 | W19: =Model!$V$19*EUR*Model!H$15 -> 0 | X19: =Model!$V$19*EUR*Model!I$15 -> 0 | Y19: =Model!$V$19*EUR*Model!J$15 -> 0 | Z19: =Model!$V$19*EUR*Model!K$15 -> 0 | AA19: =Model!$V$19*EUR*Model!L$15 -> 0 | AB19: =Model!$V$19*EUR*Model!M$15 -> 0 | AC19: =Model!$V$19*EUR*Model!N$15 -> 0 | ... AI19: =Model!$V$19*EUR*Model!T$15 -> 0
A20: Vintage P17 | G20: 0 | H20: 0 | I20: 0 | J20: 0 | K20: 0 | L20: 0 | M20: 0 | N20: 0 | O20: 0 | P20: 0 | Q20: 0 | R20: 0 | S20: 0 | T20: 0 | U20: 0 | V20: 0 | W20: =Model!$W$19*EUR*Model!G$15 -> 0 | X20: =Model!$W$19*EUR*Model!H$15 -> 0 | Y20: =Model!$W$19*EUR*Model!I$15 -> 0 | Z20: =Model!$W$19*EUR*Model!J$15 -> 0 | AA20: =Model!$W$19*EUR*Model!K$15 -> 0 | AB20: =Model!$W$19*EUR*Model!L$15 -> 0 | AC20: =Model!$W$19*EUR*Model!M$15 -> 0 | AD20: =Model!$W$19*EUR*Model!N$15 -> 0 | ... AI20: =Model!$W$19*EUR*Model!S$15 -> 0
A21: Vintage P18 | G21: 0 | H21: 0 | I21: 0 | J21: 0 | K21: 0 | L21: 0 | M21: 0 | N21: 0 | O21: 0 | P21: 0 | Q21: 0 | R21: 0 | S21: 0 | T21: 0 | U21: 0 | V21: 0 | W21: 0 | X21: =Model!$X$19*EUR*Model!G$15 -> 0 | Y21: =Model!$X$19*EUR*Model!H$15 -> 0 | Z21: =Model!$X$19*EUR*Model!I$15 -> 0 | AA21: =Model!$X$19*EUR*Model!J$15 -> 0 | AB21: =Model!$X$19*EUR*Model!K$15 -> 0 | AC21: =Model!$X$19*EUR*Model!L$15 -> 0 | AD21: =Model!$X$19*EUR*Model!M$15 -> 0 | AE21: =Model!$X$19*EUR*Model!N$15 -> 0 | ... AI21: =Model!$X$19*EUR*Model!R$15 -> 0
A22: Vintage P19 | G22: 0 | H22: 0 | I22: 0 | J22: 0 | K22: 0 | L22: 0 | M22: 0 | N22: 0 | O22: 0 | P22: 0 | Q22: 0 | R22: 0 | S22: 0 | T22: 0 | U22: 0 | V22: 0 | W22: 0 | X22: 0 | Y22: =Model!$Y$19*EUR*Model!G$15 -> 0 | Z22: =Model!$Y$19*EUR*Model!H$15 -> 0 | AA22: =Model!$Y$19*EUR*Model!I$15 -> 0 | AB22: =Model!$Y$19*EUR*Model!J$15 -> 0 | AC22: =Model!$Y$19*EUR*Model!K$15 -> 0 | AD22: =Model!$Y$19*EUR*Model!L$15 -> 0 | AE22: =Model!$Y$19*EUR*Model!M$15 -> 0 | AF22: =Model!$Y$19*EUR*Model!N$15 -> 0 | ... AI22: =Model!$Y$19*EUR*Model!Q$15 -> 0
A23: Vintage P20 | G23: 0 | H23: 0 | I23: 0 | J23: 0 | K23: 0 | L23: 0 | M23: 0 | N23: 0 | O23: 0 | P23: 0 | Q23: 0 | R23: 0 | S23: 0 | T23: 0 | U23: 0 | V23: 0 | W23: 0 | X23: 0 | Y23: 0 | Z23: =Model!$Z$19*EUR*Model!G$15 -> 0 | AA23: =Model!$Z$19*EUR*Model!H$15 -> 0 | AB23: =Model!$Z$19*EUR*Model!I$15 -> 0 | AC23: =Model!$Z$19*EUR*Model!J$15 -> 0 | AD23: =Model!$Z$19*EUR*Model!K$15 -> 0 | AE23: =Model!$Z$19*EUR*Model!L$15 -> 0 | AF23: =Model!$Z$19*EUR*Model!M$15 -> 0 | AG23: =Model!$Z$19*EUR*Model!N$15 -> 0 | ... AI23: =Model!$Z$19*EUR*Model!P$15 -> 0
A24: Vintage P21 | G24: 0 | H24: 0 | I24: 0 | J24: 0 | K24: 0 | L24: 0 | M24: 0 | N24: 0 | O24: 0 | P24: 0 | Q24: 0 | R24: 0 | S24: 0 | T24: 0 | U24: 0 | V24: 0 | W24: 0 | X24: 0 | Y24: 0 | Z24: 0 | AA24: =Model!$AA$19*EUR*Model!G$15 -> 0 | AB24: =Model!$AA$19*EUR*Model!H$15 -> 0 | AC24: =Model!$AA$19*EUR*Model!I$15 -> 0 | AD24: =Model!$AA$19*EUR*Model!J$15 -> 0 | AE24: =Model!$AA$19*EUR*Model!K$15 -> 0 | AF24: =Model!$AA$19*EUR*Model!L$15 -> 0 | AG24: =Model!$AA$19*EUR*Model!M$15 -> 0 | AH24: =Model!$AA$19*EUR*Model!N$15 -> 0 | AI24: =Model!$AA$19*EUR*Model!O$15 -> 0
A25: Vintage P22 | G25: 0 | H25: 0 | I25: 0 | J25: 0 | K25: 0 | L25: 0 | M25: 0 | N25: 0 | O25: 0 | P25: 0 | Q25: 0 | R25: 0 | S25: 0 | T25: 0 | U25: 0 | V25: 0 | W25: 0 | X25: 0 | Y25: 0 | Z25: 0 | AA25: 0 | AB25: =Model!$AB$19*EUR*Model!G$15 -> 0 | AC25: =Model!$AB$19*EUR*Model!H$15 -> 0 | AD25: =Model!$AB$19*EUR*Model!I$15 -> 0 | AE25: =Model!$AB$19*EUR*Model!J$15 -> 0 | AF25: =Model!$AB$19*EUR*Model!K$15 -> 0 | AG25: =Model!$AB$19*EUR*Model!L$15 -> 0 | AH25: =Model!$AB$19*EUR*Model!M$15 -> 0 | AI25: =Model!$AB$19*EUR*Model!N$15 -> 0
A26: Vintage P23 | G26: 0 | H26: 0 | I26: 0 | J26: 0 | K26: 0 | L26: 0 | M26: 0 | N26: 0 | O26: 0 | P26: 0 | Q26: 0 | R26: 0 | S26: 0 | T26: 0 | U26: 0 | V26: 0 | W26: 0 | X26: 0 | Y26: 0 | Z26: 0 | AA26: 0 | AB26: 0 | AC26: =Model!$AC$19*EUR*Model!G$15 -> 0 | AD26: =Model!$AC$19*EUR*Model!H$15 -> 0 | AE26: =Model!$AC$19*EUR*Model!I$15 -> 0 | AF26: =Model!$AC$19*EUR*Model!J$15 -> 0 | AG26: =Model!$AC$19*EUR*Model!K$15 -> 0 | AH26: =Model!$AC$19*EUR*Model!L$15 -> 0 | AI26: =Model!$AC$19*EUR*Model!M$15 -> 0
A27: Vintage P24 | G27: 0 | H27: 0 | I27: 0 | J27: 0 | K27: 0 | L27: 0 | M27: 0 | N27: 0 | O27: 0 | P27: 0 | Q27: 0 | R27: 0 | S27: 0 | T27: 0 | U27: 0 | V27: 0 | W27: 0 | X27: 0 | Y27: 0 | Z27: 0 | AA27: 0 | AB27: 0 | AC27: 0 | AD27: =Model!$AD$19*EUR*Model!G$15 -> 0 | AE27: =Model!$AD$19*EUR*Model!H$15 -> 0 | AF27: =Model!$AD$19*EUR*Model!I$15 -> 0 | AG27: =Model!$AD$19*EUR*Model!J$15 -> 0 | AH27: =Model!$AD$19*EUR*Model!K$15 -> 0 | AI27: =Model!$AD$19*EUR*Model!L$15 -> 0
A28: Vintage P25 | G28: 0 | H28: 0 | I28: 0 | J28: 0 | K28: 0 | L28: 0 | M28: 0 | N28: 0 | O28: 0 | P28: 0 | Q28: 0 | R28: 0 | S28: 0 | T28: 0 | U28: 0 | V28: 0 | W28: 0 | X28: 0 | Y28: 0 | Z28: 0 | AA28: 0 | AB28: 0 | AC28: 0 | AD28: 0 | AE28: =Model!$AE$19*EUR*Model!G$15 -> 0 | AF28: =Model!$AE$19*EUR*Model!H$15 -> 0 | AG28: =Model!$AE$19*EUR*Model!I$15 -> 0 | AH28: =Model!$AE$19*EUR*Model!J$15 -> 0 | AI28: =Model!$AE$19*EUR*Model!K$15 -> 0
A29: Vintage P26 | G29: 0 | H29: 0 | I29: 0 | J29: 0 | K29: 0 | L29: 0 | M29: 0 | N29: 0 | O29: 0 | P29: 0 | Q29: 0 | R29: 0 | S29: 0 | T29: 0 | U29: 0 | V29: 0 | W29: 0 | X29: 0 | Y29: 0 | Z29: 0 | AA29: 0 | AB29: 0 | AC29: 0 | AD29: 0 | AE29: 0 | AF29: =Model!$AF$19*EUR*Model!G$15 -> 0 | AG29: =Model!$AF$19*EUR*Model!H$15 -> 0 | AH29: =Model!$AF$19*EUR*Model!I$15 -> 0 | AI29: =Model!$AF$19*EUR*Model!J$15 -> 0
A30: Vintage P27 | G30: 0 | H30: 0 | I30: 0 | J30: 0 | K30: 0 | L30: 0 | M30: 0 | N30: 0 | O30: 0 | P30: 0 | Q30: 0 | R30: 0 | S30: 0 | T30: 0 | U30: 0 | V30: 0 | W30: 0 | X30: 0 | Y30: 0 | Z30: 0 | AA30: 0 | AB30: 0 | AC30: 0 | AD30: 0 | AE30: 0 | AF30: 0 | AG30: =Model!$AG$19*EUR*Model!G$15 -> 0 | AH30: =Model!$AG$19*EUR*Model!H$15 -> 0 | AI30: =Model!$AG$19*EUR*Model!I$15 -> 0
A31: Vintage P28 | G31: 0 | H31: 0 | I31: 0 | J31: 0 | K31: 0 | L31: 0 | M31: 0 | N31: 0 | O31: 0 | P31: 0 | Q31: 0 | R31: 0 | S31: 0 | T31: 0 | U31: 0 | V31: 0 | W31: 0 | X31: 0 | Y31: 0 | Z31: 0 | AA31: 0 | AB31: 0 | AC31: 0 | AD31: 0 | AE31: 0 | AF31: 0 | AG31: 0 | AH31: =Model!$AH$19*EUR*Model!G$15 -> 0 | AI31: =Model!$AH$19*EUR*Model!H$15 -> 0
A32: Vintage P29 | G32: 0 | H32: 0 | I32: 0 | J32: 0 | K32: 0 | L32: 0 | M32: 0 | N32: 0 | O32: 0 | P32: 0 | Q32: 0 | R32: 0 | S32: 0 | T32: 0 | U32: 0 | V32: 0 | W32: 0 | X32: 0 | Y32: 0 | Z32: 0 | AA32: 0 | AB32: 0 | AC32: 0 | AD32: 0 | AE32: 0 | AF32: 0 | AG32: 0 | AH32: 0 | AI32: =Model!$AI$19*EUR*Model!G$15 -> 0
A34: PRODUCING + PROVED UNDEVELOPED WELLS
A35: Vintage P1 | G35: =Model!$G$32*EUR*Model!G$15 -> 14.85 | H35: =Model!$G$32*EUR*Model!H$15 -> 18.81 | I35: =Model!$G$32*EUR*Model!I$15 -> 11.88 | J35: =Model!$G$32*EUR*Model!J$15 -> 8.91 | K35: =Model!$G$32*EUR*Model!K$15 -> 6.93 | L35: =Model!$G$32*EUR*Model!L$15 -> 5.94 | M35: =Model!$G$32*EUR*Model!M$15 -> 4.95 | N35: =Model!$G$32*EUR*Model!N$15 -> 4.455 | ... AI35: =Model!$G$32*EUR*Model!AI$15 -> 0.46807012
A36: Vintage P2 | G36: 0 | H36: =Model!$H$32*EUR*Model!G$15 -> 16.875 | I36: =Model!$H$32*EUR*Model!H$15 -> 21.375 | J36: =Model!$H$32*EUR*Model!I$15 -> 13.5 | K36: =Model!$H$32*EUR*Model!J$15 -> 10.125 | L36: =Model!$H$32*EUR*Model!K$15 -> 7.875 | M36: =Model!$H$32*EUR*Model!L$15 -> 6.75 | N36: =Model!$H$32*EUR*Model!M$15 -> 5.625 | O36: =Model!$H$32*EUR*Model!N$15 -> 5.0625 | ... AI36: =Model!$H$32*EUR*Model!AH$15 -> 0.59099763
A37: Vintage P3 | G37: 0 | H37: 0 | I37: =Model!$I$32*EUR*Model!G$15 -> 18.225 | J37: =Model!$I$32*EUR*Model!H$15 -> 23.085 | K37: =Model!$I$32*EUR*Model!I$15 -> 14.58 | L37: =Model!$I$32*EUR*Model!J$15 -> 10.935 | M37: =Model!$I$32*EUR*Model!K$15 -> 8.505 | N37: =Model!$I$32*EUR*Model!L$15 -> 7.29 | O37: =Model!$I$32*EUR*Model!M$15 -> 6.075 | P37: =Model!$I$32*EUR*Model!N$15 -> 5.4675 | ... AI37: =Model!$I$32*EUR*Model!AG$15 -> 0.70919715
A38: Vintage P4 | G38: 0 | H38: 0 | I38: 0 | J38: =Model!$J$32*EUR*Model!G$15 -> 10.8 | K38: =Model!$J$32*EUR*Model!H$15 -> 13.68 | L38: =Model!$J$32*EUR*Model!I$15 -> 8.64 | M38: =Model!$J$32*EUR*Model!J$15 -> 6.48 | N38: =Model!$J$32*EUR*Model!K$15 -> 5.04 | O38: =Model!$J$32*EUR*Model!L$15 -> 4.32 | P38: =Model!$J$32*EUR*Model!M$15 -> 3.6 | Q38: =Model!$J$32*EUR*Model!N$15 -> 3.24 | ... AI38: =Model!$J$32*EUR*Model!AF$15 -> 0.46696109
A39: Vintage P5 | G39: 0 | H39: 0 | I39: 0 | J39: 0 | K39: =Model!$K$32*EUR*Model!G$15 -> 0 | L39: =Model!$K$32*EUR*Model!H$15 -> 0 | M39: =Model!$K$32*EUR*Model!I$15 -> 0 | N39: =Model!$K$32*EUR*Model!J$15 -> 0 | O39: =Model!$K$32*EUR*Model!K$15 -> 0 | P39: =Model!$K$32*EUR*Model!L$15 -> 0 | Q39: =Model!$K$32*EUR*Model!M$15 -> 0 | R39: =Model!$K$32*EUR*Model!N$15 -> 0 | ... AI39: =Model!$K$32*EUR*Model!AE$15 -> 0
A40: Vintage P6 | G40: 0 | H40: 0 | I40: 0 | J40: 0 | K40: 0 | L40: =Model!$L$32*EUR*Model!G$15 -> 0 | M40: =Model!$L$32*EUR*Model!H$15 -> 0 | N40: =Model!$L$32*EUR*Model!I$15 -> 0 | O40: =Model!$L$32*EUR*Model!J$15 -> 0 | P40: =Model!$L$32*EUR*Model!K$15 -> 0 | Q40: =Model!$L$32*EUR*Model!L$15 -> 0 | R40: =Model!$L$32*EUR*Model!M$15 -> 0 | S40: =Model!$L$32*EUR*Model!N$15 -> 0 | ... AI40: =Model!$L$32*EUR*Model!AD$15 -> 0
A41: Vintage P7 | G41: 0 | H41: 0 | I41: 0 | J41: 0 | K41: 0 | L41: 0 | M41: =Model!$M$32*EUR*Model!G$15 -> 0 | N41: =Model!$M$32*EUR*Model!H$15 -> 0 | O41: =Model!$M$32*EUR*Model!I$15 -> 0 | P41: =Model!$M$32*EUR*Model!J$15 -> 0 | Q41: =Model!$M$32*EUR*Model!K$15 -> 0 | R41: =Model!$M$32*EUR*Model!L$15 -> 0 | S41: =Model!$M$32*EUR*Model!M$15 -> 0 | T41: =Model!$M$32*EUR*Model!N$15 -> 0 | ... AI41: =Model!$M$32*EUR*Model!AC$15 -> 0
A42: Vintage P8 | G42: 0 | H42: 0 | I42: 0 | J42: 0 | K42: 0 | L42: 0 | M42: 0 | N42: =Model!$N$32*EUR*Model!G$15 -> 0 | O42: =Model!$N$32*EUR*Model!H$15 -> 0 | P42: =Model!$N$32*EUR*Model!I$15 -> 0 | Q42: =Model!$N$32*EUR*Model!J$15 -> 0 | R42: =Model!$N$32*EUR*Model!K$15 -> 0 | S42: =Model!$N$32*EUR*Model!L$15 -> 0 | T42: =Model!$N$32*EUR*Model!M$15 -> 0 | U42: =Model!$N$32*EUR*Model!N$15 -> 0 | ... AI42: =Model!$N$32*EUR*Model!AB$15 -> 0
...
